Workbook

Sheet LEEME
A1: Kingspan Middle Americas · Commercial Review – Motor de datos (Data Engine)
A3: Cómo usar este archivo
A4: 1. Diligencie SOLO las celdas amarillas con texto azul (inputs). Todo lo demás (%, YoY, MoM, totales, mix, rankings, semáforos, Top 5) se calcula solo.
A5: 2. Cada hoja corresponde a un slide del deck (01 = Commercial Overview … 15 = Highlights). El número de la hoja = número del slide de contenido.
A6: 3. Los rankings de consultores (hojas 09–14) y los Top 5 (hojas 07–08) se reordenan automáticamente al cambiar los datos.
A7: 4. Para actualizar el PowerPoint: en cada gráfico clic derecho › "Editar datos" y pegue los valores de la tabla "Fuente gráfico" de la hoja correspondiente; en las tablas, pegue valores (Pegado especial › Valores) desde el bloque "Tabla slide".
A8: Alternativa: copie el bloque de la hoja y en PowerPoint use Pegado especial › "Pegar vínculo" (Hoja de Microsoft Excel) para dejar la tabla vinculada a este archivo.
A9: 5. Mes de corte: hoja 02_OI celda B4 y 06_Perf_Forecast celda B4 (número de mes, 9 = septiembre).
A10: 6. Revise la hoja "Validaciones": lista inconsistencias detectadas en el deck original y cómo se corrigieron.
A12: Convenciones
A13: Amarillo + azul = input · Negro = fórmula · Verde/Ámbar/Rojo = semáforo de cumplimiento (≥100% / 70–99% / <70%).
A14: Unidades: volumen en m²; ingresos en COP MM (millones de pesos); pipeline en USD.
... A24: • Mapa actual: 1 Portada · 2 Resumen ejecutivo · 3 Overview · 4 OI · 5 OI canal · 6 Backlog · 7 Backlog canal · 8 Performed/Forecast · 9 Top Opps · 10–11 Key Projects · 12 Resumen canales · 13 Sales vs Budget & margen · 14 Qué explica la desviación · 15–16 Iniciativas · 17 Actividad→Impacto · 18 Highlights · 19 Decisiones · 20 Cierre.

Sheet 00_Resumen_Ejecutivo
A1: 00 · Resumen ejecutivo – 4 preguntas
A2: Slide 2: qué nos comprometimos (amarillo = input), qué logramos (fórmula), desviación y estado (automáticos), qué la explica y acción (input).
A4: Indicador | B4: Unidad | C4: Compromiso / meta | D4: Resultado | E4: Desviación (Res − Comp) | F4: % vs compromiso | G4: Estado sugerido | H4: Estado final (override) | I4: Qué la explica | J4: Acción / decisión | K4: Responsable | L4: Fecha
A5: Order Intake YTD | B5: m² | D5: ='02_OI'!E7 -> 1400088 | E5: =IF(C5="","",D5-C5) | F5: =IF(OR(C5="",C5=0),"",D5/C5) | G5: =IF(F5="","Definir",IF(ROUND(F5,2)>=1,"Verde",IF(ROUND(F5,2)>=0.85,"Amarillo","Rojo"))) -> Definir
A6: Ventas YTD | B6: m² | C6: =RSM_Resumen_Canales!E11 -> 1247362.9 | D6: =RSM_Resumen_Canales!D11 -> 1058016 | E6: =IF(C6="","",D6-C6) -> -189346.88 | F6: =IF(OR(C6="",C6=0),"",D6/C6) -> 0.84820225 | G6: =IF(F6="","Definir",IF(ROUND(F6,2)>=1,"Verde",IF(ROUND(F6,2)>=0.85,"Amarillo","Rojo"))) -> Amarillo | I6: Industrial y Otras Geografías = 98% de la brecha | J6: Plan de cobertura territorios Industrial + plan de recuperación cuentas Ecuador / Costa Rica
A7: Margen OI YTD (Gross-STD) | B7: % | D7: ='02_OI'!E12 -> 0.25 | E7: =IF(C7="","",D7-C7) | F7: =IF(OR(C7="",C7=0),"",D7/C7) | G7: =IF(F7="","Definir",IF(ROUND(F7,2)>=1,"Verde",IF(ROUND(F7,2)>=0.85,"Amarillo","Rojo"))) -> Definir
A8: Backlog IMP | B8: m² | D8: ='04_Backlog'!B5 -> 525529 | E8: =IF(C8="","",D8-C8) | F8: =IF(OR(C8="",C8=0),"",D8/C8) | G8: =IF(F8="","Definir",IF(ROUND(F8,2)>=1,"Verde",IF(ROUND(F8,2)>=0.85,"Amarillo","Rojo"))) -> Definir
A9: Margen backlog (ponderado) | B9: % | D9: =RSM_Resumen_Canales!J11 -> 0.26897602 | E9: =IF(C9="","",D9-C9) | F9: =IF(OR(C9="",C9=0),"",D9/C9) | G9: =IF(F9="","Definir",IF(ROUND(F9,2)>=1,"Verde",IF(ROUND(F9,2)>=0.85,"Amarillo","Rojo"))) -> Definir
A10: Cierre año OI (real + forecast) | B10: m² | D10: ='06_Perf_Forecast'!B30 -> 1651050 | E10: =IF(C10="","",D10-C10) | F10: =IF(OR(C10="",C10=0),"",D10/C10) | G10: =IF(F10="","Definir",IF(ROUND(F10,2)>=1,"Verde",IF(ROUND(F10,2)>=0.85,"Amarillo","Rojo"))) -> Definir | I10: Forecast Q4 400k m² (+7,6% vs Q4-25)
A11: Iniciativas estratégicas en verde | B11: # | C11: 8 | D11: =COUNTIF('16_Iniciativas'!J5:J12,"Verde") -> 0 | E11: =IF(C11="","",D11-C11) -> -8 | F11: =IF(OR(C11="",C11=0),"",D11/C11) -> 0 | G11: =IF(COUNTA('16_Iniciativas'!J5:J12)=0,"Definir",IF(ROUND(F11,2)>=1,"Verde",IF(ROUND(F11,2)>=0.85,"Amarillo","Rojo"))) -> Definir
A13: Regla de estado sugerido: ≥100% del compromiso = Verde · 85–99% = Amarillo · <85% = Rojo. Si se diligencia "Estado final", ese prevalece en el slide.
A14: Mensaje clave del slide (1 línea): | C14: Estamos al 85% del budget de ventas YTD con OI y margen por encima del año anterior; la brecha está en territorios Industrial y dos cuentas de exportación.

Sheet 01_Overview
A1: 01 · Commercial Overview
A2: Ventas y Order Intake del mes, YTD, YoY y MoM · mix de ventas por canal y geografía
A4: Concepto (m²) | B4: Mes actual (Sep-26) | C4: Mismo mes PY (Sep-25) | D4: Mes anterior (Ago-26) | E4: YTD 2026 | F4: YTD 2025 | G4: YoY mes | H4: MoM | I4: YoY YTD
A5: Ventas (Sales) | B5: 141231 | C5: 99001 | D5: 125933 | E5: 1199504 | F5: 1120888 | G5: =IF(OR(B5="",C5=""),"",IF(C5=0,"n.a.",B5/C5-1)) -> 0.42656135 | H5: =IF(OR(B5="",D5=""),"",IF(D5=0,"n.a.",B5/D5-1)) -> 0.12147729 | I5: =IF(OR(E5="",F5=""),"",IF(F5=0,"n.a.",E5/F5-1)) -> 0.070137248
A6: Order Intake | B6: 160547 | C6: 132769 | D6: 146446 | E6: 1400088 | F6: 988103 | G6: =IF(OR(B6="",C6=""),"",IF(C6=0,"n.a.",B6/C6-1)) -> 0.20922053 | H6: =IF(OR(B6="",D6=""),"",IF(D6=0,"n.a.",B6/D6-1)) -> 0.096288052 | I6: =IF(OR(E6="",F6=""),"",IF(F6=0,"n.a.",E6/F6-1)) -> 0.4169454
A7: Book-to-bill YTD (OI / Ventas) | E7: =IFERROR(E6/E5,"") -> 1.1672225
A8: Book-to-bill mes | B8: =IFERROR(B6/B5,"") -> 1.1367688
A10: Ventas del mes por canal | B10: m² | C10: Mix %
A11: Industrial | C11: =IFERROR(B11/SUM($B$11:$B$12),0) -> 0
A12: Distribution | C12: =IFERROR(B12/SUM($B$11:$B$12),0) -> 0
A14: Ventas del mes por geografía | B14: m² | C14: Mix %
A15: Colombia | C15: =IFERROR(B15/SUM($B$15:$B$16),0) -> 0
A16: Other Geographies | C16: =IFERROR(B16/SUM($B$15:$B$16),0) -> 0
A18: Otras geografías – país | B18: m² mes | C18: % del total OG | D18: Ranking
A19: Ecuador | B19: 8828 | C19: =IFERROR(B19/SUM($B$19:$B$23),0) -> 0.21965117 | D19: =RANK(B19,$B$19:$B$23) -> 3
A20: Others | B20: 6421 | C20: =IFERROR(B20/SUM($B$19:$B$23),0) -> 0.15976214 | D20: =RANK(B20,$B$19:$B$23) -> 4
A21: Republica Dominicana | B21: 15144 | C21: =IFERROR(B21/SUM($B$19:$B$23),0) -> 0.37680078 | D21: =RANK(B21,$B$19:$B$23) -> 1
A22: Venezuela | B22: 9798 | C22: =IFERROR(B22/SUM($B$19:$B$23),0) -> 0.24378592 | D22: =RANK(B22,$B$19:$B$23) -> 2
C23: =IFERROR(B23/SUM($B$19:$B$23),0) -> 0 | D23: =RANK(B23,$B$19:$B$23) -> #N/A
A24: Total | B24: =SUM(B19:B23) -> 40191 | C24: =SUM(C19:C23) -> 1
A26: Top pedidos del mes – Cliente | B26: Proyecto | C26: Canal | D26: Valor (USD mm, según deck)
A27: Envases Tropicales | B27: Cubierta Envases Tropicales | LTORR-02071 | C27: Other Geographies | D27: 306
A28: Industrial Nutricional Avícola | B28: Industria Nutricional Avícola | C28: Cold Storage | D28: 236
A29: C.C. Chipichape P.H. | B29: Recambio cubierta Chipichape – Bodega 04 | C29: Industrial | D29: 173

Sheet 02_OI
A1: 02 · Order Intake – Octuber
A2: Tabla por producto + progresión mensual de ingresos y margen
A4: Mes de corte (1-12) | B4: 9
A6: Producto / métrica | B6: Mes actual | C6: PY | D6: YoY mes | E6: YTD | F6: Prior YTD | G6: YoY YTD
A7: IMP – Volume (m²) | B7: 160547 | C7: 132786 | D7: =IF(OR(B7="",C7=""),"",IF(C7=0,"n.a.",B7/C7-1)) -> 0.20906571 | E7: 1400088 | F7: 112088 | G7: =IF(OR(E7="",F7=""),"",IF(F7=0,"n.a.",E7/F7-1)) -> 11.490971
A8: Kingcore – Volume (m²) | B8: 20793 | C8: 10126 | D8: =IF(OR(B8="",C8=""),"",IF(C8=0,"n.a.",B8/C8-1)) -> 1.0534268 | E8: 229903 | F8: 88736 | G8: =IF(OR(E8="",F8=""),"",IF(F8=0,"n.a.",E8/F8-1)) -> 1.590865
A9: Single Skin – Volume (m²) | B9: 16271 | C9: 13834 | D9: =IF(OR(B9="",C9=""),"",IF(C9=0,"n.a.",B9/C9-1)) -> 0.17616019 | E9: 122613 | F9: 52330 | G9: =IF(OR(E9="",F9=""),"",IF(F9=0,"n.a.",E9/F9-1)) -> 1.3430728
A10: Benchmark – Volume (m²) | B10: 7880 | C10: 0 | D10: =IF(OR(B10="",C10=""),"",IF(C10=0,"n.a.",B10/C10-1)) -> n.a. | E10: 5817 | F10: 563 | G10: =IF(OR(E10="",F10=""),"",IF(F10=0,"n.a.",E10/F10-1)) -> 9.3321492
A11: IMP – Revenue (COP MM) | B11: 14484 | C11: 12723 | D11: =IF(OR(B11="",C11=""),"",IF(C11=0,"n.a.",B11/C11-1)) -> 0.13841075 | E11: 144659 | F11: 108228 | G11: =IF(OR(E11="",F11=""),"",IF(F11=0,"n.a.",E11/F11-1)) -> 0.33661345
A12: Margen (Gross-STD) | B12: 0.27 | C12: 0.24 | D12: =IF(OR(B12="",C12=""),"",(B12-C12)*100) -> 3 | E12: 0.25 | F12: 0.24 | G12: =IF(OR(E12="",F12=""),"",(E12-F12)*100) -> 1
A14: N° mes | B14: Mes | C14: Ingresos CY (COP MM) | D14: Ingresos PY (COP MM) | E14: YoY | F14: Margen CY % | G14: Fuente gráfico: CY | H14: Fuente gráfico: PY
A15: 1 | B15: Jan | C15: 9968.166 | D15: 7958.8 | E15: =IF(OR(C15="",D15=""),"",IF(D15=0,"n.a.",C15/D15-1)) -> 0.25247098 | F15: 0.251 | G15: =IF(A15<=$B$4,C15,"") -> 9968.166 | H15: =D15 -> 7958.8
A16: 2 | B16: Feb | C16: 12767.714 | D16: 10536.7 | E16: =IF(OR(C16="",D16=""),"",IF(D16=0,"n.a.",C16/D16-1)) -> 0.21173745 | F16: 0.254 | G16: =IF(A16<=$B$4,C16,"") -> 12767.714 | H16: =D16 -> 10536.7
A17: 3 | B17: Mar | C17: 14462.925 | D17: 12471.2 | E17: =IF(OR(C17="",D17=""),"",IF(D17=0,"n.a.",C17/D17-1)) -> 0.15970596 | F17: 0.261 | G17: =IF(A17<=$B$4,C17,"") -> 14462.925 | H17: =D17 -> 12471.2
A18: 4 | B18: Apr | C18: 12270.448 | D18: 9577 | E18: =IF(OR(C18="",D18=""),"",IF(D18=0,"n.a.",C18/D18-1)) -> 0.28124131 | F18: 0.257 | G18: =IF(A18<=$B$4,C18,"") -> 12270.448 | H18: =D18 -> 9577
A19: 5 | B19: May | C19: 27093.858 | D19: 8092 | E19: =IF(OR(C19="",D19=""),"",IF(D19=0,"n.a.",C19/D19-1)) -> 2.3482276 | F19: 0.209 | G19: =IF(A19<=$B$4,C19,"") -> 27093.858 | H19: =D19 -> 8092
A20: 6 | B20: Jun | C20: 13652.194 | D20: 11810.8 | E20: =IF(OR(C20="",D20=""),"",IF(D20=0,"n.a.",C20/D20-1)) -> 0.15590764 | F20: 0.285 | G20: =IF(A20<=$B$4,C20,"") -> 13652.194 | H20: =D20 -> 11810.8
A21: 7 | B21: Jul | C21: 11718.909 | D21: 7612.5 | E21: =IF(OR(C21="",D21=""),"",IF(D21=0,"n.a.",C21/D21-1)) -> 0.53942975 | F21: 0.273 | G21: =IF(A21<=$B$4,C21,"") -> 11718.909 | H21: =D21 -> 7612.5
A22: 8 | B22: Aug | C22: 14500.72 | D22: 16772.6 | E22: =IF(OR(C22="",D22=""),"",IF(D22=0,"n.a.",C22/D22-1)) -> -0.13545187 | F22: 0.268 | G22: =IF(A22<=$B$4,C22,"") -> 14500.72 | H22: =D22 -> 16772.6
A23: 9 | B23: Sep | C23: 13740.67 | D23: 10673.6 | E23: =IF(OR(C23="",D23=""),"",IF(D23=0,"n.a.",C23/D23-1)) -> 0.28735103 | F23: 0.271 | G23: =IF(A23<=$B$4,C23,"") -> 13740.67 | H23: =D23 -> 10673.6
A24: 10 | B24: Oct | C24: 14484 | D24: 12723.1 | E24: =IF(OR(C24="",D24=""),"",IF(D24=0,"n.a.",C24/D24-1)) -> 0.1384018 | G24: =IF(A24<=$B$4,C24,"") | H24: =D24 -> 12723.1
A25: 11 | B25: Nov | D25: 12445.1 | E25: =IF(OR(C25="",D25=""),"",IF(D25=0,"n.a.",C25/D25-1)) | G25: =IF(A25<=$B$4,C25,"") | H25: =D25 -> 12445.1
A26: 12 | B26: Dec | D26: 10462.4 | E26: =IF(OR(C26="",D26=""),"",IF(D26=0,"n.a.",C26/D26-1)) | G26: =IF(A26<=$B$4,C26,"") | H26: =D26 -> 10462.4
B27: YTD | C27: =SUMIFS(C15:C26,A15:A26,"<="&$B$4) -> 130175.6 | D27: =SUMIFS(D15:D26,A15:A26,"<="&$B$4) -> 95505.2 | E27: =IF(OR(C27="",D27=""),"",IF(D27=0,"n.a.",C27/D27-1)) -> 0.36302111
B28: Control vs tabla | C28: =C27-E11 -> -14483.396

Sheet 03_OI_Canal
A1: 03 · Order Intake por canal (IMP)
A2: CM / PY / YoY / Gross Margin por canal · YTD y mix se alimentan de las hojas RSM (09–14) | G2: 157039 | H2: 160547 | I2: {=H2-G1:G2} -> 160547
I3: 3508
A4: Canal | B4: OI mes CM (m²) | C4: OI mes PY (m²) | D4: YoY mes | E4: GM % CM | F4: GM % PY | G4: Δ GM (pp) | H4: OI YTD m² (RSM) | I4: Mix YTD % | J4: Ventas YTD m² | K4: Budget YTD m² | L4: % Cumpl. ventas
A5: Industrial | B5: =62296-13276+3508 -> 52528 | C5: 40646 | D5: =IF(OR(B5="",C5=""),"",IF(C5=0,"n.a.",B5/C5-1)) -> 0.29232889 | E5: 0.3307481 | F5: 0.28692083 | G5: =IF(OR(E5="",F5=""),"",(E5-F5)*100) -> 4.3827271 | H5: ='09_RSM_Industrial'!C18 -> 430568 | I5: =IFERROR(H5/$H$11,0) -> 0.33926393 | J5: ='09_RSM_Industrial'!D18 -> 339588 | K5: ='09_RSM_Industrial'!E18 -> 443901.88 | L5: =IFERROR(J5/K5,0) -> 0.76500691
A6: Distribución | B6: 29274 | C6: 53212 | D6: =IF(OR(B6="",C6=""),"",IF(C6=0,"n.a.",B6/C6-1)) -> -0.44986093 | E6: 0.3307481 | F6: 0.2701004 | G6: =IF(OR(E6="",F6=""),"",(E6-F6)*100) -> 6.0647695 | H6: ='10_RSM_Distribucion'!C20 -> 236351 | I6: =IFERROR(H6/$H$11,0) -> 0.18623161 | J6: ='10_RSM_Distribucion'!D20 -> 227016 | K6: ='10_RSM_Distribucion'!E20 -> 248524 | L6: =IFERROR(J6/K6,0) -> 0.91345705
A7: Otras Geografías | B7: 55560 | C7: 36701 | D7: =IF(OR(B7="",C7=""),"",IF(C7=0,"n.a.",B7/C7-1)) -> 0.51385521 | E7: 0.16021742 | F7: 0.10427401 | G7: =IF(OR(E7="",F7=""),"",(E7-F7)*100) -> 5.5943403 | H7: ='11_RSM_Otras_Geo'!C20 -> 367237 | I7: =IFERROR(H7/$H$11,0) -> 0.28936258 | J7: ='11_RSM_Otras_Geo'!D20 -> 306076 | K7: ='11_RSM_Otras_Geo'!E20 -> 388113 | L7: =IFERROR(J7/K7,0) -> 0.78862599
A8: Cold Storage | B8: 10911 | C8: 0 | D8: =IF(OR(B8="",C8=""),"",IF(C8=0,"n.a.",B8/C8-1)) -> n.a. | E8: 0.28710517 | F8: 0.38680242 | G8: =IF(OR(E8="",F8=""),"",(E8-F8)*100) -> -9.9697257 | H8: ='12_RSM_Cold_Storage'!C20 -> 36425 | I8: =IFERROR(H8/$H$11,0) -> 0.028700899 | J8: ='12_RSM_Cold_Storage'!D20 -> 9191 | K8: ='12_RSM_Cold_Storage'!E20 -> 10000 | L8: =IFERROR(J8/K8,0) -> 0.9191
A9: Site Cali | B9: 6625 | C9: 0 | D9: =IF(OR(B9="",C9=""),"",IF(C9=0,"n.a.",B9/C9-1)) -> n.a. | E9: 0.35059275 | F9: 0 | G9: =IF(OR(E9="",F9=""),"",(E9-F9)*100) -> 35.059275 | H9: ='13_RSM_Site_Cali'!C20 -> 140132 | I9: =IFERROR(H9/$H$11,0) -> 0.11041632 | J9: ='13_RSM_Site_Cali'!D20 -> 106715 | K9: ='13_RSM_Site_Cali'!E20 -> 111456 | L9: =IFERROR(J9/K9,0) -> 0.95746303
A10: Ventas Alternativas | B10: 5649 | C10: 2669 | D10: =IF(OR(B10="",C10=""),"",IF(C10=0,"n.a.",B10/C10-1)) -> 1.116523 | E10: 0.41498837 | F10: 0.36956934 | G10: =IF(OR(E10="",F10=""),"",(E10-F10)*100) -> 4.5419035 | H10: ='14_RSM_Vtas_Alt'!C20 -> 58411 | I10: =IFERROR(H10/$H$11,0) -> 0.04602466 | J10: ='14_RSM_Vtas_Alt'!D20 -> 69430 | K10: ='14_RSM_Vtas_Alt'!E20 -> 45368 | L10: =IFERROR(J10/K10,0) -> 1.5303738
A11: TOTAL | B11: =IF(COUNT(B5:B10)=0,"",SUM(B5:B10)) -> 160547 | C11: =IF(COUNT(C5:C10)=0,"",SUM(C5:C10)) -> 133228 | D11: =IF(OR(B11="",C11=""),"",IF(C11=0,"n.a.",B11/C11-1)) -> 0.20505449 | G11: =IF(OR(E11="",F11=""),"",(E11-F11)*100) | H11: =IF(COUNT(H5:H10)=0,"",SUM(H5:H10)) -> 1269124 | I11: =SUM(I5:I10) -> 1 | J11: =IF(COUNT(J5:J10)=0,"",SUM(J5:J10)) -> 1058016 | K11: =IF(COUNT(K5:K10)=0,"",SUM(K5:K10)) -> 1247362.9 | L11: =IFERROR(J11/K11,0) -> 0.84820225
A12: Control: Σ CM canales vs OI IMP mes (hoja 02) | B12: =IF(B11="","Pendiente",B11-'02_OI'!B7) -> 0
A13: Control: OI YTD RSM vs OI YTD IMP (hoja 02) | C13: 114611 | H13: =H11-'02_OI'!E7 -> -130964
C14: =+C13-C11 -> -18617

Sheet 04_Backlog
A1: 04 · Backlog – Octuber
A2: Tabla por producto + progresión mensual del backlog (COP MM) y margen
A4: Producto / métrica | B4: Mes actual | C4: PY | D4: Δ vs PY | E4: 1 Ene 2026 | F4: Δ vs 1 Ene
A5: IMP – Volume (m²) | B5: 525529 | C5: 360246 | D5: =IF(OR(B5="",C5=""),"",IF(C5=0,"n.a.",B5/C5-1)) -> 0.45880593 | E5: 364496 | F5: =IF(OR(B5="",E5=""),"",IF(E5=0,"n.a.",B5/E5-1)) -> 0.44179634
A6: Kingcore – Volume (m²) | B6: 78432 | C6: 38588 | D6: =IF(OR(B6="",C6=""),"",IF(C6=0,"n.a.",B6/C6-1)) -> 1.032549 | E6: 22362 | F6: =IF(OR(B6="",E6=""),"",IF(E6=0,"n.a.",B6/E6-1)) -> 2.5073786
A7: Single Skin – Volume (m²) | B7: 57196 | C7: 21370 | D7: =IF(OR(B7="",C7=""),"",IF(C7=0,"n.a.",B7/C7-1)) -> 1.6764623 | E7: 21486 | F7: =IF(OR(B7="",E7=""),"",IF(E7=0,"n.a.",B7/E7-1)) -> 1.6620125
A8: Benchmark – Volume (m²) | B8: 12167 | C8: 894 | D8: =IF(OR(B8="",C8=""),"",IF(C8=0,"n.a.",B8/C8-1)) -> 12.60962 | E8: 349 | F8: =IF(OR(B8="",E8=""),"",IF(E8=0,"n.a.",B8/E8-1)) -> 33.862464
A9: IMP – Revenue (COP MM) | B9: 49836 | C9: 35225 | D9: =IF(OR(B9="",C9=""),"",IF(C9=0,"n.a.",B9/C9-1)) -> 0.41479063 | E9: 35477 | F9: =IF(OR(B9="",E9=""),"",IF(E9=0,"n.a.",B9/E9-1)) -> 0.4047411
A10: Margen (Std) | B10: 0.273 | C10: 0.25 | D10: =(B10-C10)*100 -> 2.3 | E10: 0.25 | F10: =(B10-E10)*100 -> 2.3
A11: Margen (Std) sin Canpack | B11: 0.277 | C11: 0.25 | D11: =(B11-C11)*100 -> 2.7 | E11: 0.25 | F11: =(B11-E11)*100 -> 2.7
A13: N° mes | B13: Mes | C13: Backlog CY (COP MM) | D13: Backlog PY (COP MM) | E13: YoY | F13: Margen CY %
A14: 1 | B14: Jan | C14: 35566.1 | D14: 30422.1 | E14: =IF(OR(C14="",D14=""),"",IF(D14=0,"n.a.",C14/D14-1)) -> 0.1690876 | F14: 0.251
A15: 2 | B15: Feb | C15: 36104.5 | D15: 31461.6 | E15: =IF(OR(C15="",D15=""),"",IF(D15=0,"n.a.",C15/D15-1)) -> 0.14757355 | F15: 0.254
A16: 3 | B16: Mar | C16: 39420.9 | D16: 36223.7 | E16: =IF(OR(C16="",D16=""),"",IF(D16=0,"n.a.",C16/D16-1)) -> 0.088262657 | F16: 0.259
A17: 4 | B17: Apr | C17: 38886.8 | D17: 34454.1 | E17: =IF(OR(C17="",D17=""),"",IF(D17=0,"n.a.",C17/D17-1)) -> 0.12865523 | F17: 0.253
A18: 5 | B18: May | C18: 55927.6 | D18: 31842.8 | E18: =IF(OR(C18="",D18=""),"",IF(D18=0,"n.a.",C18/D18-1)) -> 0.75636565 | F18: 0.226
A19: 6 | B19: Jun | C19: 56477.9 | D19: 33251.2 | E19: =IF(OR(C19="",D19=""),"",IF(D19=0,"n.a.",C19/D19-1)) -> 0.69852216 | F19: 0.239
A20: 7 | B20: Jul | C20: 57136.5 | D20: 30680.1 | E20: =IF(OR(C20="",D20=""),"",IF(D20=0,"n.a.",C20/D20-1)) -> 0.86233096 | F20: 0.241
A21: 8 | B21: Aug | C21: 51456.1 | D21: 34736.9 | E21: =IF(OR(C21="",D21=""),"",IF(D21=0,"n.a.",C21/D21-1)) -> 0.4813095 | F21: 0.241
A22: 9 | B22: Sep | C22: 50189 | D22: 33247.5 | E22: =IF(OR(C22="",D22=""),"",IF(D22=0,"n.a.",C22/D22-1)) -> 0.50955711 | F22: 0.273
A23: 10 | B23: Oct | C23: 49836 | D23: 35224.5 | E23: =IF(OR(C23="",D23=""),"",IF(D23=0,"n.a.",C23/D23-1)) -> 0.41481071
A24: 11 | B24: Nov | D24: 34456 | E24: =IF(OR(C24="",D24=""),"",IF(D24=0,"n.a.",C24/D24-1))
A25: 12 | B25: Dec | D25: 35476.9 | E25: =IF(OR(C25="",D25=""),"",IF(D25=0,"n.a.",C25/D25-1))

Sheet 05_Backlog_Canal
A1: 05 · Backlog por canal (IMP)
A2: CM se alimenta del backlog por RSM (hojas 09–14); PY y márgenes se diligencian | F2: 537065 | G2: 525529 | H2: =F2-G2 -> 11536
A4: Canal | B4: Backlog CM (m²) – RSM | C4: Backlog PY (m²) | D4: YoY | E4: GM % CM | F4: GM % PY | G4: Δ GM (pp) | H4: Mix % | I4: Backlog paneles | J4: Backlog otros
A5: Industrial | B5: =251984-11536 -> 240448 | C5: 170762.19 | D5: =IF(OR(B5="",C5=""),"",IF(C5=0,"n.a.",B5/C5-1)) -> 0.4080869 | E5: 0.33117136 | F5: 0.28692083 | G5: =IF(OR(E5="",F5=""),"",(E5-F5)*100) -> 4.425053 | H5: =IFERROR(B5/$B$11,0) -> 0.45753517 | I5: ='09_RSM_Industrial'!H18 -> 210755 | J5: ='09_RSM_Industrial'!I18 -> 1913
A6: Distribución | B6: 62499 | C6: 50628.625 | D6: =IF(OR(B6="",C6=""),"",IF(C6=0,"n.a.",B6/C6-1)) -> 0.23445976 | E6: 0.29966956 | F6: 0.2701004 | G6: =IF(OR(E6="",F6=""),"",(E6-F6)*100) -> 2.9569156 | H6: =IFERROR(B6/$B$11,0) -> 0.11892588 | I6: ='10_RSM_Distribucion'!H20 -> 62537 | J6: ='10_RSM_Distribucion'!I20 -> 1979
A7: Otras Geografías | B7: 166377 | C7: 121006.42 | D7: =IF(OR(B7="",C7=""),"",IF(C7=0,"n.a.",B7/C7-1)) -> 0.37494359 | E7: 0.14624363 | F7: 0.10427401 | G7: =IF(OR(E7="",F7=""),"",(E7-F7)*100) -> 4.1969622 | H7: =IFERROR(B7/$B$11,0) -> 0.31658957 | I7: ='11_RSM_Otras_Geo'!H20 -> 136132 | J7: ='11_RSM_Otras_Geo'!I20 -> 580
A8: Cold Storage | B8: 28642 | C8: 1127.0509 | D8: =IF(OR(B8="",C8=""),"",IF(C8=0,"n.a.",B8/C8-1)) -> 24.413226 | E8: 0.28058377 | F8: 0.38680242 | G8: =IF(OR(E8="",F8=""),"",(E8-F8)*100) -> -10.621865 | H8: =IFERROR(B8/$B$11,0) -> 0.054501274 | I8: ='12_RSM_Cold_Storage'!H20 -> 27233 | J8: ='12_RSM_Cold_Storage'!I20 -> 3202
A9: Site Cali | B9: 21774 | C9: 0 | D9: =IF(OR(B9="",C9=""),"",IF(C9=0,"n.a.",B9/C9-1)) -> n.a. | E9: 0.36773598 | F9: 0 | G9: =IF(OR(E9="",F9=""),"",(E9-F9)*100) -> 36.773598 | H9: =IFERROR(B9/$B$11,0) -> 0.041432538 | I9: ='13_RSM_Site_Cali'!H20 -> 34419 | J9: ='13_RSM_Site_Cali'!I20 -> 14946
A10: Ventas Alternativas | B10: 5789 | C10: 4309.7179 | D10: =IF(OR(B10="",C10=""),"",IF(C10=0,"n.a.",B10/C10-1)) -> 0.34324339 | E10: 0.45275886 | F10: 0.36956934 | G10: =IF(OR(E10="",F10=""),"",(E10-F10)*100) -> 8.3189517 | H10: =IFERROR(B10/$B$11,0) -> 0.011015567 | I10: ='14_RSM_Vtas_Alt'!H20 -> 6066 | J10: ='14_RSM_Vtas_Alt'!I20 -> 0
A11: TOTAL | B11: =SUM(B5:B10) -> 525529 | C11: =IF(COUNT(C5:C10)=0,"",SUM(C5:C10)) -> 347834 | D11: =IF(OR(B11="",C11=""),"",IF(C11=0,"n.a.",B11/C11-1)) -> 0.5108615 | G11: =IF(OR(E11="",F11=""),"",(E11-F11)*100) | H11: =SUM(H5:H10) -> 1 | I11: =SUM(I5:I10) -> 477142 | J11: =SUM(J5:J10) -> 22620
A12: Control: backlog RSM vs backlog IMP (hoja 04) | B12: =B11-'04_Backlog'!B5 -> 0

Sheet 06_Perf_Forecast
A1: 06 · Performed / Forecast OI 2026
A2: Real vs forecast mensual, acumulados, trimestres y comparativo vs PY
A4: Mes de corte (último mes real) | B4: 9
A6: N° mes | B6: Mes | C6: Trimestre | D6: Estado | E6: Volumen m² | F6: Ingresos COP MM | G6: Acum. volumen m² | H6: Acum. ingresos COP MM | I6: Fuente gráfico: Real | J6: Fuente gráfico: Forecast
A7: 1 | B7: Jan | C7: ="Q"&ROUNDUP(A7/3,0) -> Q1 | D7: =IF(A7<=$B$4,"Real","Forecast") -> Real | E7: 104582 | F7: 9968.166 | G7: =SUM($E$7:E7) -> 104582 | H7: =SUM($F$7:F7) -> 9968.166 | I7: =IF(D7="Real",E7,0) -> 104582 | J7: =IF(D7="Forecast",E7,0) -> 0
A8: 2 | B8: Feb | C8: ="Q"&ROUNDUP(A8/3,0) -> Q1 | D8: =IF(A8<=$B$4,"Real","Forecast") -> Real | E8: 127405 | F8: 12767.714 | G8: =SUM($E$7:E8) -> 231987 | H8: =SUM($F$7:F8) -> 22735.88 | I8: =IF(D8="Real",E8,0) -> 127405 | J8: =IF(D8="Forecast",E8,0) -> 0
A9: 3 | B9: Mar | C9: ="Q"&ROUNDUP(A9/3,0) -> Q1 | D9: =IF(A9<=$B$4,"Real","Forecast") -> Real | E9: 152049 | F9: 14462.925 | G9: =SUM($E$7:E9) -> 384036 | H9: =SUM($F$7:F9) -> 37198.805 | I9: =IF(D9="Real",E9,0) -> 152049 | J9: =IF(D9="Forecast",E9,0) -> 0
A10: 4 | B10: Apr | C10: ="Q"&ROUNDUP(A10/3,0) -> Q2 | D10: =IF(A10<=$B$4,"Real","Forecast") -> Real | E10: 126530 | F10: 12270.448 | G10: =SUM($E$7:E10) -> 510566 | H10: =SUM($F$7:F10) -> 49469.253 | I10: =IF(D10="Real",E10,0) -> 126530 | J10: =IF(D10="Forecast",E10,0) -> 0
A11: 5 | B11: May | C11: ="Q"&ROUNDUP(A11/3,0) -> Q2 | D11: =IF(A11<=$B$4,"Real","Forecast") -> Real | E11: 181126 | F11: 27093.858 | G11: =SUM($E$7:E11) -> 691692 | H11: =SUM($F$7:F11) -> 76563.111 | I11: =IF(D11="Real",E11,0) -> 181126 | J11: =IF(D11="Forecast",E11,0) -> 0
A12: 6 | B12: Jun | C12: ="Q"&ROUNDUP(A12/3,0) -> Q2 | D12: =IF(A12<=$B$4,"Real","Forecast") -> Real | E12: 124406 | F12: 12022.773 | G12: =SUM($E$7:E12) -> 816098 | H12: =SUM($F$7:F12) -> 88585.884 | I12: =IF(D12="Real",E12,0) -> 124406 | J12: =IF(D12="Forecast",E12,0) -> 0
A13: 7 | B13: Jul | C13: ="Q"&ROUNDUP(A13/3,0) -> Q3 | D13: =IF(A13<=$B$4,"Real","Forecast") -> Real | E13: 114336 | F13: 11718.909 | G13: =SUM($E$7:E13) -> 930434 | H13: =SUM($F$7:F13) -> 100304.79 | I13: =IF(D13="Real",E13,0) -> 114336 | J13: =IF(D13="Forecast",E13,0) -> 0
A14: 8 | B14: Aug | C14: ="Q"&ROUNDUP(A14/3,0) -> Q3 | D14: =IF(A14<=$B$4,"Real","Forecast") -> Real | E14: 151623 | F14: 14500.72 | G14: =SUM($E$7:E14) -> 1082057 | H14: =SUM($F$7:F14) -> 114805.51 | I14: =IF(D14="Real",E14,0) -> 151623 | J14: =IF(D14="Forecast",E14,0) -> 0
A15: 9 | B15: Sep | C15: ="Q"&ROUNDUP(A15/3,0) -> Q3 | D15: =IF(A15<=$B$4,"Real","Forecast") -> Real | E15: 146446 | F15: 13740.67 | G15: =SUM($E$7:E15) -> 1228503 | H15: =SUM($F$7:F15) -> 128546.18 | I15: =IF(D15="Real",E15,0) -> 146446 | J15: =IF(D15="Forecast",E15,0) -> 0
A16: 10 | B16: Oct | C16: ="Q"&ROUNDUP(A16/3,0) -> Q4 | D16: Real | E16: 160547 | F16: 14484 | G16: =SUM($E$7:E16) -> 1389050 | H16: =SUM($F$7:F16) -> 143030.18 | I16: =IF(D16="Real",E16,0) -> 160547 | J16: =IF(D16="Forecast",E16,0) -> 0
A17: 11 | B17: Nov | C17: ="Q"&ROUNDUP(A17/3,0) -> Q4 | D17: =IF(A17<=$B$4,"Real","Forecast") -> Forecast | E17: 140000 | F17: 15077.152 | G17: =SUM($E$7:E17) -> 1529050 | H17: =SUM($F$7:F17) -> 158107.34 | I17: =IF(D17="Real",E17,0) -> 0 | J17: =IF(D17="Forecast",E17,0) -> 140000
A18: 12 | B18: Dec | C18: ="Q"&ROUNDUP(A18/3,0) -> Q4 | D18: =IF(A18<=$B$4,"Real","Forecast") -> Forecast | E18: 122000 | F18: 13335.741 | G18: =SUM($E$7:E18) -> 1651050 | H18: =SUM($F$7:F18) -> 171443.08 | I18: =IF(D18="Real",E18,0) -> 0 | J18: =IF(D18="Forecast",E18,0) -> 122000
A20: Trimestre | E20: Volumen m² | F20: Ingresos COP MM
A21: Q1 | E21: =SUMIFS($E$7:$E$18,$C$7:$C$18,A21) -> 384036 | F21: =SUMIFS($F$7:$F$18,$C$7:$C$18,A21) -> 37198.805
A22: Q2 | E22: =SUMIFS($E$7:$E$18,$C$7:$C$18,A22) -> 432062 | F22: =SUMIFS($F$7:$F$18,$C$7:$C$18,A22) -> 51387.079
A23: Q3 | E23: =SUMIFS($E$7:$E$18,$C$7:$C$18,A23) -> 412405 | F23: =SUMIFS($F$7:$F$18,$C$7:$C$18,A23) -> 39960.299
A24: Q4 | E24: =SUMIFS($E$7:$E$18,$C$7:$C$18,A24) -> 422547 | F24: =SUMIFS($F$7:$F$18,$C$7:$C$18,A24) -> 42896.894
A26: Comparativo IMP | B26: 2026 (m²) | C26: 2025 PY (m²) | D26: YoY m² | E26: 2026 COP MM | F26: 2025 COP MM | G26: YoY COP | H26: GM 2026 | I26: GM 2025 | J26: Δ GM pp
A27: Mes actual (CM) | B27: 160547 | C27: 132619 | D27: =IF(OR(B27="",C27=""),"",IF(C27=0,"n.a.",B27/C27-1)) -> 0.21058823 | E27: 14484 | F27: 10674 | G27: =IF(OR(E27="",F27=""),"",IF(F27=0,"n.a.",E27/F27-1)) -> 0.3569421 | H27: 0.27 | I27: 0.24 | J27: =IF(OR(H27="",I27=""),"",(H27-I27)*100) -> 3
A28: YTD real | B28: 1400088 | C28: 1120898 | D28: =IF(OR(B28="",C28=""),"",IF(C28=0,"n.a.",B28/C28-1)) -> 0.24907708 | E28: =SUMIFS(F7:F18,A7:A18,"<="&$B$4) -> 128546.18 | F28: 95505 | G28: =IF(OR(E28="",F28=""),"",IF(F28=0,"n.a.",E28/F28-1)) -> 0.34596286 | H28: 0.25 | I28: 0.24 | J28: =IF(OR(H28="",I28=""),"",(H28-I28)*100) -> 1
A29: Forecast resto del año | B29: =SUMIFS(E7:E18,A7:A18,">"&$B$4) -> 422547 | C29: =C30-C28 -> 238943 | D29: =IF(OR(B29="",C29=""),"",IF(C29=0,"n.a.",B29/C29-1)) -> 0.76840083 | E29: =SUMIFS(F7:F18,A7:A18,">"&$B$4) -> 42896.894 | F29: =F30-F28 -> 35630.754 | G29: =IF(OR(E29="",F29=""),"",IF(F29=0,"n.a.",E29/F29-1)) -> 0.20392888 | J29: =IF(OR(H29="",I29=""),"",(H29-I29)*100)
A30: Cierre año (Real + Fcst) | B30: =SUM(E7:E18) -> 1651050 | C30: 1359841 | D30: =IF(OR(B30="",C30=""),"",IF(C30=0,"n.a.",B30/C30-1)) -> 0.2141493 | E30: =SUM(F7:F18) -> 171443.08 | F30: 131135.75 | G30: =IF(OR(E30="",F30=""),"",IF(F30=0,"n.a.",E30/F30-1)) -> 0.30737096 | J30: =IF(OR(H30="",I30=""),"",(H30-I30)*100)
A32: Avance vs cierre año (volumen) | B32: =B28/B30 -> 0.84799855

Sheet 07_Top_Opps
A1: 07 · Top Opportunities (pipeline abierto)
A2: Top 5 por segmento, automático desde la hoja Pipeline · criterio seleccionable
A4: Criterio de orden (cambiar en hoja Pipeline!C4): | E4: =Pipeline!C4 -> USD
A6: Industrial – Top 5 oportunidades abiertas
A7: # | B7: Cliente | C7: Proyecto | D7: País | E7: Portafolio (Type) | F7: Ejecutivo | G7: m² | H7: USD | I7: Estado | J7: % Cierre | K7: Fecha cierre | L7: Valor ponderado
A8: 1 | B8: =IFERROR(IF(INDEX(Pipeline!$B$7:$B$67,MATCH(LARGE(Pipeline!$M$7:$M$67,1),Pipeline!$M$7:$M$67,0))="","—",INDEX(Pipeline!$B$7:$B$67,MATCH(LARGE(Pipeline!$M$7:$M$67,1),Pipeline!$M$7:$M$67,0))),"") -> Construplan | C8: =IFERROR(IF(INDEX(Pipeline!$C$7:$C$67,MATCH(LARGE(Pipeline!$M$7:$M$67,1),Pipeline!$M$7:$M$67,0))="","—",INDEX(Pipeline!$C$7:$C$67,MATCH(LARGE(Pipeline!$M$7:$M$67,1),Pipeline!$M$7:$M$67,0))),"") -> Walmart | D8: =IFERROR(IF(INDEX(Pipeline!$E$7:$E$67,MATCH(LARGE(Pipeline!$M$7:$M$67,1),Pipeline!$M$7:$M$67,0))="","—",INDEX(Pipeline!$E$7:$E$67,MATCH(LARGE(Pipeline!$M$7:$M$67,1),Pipeline!$M$7:$M$67,0))),"") -> Guatemala | E8: =IFERROR(IF(INDEX(Pipeline!$F$7:$F$67,MATCH(LARGE(Pipeline!$M$7:$M$67,1),Pipeline!$M$7:$M$67,0))="","—",INDEX(Pipeline!$F$7:$F$67,MATCH(LARGE(Pipeline!$M$7:$M$67,1),Pipeline!$M$7:$M$67,0))),"") -> King Wall / King Frio / King Roof | F8: =IFERROR(IF(INDEX(Pipeline!$D$7:$D$67,MATCH(LARGE(Pipeline!$M$7:$M$67,1),Pipeline!$M$7:$M$67,0))="","—",INDEX(Pipeline!$D$7:$D$67,MATCH(LARGE(Pipeline!$M$7:$M$67,1),Pipeline!$M$7:$M$67,0))),"") -> Carlos Rodriguez | G8: =IFERROR(IF(INDEX(Pipeline!$G$7:$G$67,MATCH(LARGE(Pipeline!$M$7:$M$67,1),Pipeline!$M$7:$M$67,0))="","—",INDEX(Pipeline!$G$7:$G$67,MATCH(LARGE(Pipeline!$M$7:$M$67,1),Pipeline!$M$7:$M$67,0))),"") -> 100000 | H8: =IFERROR(IF(INDEX(Pipeline!$H$7:$H$67,MATCH(LARGE(Pipeline!$M$7:$M$67,1),Pipeline!$M$7:$M$67,0))="","—",INDEX(Pipeline!$H$7:$H$67,MATCH(LARGE(Pipeline!$M$7:$M$67,1),Pipeline!$M$7:$M$67,0))),"") -> 2787794 | I8: =IFERROR(IF(INDEX(Pipeline!$I$7:$I$67,MATCH(LARGE(Pipeline!$M$7:$M$67,1),Pipeline!$M$7:$M$67,0))="","—",INDEX(Pipeline!$I$7:$I$67,MATCH(LARGE(Pipeline!$M$7:$M$67,1),Pipeline!$M$7:$M$67,0))),"") -> Specification | J8: =IFERROR(IF(INDEX(Pipeline!$J$7:$J$67,MATCH(LARGE(Pipeline!$M$7:$M$67,1),Pipeline!$M$7:$M$67,0))="","—",INDEX(Pipeline!$J$7:$J$67,MATCH(LARGE(Pipeline!$M$7:$M$67,1),Pipeline!$M$7:$M$67,0))),"") -> 0.75 | K8: =IFERROR(IF(INDEX(Pipeline!$K$7:$K$67,MATCH(LARGE(Pipeline!$M$7:$M$67,1),Pipeline!$M$7:$M$67,0))="","—",INDEX(Pipeline!$K$7:$K$67,MATCH(LARGE(Pipeline!$M$7:$M$67,1),Pipeline!$M$7:$M$67,0))),"") -> Noviembre | L8: =IFERROR(IF(INDEX(Pipeline!$L$7:$L$67,MATCH(LARGE(Pipeline!$M$7:$M$67,1),Pipeline!$M$7:$M$67,0))="","—",INDEX(Pipeline!$L$7:$L$67,MATCH(LARGE(Pipeline!$M$7:$M$67,1),Pipeline!$M$7:$M$67,0))),"") -> 2090845.5
A9: 2 | B9: =IFERROR(IF(INDEX(Pipeline!$B$7:$B$67,MATCH(LARGE(Pipeline!$M$7:$M$67,2),Pipeline!$M$7:$M$67,0))="","—",INDEX(Pipeline!$B$7:$B$67,MATCH(LARGE(Pipeline!$M$7:$M$67,2),Pipeline!$M$7:$M$67,0))),"") -> Haceb | C9: =IFERROR(IF(INDEX(Pipeline!$C$7:$C$67,MATCH(LARGE(Pipeline!$M$7:$M$67,2),Pipeline!$M$7:$M$67,0))="","—",INDEX(Pipeline!$C$7:$C$67,MATCH(LARGE(Pipeline!$M$7:$M$67,2),Pipeline!$M$7:$M$67,0))),"") -> Recambio | D9: =IFERROR(IF(INDEX(Pipeline!$E$7:$E$67,MATCH(LARGE(Pipeline!$M$7:$M$67,2),Pipeline!$M$7:$M$67,0))="","—",INDEX(Pipeline!$E$7:$E$67,MATCH(LARGE(Pipeline!$M$7:$M$67,2),Pipeline!$M$7:$M$67,0))),"") -> Colombia | E9: =IFERROR(IF(INDEX(Pipeline!$F$7:$F$67,MATCH(LARGE(Pipeline!$M$7:$M$67,2),Pipeline!$M$7:$M$67,0))="","—",INDEX(Pipeline!$F$7:$F$67,MATCH(LARGE(Pipeline!$M$7:$M$67,2),Pipeline!$M$7:$M$67,0))),"") -> KingWall / KingRoof | F9: =IFERROR(IF(INDEX(Pipeline!$D$7:$D$67,MATCH(LARGE(Pipeline!$M$7:$M$67,2),Pipeline!$M$7:$M$67,0))="","—",INDEX(Pipeline!$D$7:$D$67,MATCH(LARGE(Pipeline!$M$7:$M$67,2),Pipeline!$M$7:$M$67,0))),"") -> Ana Arias | G9: 61000 | H9: 1694102 | I9: =IFERROR(IF(INDEX(Pipeline!$I$7:$I$67,MATCH(LARGE(Pipeline!$M$7:$M$67,2),Pipeline!$M$7:$M$67,0))="","—",INDEX(Pipeline!$I$7:$I$67,MATCH(LARGE(Pipeline!$M$7:$M$67,2),Pipeline!$M$7:$M$67,0))),"") -> Pending | J9: =IFERROR(IF(INDEX(Pipeline!$J$7:$J$67,MATCH(LARGE(Pipeline!$M$7:$M$67,2),Pipeline!$M$7:$M$67,0))="","—",INDEX(Pipeline!$J$7:$J$67,MATCH(LARGE(Pipeline!$M$7:$M$67,2),Pipeline!$M$7:$M$67,0))),"") -> 0.8 | K9: =IFERROR(IF(INDEX(Pipeline!$K$7:$K$67,MATCH(LARGE(Pipeline!$M$7:$M$67,2),Pipeline!$M$7:$M$67,0))="","—",INDEX(Pipeline!$K$7:$K$67,MATCH(LARGE(Pipeline!$M$7:$M$67,2),Pipeline!$M$7:$M$67,0))),"") -> Noviembre | L9: =IFERROR(IF(INDEX(Pipeline!$L$7:$L$67,MATCH(LARGE(Pipeline!$M$7:$M$67,2),Pipeline!$M$7:$M$67,0))="","—",INDEX(Pipeline!$L$7:$L$67,MATCH(LARGE(Pipeline!$M$7:$M$67,2),Pipeline!$M$7:$M$67,0))),"") -> 1360404
A10: 3 | B10: =IFERROR(IF(INDEX(Pipeline!$B$7:$B$67,MATCH(LARGE(Pipeline!$M$7:$M$67,3),Pipeline!$M$7:$M$67,0))="","—",INDEX(Pipeline!$B$7:$B$67,MATCH(LARGE(Pipeline!$M$7:$M$67,3),Pipeline!$M$7:$M$67,0))),"") -> Ménsula / Conconcreto | C10: =IFERROR(IF(INDEX(Pipeline!$C$7:$C$67,MATCH(LARGE(Pipeline!$M$7:$M$67,3),Pipeline!$M$7:$M$67,0))="","—",INDEX(Pipeline!$C$7:$C$67,MATCH(LARGE(Pipeline!$M$7:$M$67,3),Pipeline!$M$7:$M$67,0))),"") -> Viva Suba / Claro | D10: =IFERROR(IF(INDEX(Pipeline!$E$7:$E$67,MATCH(LARGE(Pipeline!$M$7:$M$67,3),Pipeline!$M$7:$M$67,0))="","—",INDEX(Pipeline!$E$7:$E$67,MATCH(LARGE(Pipeline!$M$7:$M$67,3),Pipeline!$M$7:$M$67,0))),"") -> Colombia | E10: =IFERROR(IF(INDEX(Pipeline!$F$7:$F$67,MATCH(LARGE(Pipeline!$M$7:$M$67,3),Pipeline!$M$7:$M$67,0))="","—",INDEX(Pipeline!$F$7:$F$67,MATCH(LARGE(Pipeline!$M$7:$M$67,3),Pipeline!$M$7:$M$67,0))),"") -> KingRoof / Benchmark | F10: =IFERROR(IF(INDEX(Pipeline!$D$7:$D$67,MATCH(LARGE(Pipeline!$M$7:$M$67,3),Pipeline!$M$7:$M$67,0))="","—",INDEX(Pipeline!$D$7:$D$67,MATCH(LARGE(Pipeline!$M$7:$M$67,3),Pipeline!$M$7:$M$67,0))),"") -> Ana Arias | G10: =IFERROR(IF(INDEX(Pipeline!$G$7:$G$67,MATCH(LARGE(Pipeline!$M$7:$M$67,3),Pipeline!$M$7:$M$67,0))="","—",INDEX(Pipeline!$G$7:$G$67,MATCH(LARGE(Pipeline!$M$7:$M$67,3),Pipeline!$M$7:$M$67,0))),"") -> 10289 | H10: =IFERROR(IF(INDEX(Pipeline!$H$7:$H$67,MATCH(LARGE(Pipeline!$M$7:$M$67,3),Pipeline!$M$7:$M$67,0))="","—",INDEX(Pipeline!$H$7:$H$67,MATCH(LARGE(Pipeline!$M$7:$M$67,3),Pipeline!$M$7:$M$67,0))),"") -> 1600000 | I10: =IFERROR(IF(INDEX(Pipeline!$I$7:$I$67,MATCH(LARGE(Pipeline!$M$7:$M$67,3),Pipeline!$M$7:$M$67,0))="","—",INDEX(Pipeline!$I$7:$I$67,MATCH(LARGE(Pipeline!$M$7:$M$67,3),Pipeline!$M$7:$M$67,0))),"") -> Pending | J10: =IFERROR(IF(INDEX(Pipeline!$J$7:$J$67,MATCH(LARGE(Pipeline!$M$7:$M$67,3),Pipeline!$M$7:$M$67,0))="","—",INDEX(Pipeline!$J$7:$J$67,MATCH(LARGE(Pipeline!$M$7:$M$67,3),Pipeline!$M$7:$M$67,0))),"") -> — | K10: =IFERROR(IF(INDEX(Pipeline!$K$7:$K$67,MATCH(LARGE(Pipeline!$M$7:$M$67,3),Pipeline!$M$7:$M$67,0))="","—",INDEX(Pipeline!$K$7:$K$67,MATCH(LARGE(Pipeline!$M$7:$M$67,3),Pipeline!$M$7:$M$67,0))),"") -> — | L10: =IFERROR(IF(INDEX(Pipeline!$L$7:$L$67,MATCH(LARGE(Pipeline!$M$7:$M$67,3),Pipeline!$M$7:$M$67,0))="","—",INDEX(Pipeline!$L$7:$L$67,MATCH(LARGE(Pipeline!$M$7:$M$67,3),Pipeline!$M$7:$M$67,0))),"") -> —
A11: 4 | B11: =IFERROR(IF(INDEX(Pipeline!$B$7:$B$67,MATCH(LARGE(Pipeline!$M$7:$M$67,4),Pipeline!$M$7:$M$67,0))="","—",INDEX(Pipeline!$B$7:$B$67,MATCH(LARGE(Pipeline!$M$7:$M$67,4),Pipeline!$M$7:$M$67,0))),"") -> Imbert Dominguez | C11: =IFERROR(IF(INDEX(Pipeline!$C$7:$C$67,MATCH(LARGE(Pipeline!$M$7:$M$67,4),Pipeline!$M$7:$M$67,0))="","—",INDEX(Pipeline!$C$7:$C$67,MATCH(LARGE(Pipeline!$M$7:$M$67,4),Pipeline!$M$7:$M$67,0))),"") -> INDAL-IDA | D11: =IFERROR(IF(INDEX(Pipeline!$E$7:$E$67,MATCH(LARGE(Pipeline!$M$7:$M$67,4),Pipeline!$M$7:$M$67,0))="","—",INDEX(Pipeline!$E$7:$E$67,MATCH(LARGE(Pipeline!$M$7:$M$67,4),Pipeline!$M$7:$M$67,0))),"") -> Dominicana | E11: =IFERROR(IF(INDEX(Pipeline!$F$7:$F$67,MATCH(LARGE(Pipeline!$M$7:$M$67,4),Pipeline!$M$7:$M$67,0))="","—",INDEX(Pipeline!$F$7:$F$67,MATCH(LARGE(Pipeline!$M$7:$M$67,4),Pipeline!$M$7:$M$67,0))),"") -> KingRoof / KingWall / KingFrigo | F11: =IFERROR(IF(INDEX(Pipeline!$D$7:$D$67,MATCH(LARGE(Pipeline!$M$7:$M$67,4),Pipeline!$M$7:$M$67,0))="","—",INDEX(Pipeline!$D$7:$D$67,MATCH(LARGE(Pipeline!$M$7:$M$67,4),Pipeline!$M$7:$M$67,0))),"") -> Laura Torres | G11: =IFERROR(IF(INDEX(Pipeline!$G$7:$G$67,MATCH(LARGE(Pipeline!$M$7:$M$67,4),Pipeline!$M$7:$M$67,0))="","—",INDEX(Pipeline!$G$7:$G$67,MATCH(LARGE(Pipeline!$M$7:$M$67,4),Pipeline!$M$7:$M$67,0))),"") -> 50000 | H11: =IFERROR(IF(INDEX(Pipeline!$H$7:$H$67,MATCH(LARGE(Pipeline!$M$7:$M$67,4),Pipeline!$M$7:$M$67,0))="","—",INDEX(Pipeline!$H$7:$H$67,MATCH(LARGE(Pipeline!$M$7:$M$67,4),Pipeline!$M$7:$M$67,0))),"") -> 1550000 | I11: =IFERROR(IF(INDEX(Pipeline!$I$7:$I$67,MATCH(LARGE(Pipeline!$M$7:$M$67,4),Pipeline!$M$7:$M$67,0))="","—",INDEX(Pipeline!$I$7:$I$67,MATCH(LARGE(Pipeline!$M$7:$M$67,4),Pipeline!$M$7:$M$67,0))),"") -> Pending | J11: =IFERROR(IF(INDEX(Pipeline!$J$7:$J$67,MATCH(LARGE(Pipeline!$M$7:$M$67,4),Pipeline!$M$7:$M$67,0))="","—",INDEX(Pipeline!$J$7:$J$67,MATCH(LARGE(Pipeline!$M$7:$M$67,4),Pipeline!$M$7:$M$67,0))),"") -> 0.75 | K11: =IFERROR(IF(INDEX(Pipeline!$K$7:$K$67,MATCH(LARGE(Pipeline!$M$7:$M$67,4),Pipeline!$M$7:$M$67,0))="","—",INDEX(Pipeline!$K$7:$K$67,MATCH(LARGE(Pipeline!$M$7:$M$67,4),Pipeline!$M$7:$M$67,0))),"") -> Noviembre | L11: =IFERROR(IF(INDEX(Pipeline!$L$7:$L$67,MATCH(LARGE(Pipeline!$M$7:$M$67,4),Pipeline!$M$7:$M$67,0))="","—",INDEX(Pipeline!$L$7:$L$67,MATCH(LARGE(Pipeline!$M$7:$M$67,4),Pipeline!$M$7:$M$67,0))),"") -> 1162500
A12: 5 | B12: =IFERROR(IF(INDEX(Pipeline!$B$7:$B$67,MATCH(LARGE(Pipeline!$M$7:$M$67,5),Pipeline!$M$7:$M$67,0))="","—",INDEX(Pipeline!$B$7:$B$67,MATCH(LARGE(Pipeline!$M$7:$M$67,5),Pipeline!$M$7:$M$67,0))),"") -> Scadia | C12: =IFERROR(IF(INDEX(Pipeline!$C$7:$C$67,MATCH(LARGE(Pipeline!$M$7:$M$67,5),Pipeline!$M$7:$M$67,0))="","—",INDEX(Pipeline!$C$7:$C$67,MATCH(LARGE(Pipeline!$M$7:$M$67,5),Pipeline!$M$7:$M$67,0))),"") -> Angar Avianca (Bogotá) | D12: =IFERROR(IF(INDEX(Pipeline!$E$7:$E$67,MATCH(LARGE(Pipeline!$M$7:$M$67,5),Pipeline!$M$7:$M$67,0))="","—",INDEX(Pipeline!$E$7:$E$67,MATCH(LARGE(Pipeline!$M$7:$M$67,5),Pipeline!$M$7:$M$67,0))),"") -> Colombia | E12: =IFERROR(IF(INDEX(Pipeline!$F$7:$F$67,MATCH(LARGE(Pipeline!$M$7:$M$67,5),Pipeline!$M$7:$M$67,0))="","—",INDEX(Pipeline!$F$7:$F$67,MATCH(LARGE(Pipeline!$M$7:$M$67,5),Pipeline!$M$7:$M$67,0))),"") -> KingWall / KingRoof o SS | F12: =IFERROR(IF(INDEX(Pipeline!$D$7:$D$67,MATCH(LARGE(Pipeline!$M$7:$M$67,5),Pipeline!$M$7:$M$67,0))="","—",INDEX(Pipeline!$D$7:$D$67,MATCH(LARGE(Pipeline!$M$7:$M$67,5),Pipeline!$M$7:$M$67,0))),"") -> Julio Guerrero | G12: =IFERROR(IF(INDEX(Pipeline!$G$7:$G$67,MATCH(LARGE(Pipeline!$M$7:$M$67,5),Pipeline!$M$7:$M$67,0))="","—",INDEX(Pipeline!$G$7:$G$67,MATCH(LARGE(Pipeline!$M$7:$M$67,5),Pipeline!$M$7:$M$67,0))),"") -> 13000 | H12: =IFERROR(IF(INDEX(Pipeline!$H$7:$H$67,MATCH(LARGE(Pipeline!$M$7:$M$67,5),Pipeline!$M$7:$M$67,0))="","—",INDEX(Pipeline!$H$7:$H$67,MATCH(LARGE(Pipeline!$M$7:$M$67,5),Pipeline!$M$7:$M$67,0))),"") -> 1203774 | I12: =IFERROR(IF(INDEX(Pipeline!$I$7:$I$67,MATCH(LARGE(Pipeline!$M$7:$M$67,5),Pipeline!$M$7:$M$67,0))="","—",INDEX(Pipeline!$I$7:$I$67,MATCH(LARGE(Pipeline!$M$7:$M$67,5),Pipeline!$M$7:$M$67,0))),"") -> Pending | J12: =IFERROR(IF(INDEX(Pipeline!$J$7:$J$67,MATCH(LARGE(Pipeline!$M$7:$M$67,5),Pipeline!$M$7:$M$67,0))="","—",INDEX(Pipeline!$J$7:$J$67,MATCH(LARGE(Pipeline!$M$7:$M$67,5),Pipeline!$M$7:$M$67,0))),"") -> 0.6 | K12: =IFERROR(IF(INDEX(Pipeline!$K$7:$K$67,MATCH(LARGE(Pipeline!$M$7:$M$67,5),Pipeline!$M$7:$M$67,0))="","—",INDEX(Pipeline!$K$7:$K$67,MATCH(LARGE(Pipeline!$M$7:$M$67,5),Pipeline!$M$7:$M$67,0))),"") -> Diciembre | L12: =IFERROR(IF(INDEX(Pipeline!$L$7:$L$67,MATCH(LARGE(Pipeline!$M$7:$M$67,5),Pipeline!$M$7:$M$67,0))="","—",INDEX(Pipeline!$L$7:$L$67,MATCH(LARGE(Pipeline!$M$7:$M$67,5),Pipeline!$M$7:$M$67,0))),"") -> 722264.4
B13: Total Top 5 | G13: =SUM(G8:G12) -> 234289 | H13: =SUM(H8:H12) -> 8835670
A15: Distribución – Top 5 oportunidades abiertas
A16: # | B16: Cliente | C16: Proyecto | D16: País | E16: Portafolio (Type) | F16: Ejecutivo | G16: m² | H16: USD | I16: Estado | J16: % Cierre | K16: Fecha cierre | L16: Valor ponderado
A17: 1 | B17: =IFERROR(IF(INDEX(Pipeline!$B$7:$B$67,MATCH(LARGE(Pipeline!$N$7:$N$67,1),Pipeline!$N$7:$N$67,0))="","—",INDEX(Pipeline!$B$7:$B$67,MATCH(LARGE(Pipeline!$N$7:$N$67,1),Pipeline!$N$7:$N$67,0))),"") -> Galvaceros | C17: =IFERROR(IF(INDEX(Pipeline!$C$7:$C$67,MATCH(LARGE(Pipeline!$N$7:$N$67,1),Pipeline!$N$7:$N$67,0))="","—",INDEX(Pipeline!$C$7:$C$67,MATCH(LARGE(Pipeline!$N$7:$N$67,1),Pipeline!$N$7:$N$67,0))),"") -> Panandina Data Center | D17: =IFERROR(IF(INDEX(Pipeline!$E$7:$E$67,MATCH(LARGE(Pipeline!$N$7:$N$67,1),Pipeline!$N$7:$N$67,0))="","—",INDEX(Pipeline!$E$7:$E$67,MATCH(LARGE(Pipeline!$N$7:$N$67,1),Pipeline!$N$7:$N$67,0))),"") -> Colombia | E17: =IFERROR(IF(INDEX(Pipeline!$F$7:$F$67,MATCH(LARGE(Pipeline!$N$7:$N$67,1),Pipeline!$N$7:$N$67,0))="","—",INDEX(Pipeline!$F$7:$F$67,MATCH(LARGE(Pipeline!$N$7:$N$67,1),Pipeline!$N$7:$N$67,0))),"") -> KingRoof / KingWall LMR | F17: =IFERROR(IF(INDEX(Pipeline!$D$7:$D$67,MATCH(LARGE(Pipeline!$N$7:$N$67,1),Pipeline!$N$7:$N$67,0))="","—",INDEX(Pipeline!$D$7:$D$67,MATCH(LARGE(Pipeline!$N$7:$N$67,1),Pipeline!$N$7:$N$67,0))),"") -> Joana Perez | G17: =IFERROR(IF(INDEX(Pipeline!$G$7:$G$67,MATCH(LARGE(Pipeline!$N$7:$N$67,1),Pipeline!$N$7:$N$67,0))="","—",INDEX(Pipeline!$G$7:$G$67,MATCH(LARGE(Pipeline!$N$7:$N$67,1),Pipeline!$N$7:$N$67,0))),"") -> 4106 | H17: =IFERROR(IF(INDEX(Pipeline!$H$7:$H$67,MATCH(LARGE(Pipeline!$N$7:$N$67,1),Pipeline!$N$7:$N$67,0))="","—",INDEX(Pipeline!$H$7:$H$67,MATCH(LARGE(Pipeline!$N$7:$N$67,1),Pipeline!$N$7:$N$67,0))),"") -> 494712 | I17: Closed | J17: 1 | K17: =IFERROR(IF(INDEX(Pipeline!$K$7:$K$67,MATCH(LARGE(Pipeline!$N$7:$N$67,1),Pipeline!$N$7:$N$67,0))="","—",INDEX(Pipeline!$K$7:$K$67,MATCH(LARGE(Pipeline!$N$7:$N$67,1),Pipeline!$N$7:$N$67,0))),"") -> Diciembre | L17: =IFERROR(IF(INDEX(Pipeline!$L$7:$L$67,MATCH(LARGE(Pipeline!$N$7:$N$67,1),Pipeline!$N$7:$N$67,0))="","—",INDEX(Pipeline!$L$7:$L$67,MATCH(LARGE(Pipeline!$N$7:$N$67,1),Pipeline!$N$7:$N$67,0))),"") -> 420505.2
A18: 2 | B18: =IFERROR(IF(INDEX(Pipeline!$B$7:$B$67,MATCH(LARGE(Pipeline!$N$7:$N$67,2),Pipeline!$N$7:$N$67,0))="","—",INDEX(Pipeline!$B$7:$B$67,MATCH(LARGE(Pipeline!$N$7:$N$67,2),Pipeline!$N$7:$N$67,0))),"") -> Colcover | C18: =IFERROR(IF(INDEX(Pipeline!$C$7:$C$67,MATCH(LARGE(Pipeline!$N$7:$N$67,2),Pipeline!$N$7:$N$67,0))="","—",INDEX(Pipeline!$C$7:$C$67,MATCH(LARGE(Pipeline!$N$7:$N$67,2),Pipeline!$N$7:$N$67,0))),"") -> Proyecto | D18: =IFERROR(IF(INDEX(Pipeline!$E$7:$E$67,MATCH(LARGE(Pipeline!$N$7:$N$67,2),Pipeline!$N$7:$N$67,0))="","—",INDEX(Pipeline!$E$7:$E$67,MATCH(LARGE(Pipeline!$N$7:$N$67,2),Pipeline!$N$7:$N$67,0))),"") -> Colombia | E18: =IFERROR(IF(INDEX(Pipeline!$F$7:$F$67,MATCH(LARGE(Pipeline!$N$7:$N$67,2),Pipeline!$N$7:$N$67,0))="","—",INDEX(Pipeline!$F$7:$F$67,MATCH(LARGE(Pipeline!$N$7:$N$67,2),Pipeline!$N$7:$N$67,0))),"") -> KingRoof | F18: =IFERROR(IF(INDEX(Pipeline!$D$7:$D$67,MATCH(LARGE(Pipeline!$N$7:$N$67,2),Pipeline!$N$7:$N$67,0))="","—",INDEX(Pipeline!$D$7:$D$67,MATCH(LARGE(Pipeline!$N$7:$N$67,2),Pipeline!$N$7:$N$67,0))),"") -> Henry Acosta | G18: =IFERROR(IF(INDEX(Pipeline!$G$7:$G$67,MATCH(LARGE(Pipeline!$N$7:$N$67,2),Pipeline!$N$7:$N$67,0))="","—",INDEX(Pipeline!$G$7:$G$67,MATCH(LARGE(Pipeline!$N$7:$N$67,2),Pipeline!$N$7:$N$67,0))),"") -> 21528 | H18: =IFERROR(IF(INDEX(Pipeline!$H$7:$H$67,MATCH(LARGE(Pipeline!$N$7:$N$67,2),Pipeline!$N$7:$N$67,0))="","—",INDEX(Pipeline!$H$7:$H$67,MATCH(LARGE(Pipeline!$N$7:$N$67,2),Pipeline!$N$7:$N$67,0))),"") -> 411564.71 | I18: =IFERROR(IF(INDEX(Pipeline!$I$7:$I$67,MATCH(LARGE(Pipeline!$N$7:$N$67,2),Pipeline!$N$7:$N$67,0))="","—",INDEX(Pipeline!$I$7:$I$67,MATCH(LARGE(Pipeline!$N$7:$N$67,2),Pipeline!$N$7:$N$67,0))),"") -> Pending | J18: =IFERROR(IF(INDEX(Pipeline!$J$7:$J$67,MATCH(LARGE(Pipeline!$N$7:$N$67,2),Pipeline!$N$7:$N$67,0))="","—",INDEX(Pipeline!$J$7:$J$67,MATCH(LARGE(Pipeline!$N$7:$N$67,2),Pipeline!$N$7:$N$67,0))),"") -> 0.8 | K18: =IFERROR(IF(INDEX(Pipeline!$K$7:$K$67,MATCH(LARGE(Pipeline!$N$7:$N$67,2),Pipeline!$N$7:$N$67,0))="","—",INDEX(Pipeline!$K$7:$K$67,MATCH(LARGE(Pipeline!$N$7:$N$67,2),Pipeline!$N$7:$N$67,0))),"") -> Noviembre | L18: =IFERROR(IF(INDEX(Pipeline!$L$7:$L$67,MATCH(LARGE(Pipeline!$N$7:$N$67,2),Pipeline!$N$7:$N$67,0))="","—",INDEX(Pipeline!$L$7:$L$67,MATCH(LARGE(Pipeline!$N$7:$N$67,2),Pipeline!$N$7:$N$67,0))),"") -> 329251.77
A19: 3 | B19: =IFERROR(IF(INDEX(Pipeline!$B$7:$B$67,MATCH(LARGE(Pipeline!$N$7:$N$67,3),Pipeline!$N$7:$N$67,0))="","—",INDEX(Pipeline!$B$7:$B$67,MATCH(LARGE(Pipeline!$N$7:$N$67,3),Pipeline!$N$7:$N$67,0))),"") -> CIA Caribe Mar | C19: =IFERROR(IF(INDEX(Pipeline!$C$7:$C$67,MATCH(LARGE(Pipeline!$N$7:$N$67,3),Pipeline!$N$7:$N$67,0))="","—",INDEX(Pipeline!$C$7:$C$67,MATCH(LARGE(Pipeline!$N$7:$N$67,3),Pipeline!$N$7:$N$67,0))),"") -> Antártica | D19: =IFERROR(IF(INDEX(Pipeline!$E$7:$E$67,MATCH(LARGE(Pipeline!$N$7:$N$67,3),Pipeline!$N$7:$N$67,0))="","—",INDEX(Pipeline!$E$7:$E$67,MATCH(LARGE(Pipeline!$N$7:$N$67,3),Pipeline!$N$7:$N$67,0))),"") -> Venezuela | E19: =IFERROR(IF(INDEX(Pipeline!$F$7:$F$67,MATCH(LARGE(Pipeline!$N$7:$N$67,3),Pipeline!$N$7:$N$67,0))="","—",INDEX(Pipeline!$F$7:$F$67,MATCH(LARGE(Pipeline!$N$7:$N$67,3),Pipeline!$N$7:$N$67,0))),"") -> KingFrigo | F19: =IFERROR(IF(INDEX(Pipeline!$D$7:$D$67,MATCH(LARGE(Pipeline!$N$7:$N$67,3),Pipeline!$N$7:$N$67,0))="","—",INDEX(Pipeline!$D$7:$D$67,MATCH(LARGE(Pipeline!$N$7:$N$67,3),Pipeline!$N$7:$N$67,0))),"") -> María Yelitza Calderón | G19: =IFERROR(IF(INDEX(Pipeline!$G$7:$G$67,MATCH(LARGE(Pipeline!$N$7:$N$67,3),Pipeline!$N$7:$N$67,0))="","—",INDEX(Pipeline!$G$7:$G$67,MATCH(LARGE(Pipeline!$N$7:$N$67,3),Pipeline!$N$7:$N$67,0))),"") -> 12000 | H19: =IFERROR(IF(INDEX(Pipeline!$H$7:$H$67,MATCH(LARGE(Pipeline!$N$7:$N$67,3),Pipeline!$N$7:$N$67,0))="","—",INDEX(Pipeline!$H$7:$H$67,MATCH(LARGE(Pipeline!$N$7:$N$67,3),Pipeline!$N$7:$N$67,0))),"") -> 360000 | I19: =IFERROR(IF(INDEX(Pipeline!$I$7:$I$67,MATCH(LARGE(Pipeline!$N$7:$N$67,3),Pipeline!$N$7:$N$67,0))="","—",INDEX(Pipeline!$I$7:$I$67,MATCH(LARGE(Pipeline!$N$7:$N$67,3),Pipeline!$N$7:$N$67,0))),"") -> Specification | J19: =IFERROR(IF(INDEX(Pipeline!$J$7:$J$67,MATCH(LARGE(Pipeline!$N$7:$N$67,3),Pipeline!$N$7:$N$67,0))="","—",INDEX(Pipeline!$J$7:$J$67,MATCH(LARGE(Pipeline!$N$7:$N$67,3),Pipeline!$N$7:$N$67,0))),"") -> 0.9 | K19: =IFERROR(IF(INDEX(Pipeline!$K$7:$K$67,MATCH(LARGE(Pipeline!$N$7:$N$67,3),Pipeline!$N$7:$N$67,0))="","—",INDEX(Pipeline!$K$7:$K$67,MATCH(LARGE(Pipeline!$N$7:$N$67,3),Pipeline!$N$7:$N$67,0))),"") -> Noviembre | L19: =IFERROR(IF(INDEX(Pipeline!$L$7:$L$67,MATCH(LARGE(Pipeline!$N$7:$N$67,3),Pipeline!$N$7:$N$67,0))="","—",INDEX(Pipeline!$L$7:$L$67,MATCH(LARGE(Pipeline!$N$7:$N$67,3),Pipeline!$N$7:$N$67,0))),"") -> 324000
A20: 4 | B20: =IFERROR(IF(INDEX(Pipeline!$B$7:$B$67,MATCH(LARGE(Pipeline!$N$7:$N$67,4),Pipeline!$N$7:$N$67,0))="","—",INDEX(Pipeline!$B$7:$B$67,MATCH(LARGE(Pipeline!$N$7:$N$67,4),Pipeline!$N$7:$N$67,0))),"") -> Galvaceros | C20: =IFERROR(IF(INDEX(Pipeline!$C$7:$C$67,MATCH(LARGE(Pipeline!$N$7:$N$67,4),Pipeline!$N$7:$N$67,0))="","—",INDEX(Pipeline!$C$7:$C$67,MATCH(LARGE(Pipeline!$N$7:$N$67,4),Pipeline!$N$7:$N$67,0))),"") -> Colegios Sucre | D20: =IFERROR(IF(INDEX(Pipeline!$E$7:$E$67,MATCH(LARGE(Pipeline!$N$7:$N$67,4),Pipeline!$N$7:$N$67,0))="","—",INDEX(Pipeline!$E$7:$E$67,MATCH(LARGE(Pipeline!$N$7:$N$67,4),Pipeline!$N$7:$N$67,0))),"") -> Colombia | E20: =IFERROR(IF(INDEX(Pipeline!$F$7:$F$67,MATCH(LARGE(Pipeline!$N$7:$N$67,4),Pipeline!$N$7:$N$67,0))="","—",INDEX(Pipeline!$F$7:$F$67,MATCH(LARGE(Pipeline!$N$7:$N$67,4),Pipeline!$N$7:$N$67,0))),"") -> KingRoof | F20: =IFERROR(IF(INDEX(Pipeline!$D$7:$D$67,MATCH(LARGE(Pipeline!$N$7:$N$67,4),Pipeline!$N$7:$N$67,0))="","—",INDEX(Pipeline!$D$7:$D$67,MATCH(LARGE(Pipeline!$N$7:$N$67,4),Pipeline!$N$7:$N$67,0))),"") -> Joana Perez | G20: =IFERROR(IF(INDEX(Pipeline!$G$7:$G$67,MATCH(LARGE(Pipeline!$N$7:$N$67,4),Pipeline!$N$7:$N$67,0))="","—",INDEX(Pipeline!$G$7:$G$67,MATCH(LARGE(Pipeline!$N$7:$N$67,4),Pipeline!$N$7:$N$67,0))),"") -> 14000 | H20: =IFERROR(IF(INDEX(Pipeline!$H$7:$H$67,MATCH(LARGE(Pipeline!$N$7:$N$67,4),Pipeline!$N$7:$N$67,0))="","—",INDEX(Pipeline!$H$7:$H$67,MATCH(LARGE(Pipeline!$N$7:$N$67,4),Pipeline!$N$7:$N$67,0))),"") -> 333529 | I20: =IFERROR(IF(INDEX(Pipeline!$I$7:$I$67,MATCH(LARGE(Pipeline!$N$7:$N$67,4),Pipeline!$N$7:$N$67,0))="","—",INDEX(Pipeline!$I$7:$I$67,MATCH(LARGE(Pipeline!$N$7:$N$67,4),Pipeline!$N$7:$N$67,0))),"") -> Pending | J20: =IFERROR(IF(INDEX(Pipeline!$J$7:$J$67,MATCH(LARGE(Pipeline!$N$7:$N$67,4),Pipeline!$N$7:$N$67,0))="","—",INDEX(Pipeline!$J$7:$J$67,MATCH(LARGE(Pipeline!$N$7:$N$67,4),Pipeline!$N$7:$N$67,0))),"") -> 0.82 | K20: =IFERROR(IF(INDEX(Pipeline!$K$7:$K$67,MATCH(LARGE(Pipeline!$N$7:$N$67,4),Pipeline!$N$7:$N$67,0))="","—",INDEX(Pipeline!$K$7:$K$67,MATCH(LARGE(Pipeline!$N$7:$N$67,4),Pipeline!$N$7:$N$67,0))),"") -> Noviembre | L20: =IFERROR(IF(INDEX(Pipeline!$L$7:$L$67,MATCH(LARGE(Pipeline!$N$7:$N$67,4),Pipeline!$N$7:$N$67,0))="","—",INDEX(Pipeline!$L$7:$L$67,MATCH(LARGE(Pipeline!$N$7:$N$67,4),Pipeline!$N$7:$N$67,0))),"") -> 273493.78
A21: 5 | B21: =IFERROR(IF(INDEX(Pipeline!$B$7:$B$67,MATCH(LARGE(Pipeline!$N$7:$N$67,5),Pipeline!$N$7:$N$67,0))="","—",INDEX(Pipeline!$B$7:$B$67,MATCH(LARGE(Pipeline!$N$7:$N$67,5),Pipeline!$N$7:$N$67,0))),"") -> Espuma SantaFe | C21: =IFERROR(IF(INDEX(Pipeline!$C$7:$C$67,MATCH(LARGE(Pipeline!$N$7:$N$67,5),Pipeline!$N$7:$N$67,0))="","—",INDEX(Pipeline!$C$7:$C$67,MATCH(LARGE(Pipeline!$N$7:$N$67,5),Pipeline!$N$7:$N$67,0))),"") -> Recambio | D21: =IFERROR(IF(INDEX(Pipeline!$E$7:$E$67,MATCH(LARGE(Pipeline!$N$7:$N$67,5),Pipeline!$N$7:$N$67,0))="","—",INDEX(Pipeline!$E$7:$E$67,MATCH(LARGE(Pipeline!$N$7:$N$67,5),Pipeline!$N$7:$N$67,0))),"") -> Colombia | E21: =IFERROR(IF(INDEX(Pipeline!$F$7:$F$67,MATCH(LARGE(Pipeline!$N$7:$N$67,5),Pipeline!$N$7:$N$67,0))="","—",INDEX(Pipeline!$F$7:$F$67,MATCH(LARGE(Pipeline!$N$7:$N$67,5),Pipeline!$N$7:$N$67,0))),"") -> KingRoof / KingWall | F21: =IFERROR(IF(INDEX(Pipeline!$D$7:$D$67,MATCH(LARGE(Pipeline!$N$7:$N$67,5),Pipeline!$N$7:$N$67,0))="","—",INDEX(Pipeline!$D$7:$D$67,MATCH(LARGE(Pipeline!$N$7:$N$67,5),Pipeline!$N$7:$N$67,0))),"") -> Henry Acosta | G21: 2088 | H21: =IFERROR(IF(INDEX(Pipeline!$H$7:$H$67,MATCH(LARGE(Pipeline!$N$7:$N$67,5),Pipeline!$N$7:$N$67,0))="","—",INDEX(Pipeline!$H$7:$H$67,MATCH(LARGE(Pipeline!$N$7:$N$67,5),Pipeline!$N$7:$N$67,0))),"") -> 152072 | I21: closed | J21: 1 | K21: Octuber | L21: =IFERROR(IF(INDEX(Pipeline!$L$7:$L$67,MATCH(LARGE(Pipeline!$N$7:$N$67,5),Pipeline!$N$7:$N$67,0))="","—",INDEX(Pipeline!$L$7:$L$67,MATCH(LARGE(Pipeline!$N$7:$N$67,5),Pipeline!$N$7:$N$67,0))),"") -> 121657.6
B22: Total Top 5 | G22: =SUM(G17:G21) -> 53722 | H22: =SUM(H17:H21) -> 1751877.7
B24: Top 5 Industrial / pipeline Industrial USD | H24: =H13/SUMIFS(Pipeline!H7:H67,Pipeline!A7:A67,"Industrial") -> 0.41998588
B25: Top 5 Distribución / pipeline Distribución USD | H25: =H22/SUMIFS(Pipeline!H7:H67,Pipeline!A7:A67,"Distribución") -> 0.71228824

Sheet 08_Key_Projects
A1: 08 · Key Projects – Industrial y Distribución
A2: Top 5 por m² (todos los estados) + resumen de pipeline
A6: Industrial – Top 5 proyectos por m² (todos los estados)
A7: # | B7: Cliente | C7: Proyecto | D7: País | E7: Portafolio (Type) | F7: Ejecutivo | G7: m² | H7: USD | I7: Estado | J7: % Cierre | K7: Fecha cierre | L7: Valor ponderado
A8: 1 | B8: =IFERROR(IF(INDEX(Pipeline!$B$7:$B$67,MATCH(LARGE(Pipeline!$O$7:$O$67,1),Pipeline!$O$7:$O$67,0))="","—",INDEX(Pipeline!$B$7:$B$67,MATCH(LARGE(Pipeline!$O$7:$O$67,1),Pipeline!$O$7:$O$67,0))),"") -> Construplan | C8: =IFERROR(IF(INDEX(Pipeline!$C$7:$C$67,MATCH(LARGE(Pipeline!$O$7:$O$67,1),Pipeline!$O$7:$O$67,0))="","—",INDEX(Pipeline!$C$7:$C$67,MATCH(LARGE(Pipeline!$O$7:$O$67,1),Pipeline!$O$7:$O$67,0))),"") -> Walmart | D8: =IFERROR(IF(INDEX(Pipeline!$E$7:$E$67,MATCH(LARGE(Pipeline!$O$7:$O$67,1),Pipeline!$O$7:$O$67,0))="","—",INDEX(Pipeline!$E$7:$E$67,MATCH(LARGE(Pipeline!$O$7:$O$67,1),Pipeline!$O$7:$O$67,0))),"") -> Guatemala | E8: =IFERROR(IF(INDEX(Pipeline!$F$7:$F$67,MATCH(LARGE(Pipeline!$O$7:$O$67,1),Pipeline!$O$7:$O$67,0))="","—",INDEX(Pipeline!$F$7:$F$67,MATCH(LARGE(Pipeline!$O$7:$O$67,1),Pipeline!$O$7:$O$67,0))),"") -> King Wall / King Frio / King Roof | F8: =IFERROR(IF(INDEX(Pipeline!$D$7:$D$67,MATCH(LARGE(Pipeline!$O$7:$O$67,1),Pipeline!$O$7:$O$67,0))="","—",INDEX(Pipeline!$D$7:$D$67,MATCH(LARGE(Pipeline!$O$7:$O$67,1),Pipeline!$O$7:$O$67,0))),"") -> Carlos Rodriguez | G8: =IFERROR(IF(INDEX(Pipeline!$G$7:$G$67,MATCH(LARGE(Pipeline!$O$7:$O$67,1),Pipeline!$O$7:$O$67,0))="","—",INDEX(Pipeline!$G$7:$G$67,MATCH(LARGE(Pipeline!$O$7:$O$67,1),Pipeline!$O$7:$O$67,0))),"") -> 100000 | H8: =IFERROR(IF(INDEX(Pipeline!$H$7:$H$67,MATCH(LARGE(Pipeline!$O$7:$O$67,1),Pipeline!$O$7:$O$67,0))="","—",INDEX(Pipeline!$H$7:$H$67,MATCH(LARGE(Pipeline!$O$7:$O$67,1),Pipeline!$O$7:$O$67,0))),"") -> 2787794 | I8: =IFERROR(IF(INDEX(Pipeline!$I$7:$I$67,MATCH(LARGE(Pipeline!$O$7:$O$67,1),Pipeline!$O$7:$O$67,0))="","—",INDEX(Pipeline!$I$7:$I$67,MATCH(LARGE(Pipeline!$O$7:$O$67,1),Pipeline!$O$7:$O$67,0))),"") -> Specification | J8: =IFERROR(IF(INDEX(Pipeline!$J$7:$J$67,MATCH(LARGE(Pipeline!$O$7:$O$67,1),Pipeline!$O$7:$O$67,0))="","—",INDEX(Pipeline!$J$7:$J$67,MATCH(LARGE(Pipeline!$O$7:$O$67,1),Pipeline!$O$7:$O$67,0))),"") -> 0.75 | K8: =IFERROR(IF(INDEX(Pipeline!$K$7:$K$67,MATCH(LARGE(Pipeline!$O$7:$O$67,1),Pipeline!$O$7:$O$67,0))="","—",INDEX(Pipeline!$K$7:$K$67,MATCH(LARGE(Pipeline!$O$7:$O$67,1),Pipeline!$O$7:$O$67,0))),"") -> Noviembre | L8: =IFERROR(IF(INDEX(Pipeline!$L$7:$L$67,MATCH(LARGE(Pipeline!$O$7:$O$67,1),Pipeline!$O$7:$O$67,0))="","—",INDEX(Pipeline!$L$7:$L$67,MATCH(LARGE(Pipeline!$O$7:$O$67,1),Pipeline!$O$7:$O$67,0))),"") -> 2090845.5
A9: 2 | B9: =IFERROR(IF(INDEX(Pipeline!$B$7:$B$67,MATCH(LARGE(Pipeline!$O$7:$O$67,2),Pipeline!$O$7:$O$67,0))="","—",INDEX(Pipeline!$B$7:$B$67,MATCH(LARGE(Pipeline!$O$7:$O$67,2),Pipeline!$O$7:$O$67,0))),"") -> Haceb | C9: =IFERROR(IF(INDEX(Pipeline!$C$7:$C$67,MATCH(LARGE(Pipeline!$O$7:$O$67,2),Pipeline!$O$7:$O$67,0))="","—",INDEX(Pipeline!$C$7:$C$67,MATCH(LARGE(Pipeline!$O$7:$O$67,2),Pipeline!$O$7:$O$67,0))),"") -> Recambio | D9: =IFERROR(IF(INDEX(Pipeline!$E$7:$E$67,MATCH(LARGE(Pipeline!$O$7:$O$67,2),Pipeline!$O$7:$O$67,0))="","—",INDEX(Pipeline!$E$7:$E$67,MATCH(LARGE(Pipeline!$O$7:$O$67,2),Pipeline!$O$7:$O$67,0))),"") -> Colombia | E9: =IFERROR(IF(INDEX(Pipeline!$F$7:$F$67,MATCH(LARGE(Pipeline!$O$7:$O$67,2),Pipeline!$O$7:$O$67,0))="","—",INDEX(Pipeline!$F$7:$F$67,MATCH(LARGE(Pipeline!$O$7:$O$67,2),Pipeline!$O$7:$O$67,0))),"") -> KingWall / KingRoof | F9: =IFERROR(IF(INDEX(Pipeline!$D$7:$D$67,MATCH(LARGE(Pipeline!$O$7:$O$67,2),Pipeline!$O$7:$O$67,0))="","—",INDEX(Pipeline!$D$7:$D$67,MATCH(LARGE(Pipeline!$O$7:$O$67,2),Pipeline!$O$7:$O$67,0))),"") -> Ana Arias | G9: =IFERROR(IF(INDEX(Pipeline!$G$7:$G$67,MATCH(LARGE(Pipeline!$O$7:$O$67,2),Pipeline!$O$7:$O$67,0))="","—",INDEX(Pipeline!$G$7:$G$67,MATCH(LARGE(Pipeline!$O$7:$O$67,2),Pipeline!$O$7:$O$67,0))),"") -> 61000 | H9: =IFERROR(IF(INDEX(Pipeline!$H$7:$H$67,MATCH(LARGE(Pipeline!$O$7:$O$67,2),Pipeline!$O$7:$O$67,0))="","—",INDEX(Pipeline!$H$7:$H$67,MATCH(LARGE(Pipeline!$O$7:$O$67,2),Pipeline!$O$7:$O$67,0))),"") -> 1700505 | I9: =IFERROR(IF(INDEX(Pipeline!$I$7:$I$67,MATCH(LARGE(Pipeline!$O$7:$O$67,2),Pipeline!$O$7:$O$67,0))="","—",INDEX(Pipeline!$I$7:$I$67,MATCH(LARGE(Pipeline!$O$7:$O$67,2),Pipeline!$O$7:$O$67,0))),"") -> Pending | J9: =IFERROR(IF(INDEX(Pipeline!$J$7:$J$67,MATCH(LARGE(Pipeline!$O$7:$O$67,2),Pipeline!$O$7:$O$67,0))="","—",INDEX(Pipeline!$J$7:$J$67,MATCH(LARGE(Pipeline!$O$7:$O$67,2),Pipeline!$O$7:$O$67,0))),"") -> 0.8 | K9: =IFERROR(IF(INDEX(Pipeline!$K$7:$K$67,MATCH(LARGE(Pipeline!$O$7:$O$67,2),Pipeline!$O$7:$O$67,0))="","—",INDEX(Pipeline!$K$7:$K$67,MATCH(LARGE(Pipeline!$O$7:$O$67,2),Pipeline!$O$7:$O$67,0))),"") -> Noviembre | L9: =IFERROR(IF(INDEX(Pipeline!$L$7:$L$67,MATCH(LARGE(Pipeline!$O$7:$O$67,2),Pipeline!$O$7:$O$67,0))="","—",INDEX(Pipeline!$L$7:$L$67,MATCH(LARGE(Pipeline!$O$7:$O$67,2),Pipeline!$O$7:$O$67,0))),"") -> 1360404
A10: 3 | B10: =IFERROR(IF(INDEX(Pipeline!$B$7:$B$67,MATCH(LARGE(Pipeline!$O$7:$O$67,3),Pipeline!$O$7:$O$67,0))="","—",INDEX(Pipeline!$B$7:$B$67,MATCH(LARGE(Pipeline!$O$7:$O$67,3),Pipeline!$O$7:$O$67,0))),"") -> Conmetal | C10: =IFERROR(IF(INDEX(Pipeline!$C$7:$C$67,MATCH(LARGE(Pipeline!$O$7:$O$67,3),Pipeline!$O$7:$O$67,0))="","—",INDEX(Pipeline!$C$7:$C$67,MATCH(LARGE(Pipeline!$O$7:$O$67,3),Pipeline!$O$7:$O$67,0))),"") -> Bodegas AMT | D10: =IFERROR(IF(INDEX(Pipeline!$E$7:$E$67,MATCH(LARGE(Pipeline!$O$7:$O$67,3),Pipeline!$O$7:$O$67,0))="","—",INDEX(Pipeline!$E$7:$E$67,MATCH(LARGE(Pipeline!$O$7:$O$67,3),Pipeline!$O$7:$O$67,0))),"") -> Guatemala | E10: =IFERROR(IF(INDEX(Pipeline!$F$7:$F$67,MATCH(LARGE(Pipeline!$O$7:$O$67,3),Pipeline!$O$7:$O$67,0))="","—",INDEX(Pipeline!$F$7:$F$67,MATCH(LARGE(Pipeline!$O$7:$O$67,3),Pipeline!$O$7:$O$67,0))),"") -> KingRoof / KingWall | F10: =IFERROR(IF(INDEX(Pipeline!$D$7:$D$67,MATCH(LARGE(Pipeline!$O$7:$O$67,3),Pipeline!$O$7:$O$67,0))="","—",INDEX(Pipeline!$D$7:$D$67,MATCH(LARGE(Pipeline!$O$7:$O$67,3),Pipeline!$O$7:$O$67,0))),"") -> Carlos Rodriguez | G10: =IFERROR(IF(INDEX(Pipeline!$G$7:$G$67,MATCH(LARGE(Pipeline!$O$7:$O$67,3),Pipeline!$O$7:$O$67,0))="","—",INDEX(Pipeline!$G$7:$G$67,MATCH(LARGE(Pipeline!$O$7:$O$67,3),Pipeline!$O$7:$O$67,0))),"") -> 50000 | H10: =IFERROR(IF(INDEX(Pipeline!$H$7:$H$67,MATCH(LARGE(Pipeline!$O$7:$O$67,3),Pipeline!$O$7:$O$67,0))="","—",INDEX(Pipeline!$H$7:$H$67,MATCH(LARGE(Pipeline!$O$7:$O$67,3),Pipeline!$O$7:$O$67,0))),"") -> 1200000 | I10: =IFERROR(IF(INDEX(Pipeline!$I$7:$I$67,MATCH(LARGE(Pipeline!$O$7:$O$67,3),Pipeline!$O$7:$O$67,0))="","—",INDEX(Pipeline!$I$7:$I$67,MATCH(LARGE(Pipeline!$O$7:$O$67,3),Pipeline!$O$7:$O$67,0))),"") -> Pending | J10: =IFERROR(IF(INDEX(Pipeline!$J$7:$J$67,MATCH(LARGE(Pipeline!$O$7:$O$67,3),Pipeline!$O$7:$O$67,0))="","—",INDEX(Pipeline!$J$7:$J$67,MATCH(LARGE(Pipeline!$O$7:$O$67,3),Pipeline!$O$7:$O$67,0))),"") -> 0.6 | K10: =IFERROR(IF(INDEX(Pipeline!$K$7:$K$67,MATCH(LARGE(Pipeline!$O$7:$O$67,3),Pipeline!$O$7:$O$67,0))="","—",INDEX(Pipeline!$K$7:$K$67,MATCH(LARGE(Pipeline!$O$7:$O$67,3),Pipeline!$O$7:$O$67,0))),"") -> Diciembre | L10: =IFERROR(IF(INDEX(Pipeline!$L$7:$L$67,MATCH(LARGE(Pipeline!$O$7:$O$67,3),Pipeline!$O$7:$O$67,0))="","—",INDEX(Pipeline!$L$7:$L$67,MATCH(LARGE(Pipeline!$O$7:$O$67,3),Pipeline!$O$7:$O$67,0))),"") -> 720000
A11: 4 | B11: =IFERROR(IF(INDEX(Pipeline!$B$7:$B$67,MATCH(LARGE(Pipeline!$O$7:$O$67,4),Pipeline!$O$7:$O$67,0))="","—",INDEX(Pipeline!$B$7:$B$67,MATCH(LARGE(Pipeline!$O$7:$O$67,4),Pipeline!$O$7:$O$67,0))),"") -> Imbert Dominguez | C11: =IFERROR(IF(INDEX(Pipeline!$C$7:$C$67,MATCH(LARGE(Pipeline!$O$7:$O$67,4),Pipeline!$O$7:$O$67,0))="","—",INDEX(Pipeline!$C$7:$C$67,MATCH(LARGE(Pipeline!$O$7:$O$67,4),Pipeline!$O$7:$O$67,0))),"") -> INDAL-IDA | D11: =IFERROR(IF(INDEX(Pipeline!$E$7:$E$67,MATCH(LARGE(Pipeline!$O$7:$O$67,4),Pipeline!$O$7:$O$67,0))="","—",INDEX(Pipeline!$E$7:$E$67,MATCH(LARGE(Pipeline!$O$7:$O$67,4),Pipeline!$O$7:$O$67,0))),"") -> Dominicana | E11: =IFERROR(IF(INDEX(Pipeline!$F$7:$F$67,MATCH(LARGE(Pipeline!$O$7:$O$67,4),Pipeline!$O$7:$O$67,0))="","—",INDEX(Pipeline!$F$7:$F$67,MATCH(LARGE(Pipeline!$O$7:$O$67,4),Pipeline!$O$7:$O$67,0))),"") -> KingRoof / KingWall / KingFrigo | F11: =IFERROR(IF(INDEX(Pipeline!$D$7:$D$67,MATCH(LARGE(Pipeline!$O$7:$O$67,4),Pipeline!$O$7:$O$67,0))="","—",INDEX(Pipeline!$D$7:$D$67,MATCH(LARGE(Pipeline!$O$7:$O$67,4),Pipeline!$O$7:$O$67,0))),"") -> Laura Torres | G11: =IFERROR(IF(INDEX(Pipeline!$G$7:$G$67,MATCH(LARGE(Pipeline!$O$7:$O$67,4),Pipeline!$O$7:$O$67,0))="","—",INDEX(Pipeline!$G$7:$G$67,MATCH(LARGE(Pipeline!$O$7:$O$67,4),Pipeline!$O$7:$O$67,0))),"") -> 50000 | H11: =IFERROR(IF(INDEX(Pipeline!$H$7:$H$67,MATCH(LARGE(Pipeline!$O$7:$O$67,4),Pipeline!$O$7:$O$67,0))="","—",INDEX(Pipeline!$H$7:$H$67,MATCH(LARGE(Pipeline!$O$7:$O$67,4),Pipeline!$O$7:$O$67,0))),"") -> 1550000 | I11: =IFERROR(IF(INDEX(Pipeline!$I$7:$I$67,MATCH(LARGE(Pipeline!$O$7:$O$67,4),Pipeline!$O$7:$O$67,0))="","—",INDEX(Pipeline!$I$7:$I$67,MATCH(LARGE(Pipeline!$O$7:$O$67,4),Pipeline!$O$7:$O$67,0))),"") -> Pending | J11: =IFERROR(IF(INDEX(Pipeline!$J$7:$J$67,MATCH(LARGE(Pipeline!$O$7:$O$67,4),Pipeline!$O$7:$O$67,0))="","—",INDEX(Pipeline!$J$7:$J$67,MATCH(LARGE(Pipeline!$O$7:$O$67,4),Pipeline!$O$7:$O$67,0))),"") -> 0.75 | K11: =IFERROR(IF(INDEX(Pipeline!$K$7:$K$67,MATCH(LARGE(Pipeline!$O$7:$O$67,4),Pipeline!$O$7:$O$67,0))="","—",INDEX(Pipeline!$K$7:$K$67,MATCH(LARGE(Pipeline!$O$7:$O$67,4),Pipeline!$O$7:$O$67,0))),"") -> Noviembre | L11: =IFERROR(IF(INDEX(Pipeline!$L$7:$L$67,MATCH(LARGE(Pipeline!$O$7:$O$67,4),Pipeline!$O$7:$O$67,0))="","—",INDEX(Pipeline!$L$7:$L$67,MATCH(LARGE(Pipeline!$O$7:$O$67,4),Pipeline!$O$7:$O$67,0))),"") -> 1162500
