Workbook

Sheet LEEME
A1: Kingspan Middle Americas · Commercial Review – Motor de datos (Data Engine)
A3: Cómo usar este archivo
A4: 1. Diligencie SOLO las celdas amarillas con texto azul (inputs). Todo lo demás (%, YoY, MoM, totales, mix, rankings, semáforos, Top 5) se calcula solo.
A5: 2. Cada hoja corresponde a un slide del deck (01 = Commercial Overview … 15 = Highlights). El número de la hoja = número del slide de contenido.
A6: 3. Los rankings de consultores (hojas 09–14) y los Top 5 (hojas 07–08) se reordenan automáticamente al cambiar los datos.
A7: 4. Para actualizar el PowerPoint: en cada gráfico clic derecho › "Editar datos" y pegue los valores de la tabla "Fuente gráfico" de la hoja correspondiente; en las tablas, pegue valores (Pegado especial › Valores) desde el bloque "Tabla slide".
A8: Alternativa: copie el bloque de la hoja y en PowerPoint use Pegado especial › "Pegar vínculo" (Hoja de Microsoft Excel) para dejar la tabla vinculada a este archivo.
A9: 5. Mes de corte: hoja 02_OI celda B4 y 06_Perf_Forecast celda B4 (número de mes, 9 = septiembre).
A10: 6. Revise la hoja "Validaciones": lista inconsistencias detectadas en el deck original y cómo se corrigieron.
A12: Convenciones
A13: Amarillo + azul = input · Negro = fórmula · Verde/Ámbar/Rojo = semáforo de cumplimiento (≥100% / 70–99% / <70%).
A14: Unidades: volumen en m²; ingresos en COP MM (millones de pesos); pipeline en USD.
... A34: • Para regenerar el deck: python scripts/actualizar_deck_comercial.py <este Excel> <deck base> <salida>.

Sheet 00_Resumen_Ejecutivo
A1: 00 · Resumen ejecutivo – 4 preguntas
A2: Slide 2: qué nos comprometimos (amarillo = input), qué logramos (fórmula), desviación y estado (automáticos), qué la explica y acción (input).
A4: Indicador | B4: Unidad | C4: Compromiso / meta | D4: Resultado | E4: Desviación (Res − Comp) | F4: % vs compromiso | G4: Estado sugerido | H4: Estado final (override) | I4: Qué la explica | J4: Acción / decisión | K4: Responsable | L4: Fecha
A5: Order Intake YTD | B5: m² | D5: ='02_OI'!E7 | E5: =IF(C5="","",D5-C5) | F5: =IF(OR(C5="",C5=0),"",D5/C5) | G5: =IF(F5="","Definir",IF(ROUND(F5,2)>=1,"Verde",IF(ROUND(F5,2)>=0.85,"Amarillo","Rojo")))
A6: Ventas YTD | B6: m² | C6: =RSM_Resumen_Canales!T11 | D6: =RSM_Resumen_Canales!D11 | E6: =IF(C6="","",D6-C6) | F6: =IF(OR(C6="",C6=0),"",D6/C6) | G6: =IF(F6="","Definir",IF(ROUND(F6,2)>=1,"Verde",IF(ROUND(F6,2)>=0.85,"Amarillo","Rojo"))) | I6: Industrial y Otras Geografías = 98% de la brecha | J6: Plan de cobertura territorios Industrial + plan de recuperación cuentas Ecuador / Costa Rica
A7: Margen OI YTD (Gross-STD) | B7: % | D7: ='02_OI'!E12 | E7: =IF(C7="","",D7-C7) | F7: =IF(OR(C7="",C7=0),"",D7/C7) | G7: =IF(F7="","Definir",IF(ROUND(F7,2)>=1,"Verde",IF(ROUND(F7,2)>=0.85,"Amarillo","Rojo")))
A8: Backlog IMP | B8: m² | D8: ='04_Backlog'!B5 | E8: =IF(C8="","",D8-C8) | F8: =IF(OR(C8="",C8=0),"",D8/C8) | G8: =IF(F8="","Definir",IF(ROUND(F8,2)>=1,"Verde",IF(ROUND(F8,2)>=0.85,"Amarillo","Rojo")))
A9: Margen backlog (ponderado) | B9: % | D9: =RSM_Resumen_Canales!J11 | E9: =IF(C9="","",D9-C9) | F9: =IF(OR(C9="",C9=0),"",D9/C9) | G9: =IF(F9="","Definir",IF(ROUND(F9,2)>=1,"Verde",IF(ROUND(F9,2)>=0.85,"Amarillo","Rojo")))
A10: Cierre año OI (real + forecast) | B10: m² | D10: ='06_Perf_Forecast'!B30 | E10: =IF(C10="","",D10-C10) | F10: =IF(OR(C10="",C10=0),"",D10/C10) | G10: =IF(F10="","Definir",IF(ROUND(F10,2)>=1,"Verde",IF(ROUND(F10,2)>=0.85,"Amarillo","Rojo"))) | I10: Forecast Q4 400k m² (+7,6% vs Q4-25)
A11: Iniciativas estratégicas en verde | B11: # | C11: 8 | D11: =COUNTIF('16_Iniciativas'!J5:J12,"Verde") | E11: =IF(C11="","",D11-C11) | F11: =IF(OR(C11="",C11=0),"",D11/C11) | G11: =IF(COUNTA('16_Iniciativas'!J5:J12)=0,"Definir",IF(ROUND(F11,2)>=1,"Verde",IF(ROUND(F11,2)>=0.85,"Amarillo","Rojo")))
A13: Regla de estado sugerido: ≥100% del compromiso = Verde · 85–99% = Amarillo · <85% = Rojo. Si se diligencia "Estado final", ese prevalece en el slide.
A14: Mensaje clave del slide (1 línea): | C14: Estamos al 85% del budget de ventas YTD con OI y margen por encima del año anterior; la brecha está en territorios Industrial y dos cuentas de exportación.

Sheet 01_Overview
A1: 01 · Commercial Overview
A2: Ventas y Order Intake del mes, YTD, YoY y MoM · mix de ventas por canal y geografía
A4: Concepto (m²) | B4: Mes actual (Sep-26) | C4: Mismo mes PY (Sep-25) | D4: Mes anterior (Ago-26) | E4: YTD 2026 | F4: YTD 2025 | G4: YoY mes | H4: MoM | I4: YoY YTD
A5: Ventas (Sales) | B5: 141231 | C5: 99001 | D5: 125933 | E5: 1199504 | F5: 1120888 | G5: =IF(OR(B5="",C5=""),"",IF(C5=0,"n.a.",B5/C5-1)) | H5: =IF(OR(B5="",D5=""),"",IF(D5=0,"n.a.",B5/D5-1)) | I5: =IF(OR(E5="",F5=""),"",IF(F5=0,"n.a.",E5/F5-1))
A6: Order Intake | B6: 160547 | C6: 132769 | D6: 146446 | E6: 1400088 | F6: 1120898 | G6: =IF(OR(B6="",C6=""),"",IF(C6=0,"n.a.",B6/C6-1)) | H6: =IF(OR(B6="",D6=""),"",IF(D6=0,"n.a.",B6/D6-1)) | I6: =IF(OR(E6="",F6=""),"",IF(F6=0,"n.a.",E6/F6-1))
A7: Book-to-bill YTD (OI / Ventas) | E7: =IFERROR(E6/E5,"")
A8: Book-to-bill mes | B8: =IFERROR(B6/B5,"")
A10: Ventas del mes por canal | B10: m² | C10: Mix %
A11: Industrial | C11: =IFERROR(B11/SUM($B$11:$B$12),0)
A12: Distribution | C12: =IFERROR(B12/SUM($B$11:$B$12),0)
A14: Ventas del mes por geografía | B14: m² | C14: Mix %
A15: Colombia | C15: =IFERROR(B15/SUM($B$15:$B$16),0)
A16: Other Geographies | C16: =IFERROR(B16/SUM($B$15:$B$16),0)
A18: Otras geografías – país | B18: m² mes | C18: % del total OG | D18: Ranking
A19: Ecuador | B19: 8828 | C19: =IFERROR(B19/SUM($B$19:$B$23),0) | D19: =RANK(B19,$B$19:$B$23)
A20: Others | B20: 6421 | C20: =IFERROR(B20/SUM($B$19:$B$23),0) | D20: =RANK(B20,$B$19:$B$23)
A21: Republica Dominicana | B21: 15144 | C21: =IFERROR(B21/SUM($B$19:$B$23),0) | D21: =RANK(B21,$B$19:$B$23)
A22: Venezuela | B22: 9798 | C22: =IFERROR(B22/SUM($B$19:$B$23),0) | D22: =RANK(B22,$B$19:$B$23)
C23: =IFERROR(B23/SUM($B$19:$B$23),0) | D23: =RANK(B23,$B$19:$B$23)
A24: Total | B24: =SUM(B19:B23) | C24: =SUM(C19:C23)
A26: Top pedidos del mes – Cliente | B26: Proyecto | C26: Canal | D26: Valor (USD mm, según deck)
A27: Envases Tropicales | B27: Cubierta Envases Tropicales | LTORR-02071 | C27: Other Geographies | D27: 306
A28: Industrial Nutricional Avícola | B28: Industria Nutricional Avícola | C28: Cold Storage | D28: 236
A29: C.C. Chipichape P.H. | B29: Recambio cubierta Chipichape – Bodega 04 | C29: Industrial | D29: 173

Sheet 19_OI_Regiones
A1: 19 · Order Intake por región (slide Commercial Overview)
A2: Diligencie el OI del mes y el YTD por región (amarillo). Seleccione la vista en B4: el ranking y el gráfico se reordenan solos de mayor a menor volumen.
A4: Vista del gráfico | B4: Mes
A6: Región | B6: OI mes (m²) | C6: OI YTD (m²) | D6: Fuente / estado del dato | E6: Valor vista | F6: Clave orden (aux)
A7: Colombia | B7: 104987 | D7: Estimado: OI IMP mes − OI Otras Geografías (03_OI_Canal B7) | E7: =IF($B$4="YTD",C7,B7) | F7: =N(E7)+(100-ROW())/1000000000
A8: Centro América | B8: 6756 | D8: Estimado: Otras Geo × mix ventas 'Others' × peso pipeline CA | E8: =IF($B$4="YTD",C8,B8) | F8: =N(E8)+(100-ROW())/1000000000
A9: Caribe | B9: 20935 | D9: Estimado: Otras Geo × mix ventas Rep. Dominicana | E9: =IF($B$4="YTD",C9,B9) | F9: =N(E9)+(100-ROW())/1000000000
A10: Ecuador | B10: 12204 | D10: Estimado: Otras Geo × mix ventas Ecuador | E10: =IF($B$4="YTD",C10,B10) | F10: =N(E10)+(100-ROW())/1000000000
A11: Perú | B11: 2120 | D11: Estimado: Otras Geo × mix ventas 'Others' × peso pipeline Perú | E11: =IF($B$4="YTD",C11,B11) | F11: =N(E11)+(100-ROW())/1000000000
A12: Venezuela | B12: 13545 | D12: Estimado: Otras Geo × mix ventas Venezuela | E12: =IF($B$4="YTD",C12,B12) | F12: =N(E12)+(100-ROW())/1000000000
A13: TOTAL | B13: =SUM(B7:B12) | C13: =SUM(C7:C12) | E13: =SUM(E7:E12)
A14: Control: Σ regiones mes − OI IMP mes (02_OI B7) | B14: =B13-'02_OI'!B7
A15: Control: Σ regiones YTD − OI IMP YTD (02_OI E7) | C15: =IF(C13=0,"Pendiente",C13-'02_OI'!E7)
A17: RANKING – fuente del gráfico (se ordena solo)
A18: # | B18: Región | C18: m² | D18: % del total
A19: 1 | B19: =INDEX($A$7:$A$12,MATCH(LARGE($F$7:$F$12,A19),$F$7:$F$12,0)) | C19: =INDEX($E$7:$E$12,MATCH(LARGE($F$7:$F$12,A19),$F$7:$F$12,0)) | D19: =IFERROR(C19/$E$13,0)
A20: 2 | B20: =INDEX($A$7:$A$12,MATCH(LARGE($F$7:$F$12,A20),$F$7:$F$12,0)) | C20: =INDEX($E$7:$E$12,MATCH(LARGE($F$7:$F$12,A20),$F$7:$F$12,0)) | D20: =IFERROR(C20/$E$13,0)
A21: 3 | B21: =INDEX($A$7:$A$12,MATCH(LARGE($F$7:$F$12,A21),$F$7:$F$12,0)) | C21: =INDEX($E$7:$E$12,MATCH(LARGE($F$7:$F$12,A21),$F$7:$F$12,0)) | D21: =IFERROR(C21/$E$13,0)
A22: 4 | B22: =INDEX($A$7:$A$12,MATCH(LARGE($F$7:$F$12,A22),$F$7:$F$12,0)) | C22: =INDEX($E$7:$E$12,MATCH(LARGE($F$7:$F$12,A22),$F$7:$F$12,0)) | D22: =IFERROR(C22/$E$13,0)
A23: 5 | B23: =INDEX($A$7:$A$12,MATCH(LARGE($F$7:$F$12,A23),$F$7:$F$12,0)) | C23: =INDEX($E$7:$E$12,MATCH(LARGE($F$7:$F$12,A23),$F$7:$F$12,0)) | D23: =IFERROR(C23/$E$13,0)
A24: 6 | B24: =INDEX($A$7:$A$12,MATCH(LARGE($F$7:$F$12,A24),$F$7:$F$12,0)) | C24: =INDEX($E$7:$E$12,MATCH(LARGE($F$7:$F$12,A24),$F$7:$F$12,0)) | D24: =IFERROR(C24/$E$13,0)
A26: Las celdas en salmón son estimaciones iniciales: reemplácelas con el OI real por país.

Sheet 02_OI
A1: 02 · Order Intake – Octuber
A2: Tabla por producto + progresión mensual de ingresos y margen
A4: Mes de corte (1-12) | B4: 10
A6: Producto / métrica | B6: Mes actual | C6: PY | D6: YoY mes | E6: YTD | F6: Prior YTD | G6: YoY YTD
A7: IMP – Volume (m²) | B7: 160547 | C7: 132786 | D7: =IF(OR(B7="",C7=""),"",IF(C7=0,"n.a.",B7/C7-1)) | E7: 1400088 | F7: 1120898 | G7: =IF(OR(E7="",F7=""),"",IF(F7=0,"n.a.",E7/F7-1))
A8: Kingcore – Volume (m²) | B8: 20793 | C8: 10126 | D8: =IF(OR(B8="",C8=""),"",IF(C8=0,"n.a.",B8/C8-1)) | E8: 229903 | F8: 88736 | G8: =IF(OR(E8="",F8=""),"",IF(F8=0,"n.a.",E8/F8-1))
A9: Single Skin – Volume (m²) | B9: 16271 | C9: 13834 | D9: =IF(OR(B9="",C9=""),"",IF(C9=0,"n.a.",B9/C9-1)) | E9: 122613 | F9: 52330 | G9: =IF(OR(E9="",F9=""),"",IF(F9=0,"n.a.",E9/F9-1))
A10: Benchmark – Volume (m²) | B10: 7880 | C10: 0 | D10: =IF(OR(B10="",C10=""),"",IF(C10=0,"n.a.",B10/C10-1)) | E10: 5817 | F10: 563 | G10: =IF(OR(E10="",F10=""),"",IF(F10=0,"n.a.",E10/F10-1))
A11: IMP – Revenue (COP MM) | B11: 14484 | C11: 12723 | D11: =IF(OR(B11="",C11=""),"",IF(C11=0,"n.a.",B11/C11-1)) | E11: 144659 | F11: 108228 | G11: =IF(OR(E11="",F11=""),"",IF(F11=0,"n.a.",E11/F11-1))
A12: Margen (Gross-STD) | B12: 0.27 | C12: 0.24 | D12: =IF(OR(B12="",C12=""),"",(B12-C12)*100) | E12: 0.25 | F12: 0.24 | G12: =IF(OR(E12="",F12=""),"",(E12-F12)*100)
A14: N° mes | B14: Mes | C14: Ingresos CY (COP MM) | D14: Ingresos PY (COP MM) | E14: YoY | F14: Margen CY % | G14: Fuente gráfico: CY | H14: Fuente gráfico: PY | I14: Etiqueta barra 2026: OI m² | J14: Etiqueta barra 2025: OI m² (input)
A15: 1 | B15: Jan | C15: 9968.166 | D15: 7958.8 | E15: =IF(OR(C15="",D15=""),"",IF(D15=0,"n.a.",C15/D15-1)) | F15: 0.251 | G15: =IF(A15<=$B$4,C15,"") | H15: =D15 | I15: =IF(A15<=$B$4,'06_Perf_Forecast'!E7,"")
A16: 2 | B16: Feb | C16: 12767.714 | D16: 10536.7 | E16: =IF(OR(C16="",D16=""),"",IF(D16=0,"n.a.",C16/D16-1)) | F16: 0.254 | G16: =IF(A16<=$B$4,C16,"") | H16: =D16 | I16: =IF(A16<=$B$4,'06_Perf_Forecast'!E8,"")
A17: 3 | B17: Mar | C17: 14462.925 | D17: 12471.2 | E17: =IF(OR(C17="",D17=""),"",IF(D17=0,"n.a.",C17/D17-1)) | F17: 0.261 | G17: =IF(A17<=$B$4,C17,"") | H17: =D17 | I17: =IF(A17<=$B$4,'06_Perf_Forecast'!E9,"")
A18: 4 | B18: Apr | C18: 12270.448 | D18: 9577 | E18: =IF(OR(C18="",D18=""),"",IF(D18=0,"n.a.",C18/D18-1)) | F18: 0.257 | G18: =IF(A18<=$B$4,C18,"") | H18: =D18 | I18: =IF(A18<=$B$4,'06_Perf_Forecast'!E10,"")
A19: 5 | B19: May | C19: 27093.858 | D19: 8092 | E19: =IF(OR(C19="",D19=""),"",IF(D19=0,"n.a.",C19/D19-1)) | F19: 0.209 | G19: =IF(A19<=$B$4,C19,"") | H19: =D19 | I19: =IF(A19<=$B$4,'06_Perf_Forecast'!E11,"")
A20: 6 | B20: Jun | C20: 13652.194 | D20: 11810.8 | E20: =IF(OR(C20="",D20=""),"",IF(D20=0,"n.a.",C20/D20-1)) | F20: 0.285 | G20: =IF(A20<=$B$4,C20,"") | H20: =D20 | I20: =IF(A20<=$B$4,'06_Perf_Forecast'!E12,"")
A21: 7 | B21: Jul | C21: 11718.909 | D21: 7612.5 | E21: =IF(OR(C21="",D21=""),"",IF(D21=0,"n.a.",C21/D21-1)) | F21: 0.273 | G21: =IF(A21<=$B$4,C21,"") | H21: =D21 | I21: =IF(A21<=$B$4,'06_Perf_Forecast'!E13,"")
A22: 8 | B22: Aug | C22: 14500.72 | D22: 16772.6 | E22: =IF(OR(C22="",D22=""),"",IF(D22=0,"n.a.",C22/D22-1)) | F22: 0.268 | G22: =IF(A22<=$B$4,C22,"") | H22: =D22 | I22: =IF(A22<=$B$4,'06_Perf_Forecast'!E14,"")
A23: 9 | B23: Sep | C23: 13740.67 | D23: 10673.6 | E23: =IF(OR(C23="",D23=""),"",IF(D23=0,"n.a.",C23/D23-1)) | F23: 0.271 | G23: =IF(A23<=$B$4,C23,"") | H23: =D23 | I23: =IF(A23<=$B$4,'06_Perf_Forecast'!E15,"")
A24: 10 | B24: Oct | C24: 14484 | D24: 12723.1 | E24: =IF(OR(C24="",D24=""),"",IF(D24=0,"n.a.",C24/D24-1)) | F24: =B12 | G24: =IF(A24<=$B$4,C24,"") | H24: =D24 | I24: =IF(A24<=$B$4,'06_Perf_Forecast'!E16,"")
A25: 11 | B25: Nov | D25: 12445.1 | E25: =IF(OR(C25="",D25=""),"",IF(D25=0,"n.a.",C25/D25-1)) | G25: =IF(A25<=$B$4,C25,"") | H25: =D25 | I25: =IF(A25<=$B$4,'06_Perf_Forecast'!E17,"")
A26: 12 | B26: Dec | D26: 10462.4 | E26: =IF(OR(C26="",D26=""),"",IF(D26=0,"n.a.",C26/D26-1)) | G26: =IF(A26<=$B$4,C26,"") | H26: =D26 | I26: =IF(A26<=$B$4,'06_Perf_Forecast'!E18,"")
B27: YTD | C27: =SUMIFS(C15:C26,A15:A26,"<="&$B$4) | D27: =SUMIFS(D15:D26,A15:A26,"<="&$B$4) | E27: =IF(OR(C27="",D27=""),"",IF(D27=0,"n.a.",C27/D27-1))
B28: Control vs tabla | C28: =C27-E11

Sheet 03_OI_Canal
A1: 03 · Order Intake por canal (IMP)
A2: CM / PY / YoY / Gross Margin por canal · YTD y mix se alimentan de las hojas RSM (09–14) | G2: 157039 | H2: 160547 | I2: {=H2-G1:G2}
I3: 3508
A4: Canal | B4: OI mes CM (m²) | C4: OI mes PY (m²) | D4: YoY mes | E4: GM % CM | F4: GM % PY | G4: Δ GM (pp) | H4: OI YTD m² (RSM) | I4: Mix YTD % | J4: Ventas YTD m² | K4: Budget YTD m² | L4: % Cumpl. ventas
A5: Industrial | B5: =62296-13276+3508 | C5: 40646 | D5: =IF(OR(B5="",C5=""),"",IF(C5=0,"n.a.",B5/C5-1)) | E5: 0.3307481 | F5: 0.28692083 | G5: =IF(OR(E5="",F5=""),"",(E5-F5)*100) | H5: ='09_RSM_Industrial'!C18 | I5: =IFERROR(H5/$H$11,0) | J5: ='09_RSM_Industrial'!D18 | K5: ='09_RSM_Industrial'!E18 | L5: =IFERROR(J5/K5,0)
A6: Distribución | B6: 29274 | C6: 53212 | D6: =IF(OR(B6="",C6=""),"",IF(C6=0,"n.a.",B6/C6-1)) | E6: 0.3307481 | F6: 0.2701004 | G6: =IF(OR(E6="",F6=""),"",(E6-F6)*100) | H6: ='10_RSM_Distribucion'!C20 | I6: =IFERROR(H6/$H$11,0) | J6: ='10_RSM_Distribucion'!D20 | K6: ='10_RSM_Distribucion'!E20 | L6: =IFERROR(J6/K6,0)
A7: Otras Geografías | B7: 55560 | C7: 36701 | D7: =IF(OR(B7="",C7=""),"",IF(C7=0,"n.a.",B7/C7-1)) | E7: 0.16021742 | F7: 0.10427401 | G7: =IF(OR(E7="",F7=""),"",(E7-F7)*100) | H7: ='11_RSM_Otras_Geo'!C20 | I7: =IFERROR(H7/$H$11,0) | J7: ='11_RSM_Otras_Geo'!D20 | K7: ='11_RSM_Otras_Geo'!E20 | L7: =IFERROR(J7/K7,0)
A8: Cold Storage | B8: 10911 | C8: 0 | D8: =IF(OR(B8="",C8=""),"",IF(C8=0,"n.a.",B8/C8-1)) | E8: 0.28710517 | F8: 0.38680242 | G8: =IF(OR(E8="",F8=""),"",(E8-F8)*100) | H8: ='12_RSM_Cold_Storage'!C20 | I8: =IFERROR(H8/$H$11,0) | J8: ='12_RSM_Cold_Storage'!D20 | K8: ='12_RSM_Cold_Storage'!E20 | L8: =IFERROR(J8/K8,0)
A9: Site Cali | B9: 6625 | C9: 0 | D9: =IF(OR(B9="",C9=""),"",IF(C9=0,"n.a.",B9/C9-1)) | E9: 0.35059275 | F9: 0 | G9: =IF(OR(E9="",F9=""),"",(E9-F9)*100) | H9: ='13_RSM_Site_Cali'!C20 | I9: =IFERROR(H9/$H$11,0) | J9: ='13_RSM_Site_Cali'!D20 | K9: ='13_RSM_Site_Cali'!E20 | L9: =IFERROR(J9/K9,0)
A10: Ventas Alternativas | B10: 5649 | C10: 2669 | D10: =IF(OR(B10="",C10=""),"",IF(C10=0,"n.a.",B10/C10-1)) | E10: 0.41498837 | F10: 0.36956934 | G10: =IF(OR(E10="",F10=""),"",(E10-F10)*100) | H10: ='14_RSM_Vtas_Alt'!C20 | I10: =IFERROR(H10/$H$11,0) | J10: ='14_RSM_Vtas_Alt'!D20 | K10: ='14_RSM_Vtas_Alt'!E20 | L10: =IFERROR(J10/K10,0)
A11: TOTAL | B11: =IF(COUNT(B5:B10)=0,"",SUM(B5:B10)) | C11: =IF(COUNT(C5:C10)=0,"",SUM(C5:C10)) | D11: =IF(OR(B11="",C11=""),"",IF(C11=0,"n.a.",B11/C11-1)) | G11: =IF(OR(E11="",F11=""),"",(E11-F11)*100) | H11: =IF(COUNT(H5:H10)=0,"",SUM(H5:H10)) | I11: =SUM(I5:I10) | J11: =IF(COUNT(J5:J10)=0,"",SUM(J5:J10)) | K11: =IF(COUNT(K5:K10)=0,"",SUM(K5:K10)) | L11: =IFERROR(J11/K11,0)
A12: Control: Σ CM canales vs OI IMP mes (hoja 02) | B12: =IF(B11="","Pendiente",B11-'02_OI'!B7)
A13: Control: OI YTD RSM vs OI YTD IMP (hoja 02) | C13: 114611 | H13: =H11-'02_OI'!E7
C14: =+C13-C11

Sheet 22_Canales_Segmentos
A1: 22 · Motor de canales (Industrial · Distribución · Ventas Alternativas) y segmentos (Construcción · Refrigeración)
A2: Regla: Ventas Alternativas = valor del canal actual · Industrial + Distribución = total IMP − Alternativas, prorrateado con la participación Industrial/(Industrial+Distribución) del canal actual (o el % manual) · Segmentos = total de los 3 canales × % asignado manualmente.
A4: PARÁMETROS
A5: % Construcción por defecto (Refrigeración = 1 − Construcción) | B5: 0.7 | C5: Asigne el % real del mes. Se puede ajustar por métrica en la fila 24.
A8: Concepto (m²) | B8: OI mes CM | C8: OI mes PY | D8: OI YTD | E8: Ventas YTD | F8: Presupuesto YTD (Junta) | G8: Backlog CM | H8: Backlog PY | I8: OI YTD (RSM) | J8: Ventas YTD (RSM)
A9: Fuente del total | B9: 02_OI B7 | C9: 02_OI C7 | D9: 02_OI E7 | E9: 01_Overview E5 | F9: 21_Ppto_Junta N41 | G9: 04_Backlog B5 | H9: 04_Backlog C5 | I9: RSM C11 | J9: RSM D11
A10: Total IMP (m²) | B10: ='02_OI'!B7 | C10: ='02_OI'!C7 | D10: ='02_OI'!E7 | E10: ='01_Overview'!E5 | F10: ='21_Ppto_Junta'!N41 | G10: ='04_Backlog'!B5 | H10: ='04_Backlog'!C5 | I10: =RSM_Resumen_Canales!C11 | J10: =RSM_Resumen_Canales!D11
A11: Ventas Alternativas – canal actual | B11: ='03_OI_Canal'!B10 | C11: ='03_OI_Canal'!C10 | D11: ='03_OI_Canal'!H10 | E11: =RSM_Resumen_Canales!D10 | F11: ='21_Ppto_Junta'!N40 | G11: ='05_Backlog_Canal'!B10 | H11: ='05_Backlog_Canal'!C10 | I11: =RSM_Resumen_Canales!C10 | J11: =RSM_Resumen_Canales!D10
A12: Industrial + Distribución = Total − Alternativas | B12: =B10-B11 | C12: =C10-C11 | D12: =D10-D11 | E12: =E10-E11 | F12: =F10-F11 | G12: =G10-G11 | H12: =H10-H11 | I12: =I10-I11 | J12: =J10-J11
A13: Base prorrateo: Industrial (canal actual) | B13: ='03_OI_Canal'!B5 | C13: ='03_OI_Canal'!C5 | D13: ='03_OI_Canal'!H5 | E13: =RSM_Resumen_Canales!D5 | F13: ='21_Ppto_Junta'!N35 | G13: ='05_Backlog_Canal'!B5 | H13: ='05_Backlog_Canal'!C5 | I13: =RSM_Resumen_Canales!C5 | J13: =RSM_Resumen_Canales!D5
A14: Base prorrateo: Distribución (canal actual) | B14: ='03_OI_Canal'!B6 | C14: ='03_OI_Canal'!C6 | D14: ='03_OI_Canal'!H6 | E14: =RSM_Resumen_Canales!D6 | F14: ='21_Ppto_Junta'!N36 | G14: ='05_Backlog_Canal'!B6 | H14: ='05_Backlog_Canal'!C6 | I14: =RSM_Resumen_Canales!C6 | J14: =RSM_Resumen_Canales!D6
A15: % Industrial – prorrateo automático | B15: =IFERROR(B13/(B13+B14),0.5) | C15: =IFERROR(C13/(C13+C14),0.5) | D15: =IFERROR(D13/(D13+D14),0.5) | E15: =IFERROR(E13/(E13+E14),0.5) | F15: =IFERROR(F13/(F13+F14),0.5) | G15: =IFERROR(G13/(G13+G14),0.5) | H15: =IFERROR(H13/(H13+H14),0.5) | I15: =IFERROR(I13/(I13+I14),0.5) | J15: =IFERROR(J13/(J13+J14),0.5)
A16: % Industrial – ajuste manual (opcional)
A17: % Industrial aplicado | B17: =IF(B16="",B15,B16) | C17: =IF(C16="",C15,C16) | D17: =IF(D16="",D15,D16) | E17: =IF(E16="",E15,E16) | F17: =IF(F16="",F15,F16) | G17: =IF(G16="",G15,G16) | H17: =IF(H16="",H15,H16) | I17: =IF(I16="",I15,I16) | J17: =IF(J16="",J15,J16)
A18: % Distribución aplicado | B18: =1-B17 | C18: =1-C17 | D18: =1-D17 | E18: =1-E17 | F18: =1-F17 | G18: =1-G17 | H18: =1-H17 | I18: =1-I17 | J18: =1-J17
A19: INDUSTRIAL | B19: =B12*B17 | C19: =C12*C17 | D19: =D12*D17 | E19: =E12*E17 | F19: =F12*F17 | G19: =G12*G17 | H19: =H12*H17 | I19: =I12*I17 | J19: =J12*J17
A20: DISTRIBUCIÓN | B20: =B12*B18 | C20: =C12*C18 | D20: =D12*D18 | E20: =E12*E18 | F20: =F12*F18 | G20: =G12*G18 | H20: =H12*H18 | I20: =I12*I18 | J20: =J12*J18
A21: VENTAS ALTERNATIVAS | B21: =B11 | C21: =C11 | D21: =D11 | E21: =E11 | F21: =F11 | G21: =G11 | H21: =H11 | I21: =I11 | J21: =J11
A22: TOTAL CANALES | B22: =SUM(B19:B21) | C22: =SUM(C19:C21) | D22: =SUM(D19:D21) | E22: =SUM(E19:E21) | F22: =SUM(F19:F21) | G22: =SUM(G19:G21) | H22: =SUM(H19:H21) | I22: =SUM(I19:I21) | J22: =SUM(J19:J21)
A23: Control vs total IMP (debe ser 0) | B23: =ROUND(B22-B10,0) | C23: =ROUND(C22-C10,0) | D23: =ROUND(D22-D10,0) | E23: =ROUND(E22-E10,0) | F23: =ROUND(F22-F10,0) | G23: =ROUND(G22-G10,0) | H23: =ROUND(H22-H10,0) | I23: =ROUND(I22-I10,0) | J23: =ROUND(J22-J10,0)
A24: % Construcción – ajuste manual (opcional)
A25: % Construcción aplicado | B25: =IF(B24="",$B$5,B24) | C25: =IF(C24="",$B$5,C24) | D25: =IF(D24="",$B$5,D24) | E25: =IF(E24="",$B$5,E24) | F25: =IF(F24="",$B$5,F24) | G25: =IF(G24="",$B$5,G24) | H25: =IF(H24="",$B$5,H24) | I25: =IF(I24="",$B$5,I24) | J25: =IF(J24="",$B$5,J24)
A26: % Refrigeración aplicado | B26: =1-B25 | C26: =1-C25 | D26: =1-D25 | E26: =1-E25 | F26: =1-F25 | G26: =1-G25 | H26: =1-H25 | I26: =1-I25 | J26: =1-J25
A27: CONSTRUCCIÓN | B27: =B22*B25 | C27: =C22*C25 | D27: =D22*D25 | E27: =E22*E25 | F27: =F22*F25 | G27: =G22*G25 | H27: =H22*H25 | I27: =I22*I25 | J27: =J22*J25
A28: REFRIGERACIÓN | B28: =B22*B26 | C28: =C22*C26 | D28: =D22*D26 | E28: =E22*E26 | F28: =F22*F26 | G28: =G22*G26 | H28: =H22*H26 | I28: =I22*I26 | J28: =J22*J26
A29: TOTAL SEGMENTOS | B29: =B27+B28 | C29: =C27+C28 | D29: =D27+D28 | E29: =E27+E28 | F29: =F27+F28 | G29: =G27+G28 | H29: =H27+H28 | I29: =I27+I28 | J29: =J27+J28
A31: MARGEN BRUTO (GM %) POR CANAL NUEVO – ponderado por volumen
A32: Canal | B32: OI GM CM | C32: OI GM PY | D32: Backlog GM CM | E32: Backlog GM PY
A33: Industrial | B33: =IFERROR(('03_OI_Canal'!B5*'03_OI_Canal'!E5+$B$17*SUMPRODUCT('03_OI_Canal'!B7:B9,'03_OI_Canal'!E7:E9))/('03_OI_Canal'!B5+$B$17*SUM('03_OI_Canal'!B7:B9)),"") | C33: =IFERROR(('03_OI_Canal'!C5*'03_OI_Canal'!F5+$C$17*SUMPRODUCT('03_OI_Canal'!C7:C9,'03_OI_Canal'!F7:F9))/('03_OI_Canal'!C5+$C$17*SUM('03_OI_Canal'!C7:C9)),"") | D33: =IFERROR(('05_Backlog_Canal'!B5*'05_Backlog_Canal'!E5+$G$17*SUMPRODUCT('05_Backlog_Canal'!B7:B9,'05_Backlog_Canal'!E7:E9))/('05_Backlog_Canal'!B5+$G$17*SUM('05_Backlog_Canal'!B7:B9)),"") | E33: =IFERROR(('05_Backlog_Canal'!C5*'05_Backlog_Canal'!F5+$H$17*SUMPRODUCT('05_Backlog_Canal'!C7:C9,'05_Backlog_Canal'!F7:F9))/('05_Backlog_Canal'!C5+$H$17*SUM('05_Backlog_Canal'!C7:C9)),"")
A34: Distribución | B34: =IFERROR(('03_OI_Canal'!B6*'03_OI_Canal'!E6+(1-$B$17)*SUMPRODUCT('03_OI_Canal'!B7:B9,'03_OI_Canal'!E7:E9))/('03_OI_Canal'!B6+(1-$B$17)*SUM('03_OI_Canal'!B7:B9)),"") | C34: =IFERROR(('03_OI_Canal'!C6*'03_OI_Canal'!F6+(1-$C$17)*SUMPRODUCT('03_OI_Canal'!C7:C9,'03_OI_Canal'!F7:F9))/('03_OI_Canal'!C6+(1-$C$17)*SUM('03_OI_Canal'!C7:C9)),"") | D34: =IFERROR(('05_Backlog_Canal'!B6*'05_Backlog_Canal'!E6+(1-$G$17)*SUMPRODUCT('05_Backlog_Canal'!B7:B9,'05_Backlog_Canal'!E7:E9))/('05_Backlog_Canal'!B6+(1-$G$17)*SUM('05_Backlog_Canal'!B7:B9)),"") | E34: =IFERROR(('05_Backlog_Canal'!C6*'05_Backlog_Canal'!F6+(1-$H$17)*SUMPRODUCT('05_Backlog_Canal'!C7:C9,'05_Backlog_Canal'!F7:F9))/('05_Backlog_Canal'!C6+(1-$H$17)*SUM('05_Backlog_Canal'!C7:C9)),"")
A35: Ventas Alternativas | B35: =IFERROR('03_OI_Canal'!E10,"") | C35: =IFERROR('03_OI_Canal'!F10,"") | D35: =IFERROR('05_Backlog_Canal'!E10,"") | E35: =IFERROR('05_Backlog_Canal'!F10,"")
A36: TOTAL (ponderado) | B36: =IFERROR(SUMPRODUCT('03_OI_Canal'!B5:B10,'03_OI_Canal'!E5:E10)/SUM('03_OI_Canal'!B5:B10),"") | C36: =IFERROR(SUMPRODUCT('03_OI_Canal'!C5:C10,'03_OI_Canal'!F5:F10)/SUM('03_OI_Canal'!C5:C10),"") | D36: =IFERROR(SUMPRODUCT('05_Backlog_Canal'!B5:B10,'05_Backlog_Canal'!E5:E10)/SUM('05_Backlog_Canal'!B5:B10),"") | E36: =IFERROR(SUMPRODUCT('05_Backlog_Canal'!C5:C10,'05_Backlog_Canal'!F5:F10)/SUM('05_Backlog_Canal'!C5:C10),"")
A37: Construcción (input opcional)
A38: Refrigeración (input opcional)
A39: Si el GM por segmento queda en blanco, el slide muestra '—'.
A41: TABLA SLIDE · ORDER INTAKE BY CHANNEL – IMP
A42: Canal | B42: OI CM | C42: OI PY | D42: YoY | E42: GM CM | F42: GM PY | G42: Var GM (pp) | H42: OI YTD | I42: Mix YTD | J42: Ventas YTD | K42: Budget YTD | L42: % Budget
A43: Industrial | B43: =B19 | C43: =C19 | D43: =IF(OR(B43="",C43=""),"",IF(C43=0,"n.a.",B43/C43-1)) | E43: =B33 | F43: =C33 | G43: =IF(OR(E43="",F43=""),"",(E43-F43)*100) | H43: =D19 | I43: =IFERROR(H43/$H$46,0) | J43: =E19 | K43: =F19 | L43: =IFERROR(J43/K43,0)
A44: Distribución | B44: =B20 | C44: =C20 | D44: =IF(OR(B44="",C44=""),"",IF(C44=0,"n.a.",B44/C44-1)) | E44: =B34 | F44: =C34 | G44: =IF(OR(E44="",F44=""),"",(E44-F44)*100) | H44: =D20 | I44: =IFERROR(H44/$H$46,0) | J44: =E20 | K44: =F20 | L44: =IFERROR(J44/K44,0)
A45: Ventas Alternativas | B45: =B21 | C45: =C21 | D45: =IF(OR(B45="",C45=""),"",IF(C45=0,"n.a.",B45/C45-1)) | E45: =B35 | F45: =C35 | G45: =IF(OR(E45="",F45=""),"",(E45-F45)*100) | H45: =D21 | I45: =IFERROR(H45/$H$46,0) | J45: =E21 | K45: =F21 | L45: =IFERROR(J45/K45,0)
...

Sheet 21_Ppto_Junta
A1: 21 · Presupuesto de Junta, metas y ventas reales (IMP, m²)
A2: Amarillo = input. Actualice el presupuesto mensual, los % por canal y las ventas reales; todo lo demás (YTD, asignación por canal y por segmento) es fórmula.
A4: Mes de corte (de 02_OI B4) | B4: ='02_OI'!B4
A5: Base de participación por canal | B5: Anterior | C5: Anterior = % de cada canal en el presupuesto previo (RSM). Junta = % mensuales del archivo de Junta (filas 17–21).
A7: Concepto | B7: Ene | C7: Feb | D7: Mar | E7: Abr | F7: May | G7: Jun | H7: Jul | I7: Ago | J7: Sep | K7: Oct | L7: Nov | M7: Dic | N7: YTD (≤ corte) | O7: Total año
A8: N° mes | B8: 1 | C8: 2 | D8: 3 | E8: 4 | F8: 5 | G8: 6 | H8: 7 | I8: 8 | J8: 9 | K8: 10 | L8: 11 | M8: 12
A9: Presupuesto Junta IMP (m²) | B9: 104628 | C9: 96362.693 | D9: 115099.08 | E9: 98564.602 | F9: 106108.77 | G9: 121966.05 | H9: 115931.37 | I9: 143000 | J9: 125010 | K9: 123189 | L9: 132443 | M9: 90000 | N9: =SUMIFS(B9:M9,$B$8:$M$8,"<="&$B$4) | O9: =SUM(B9:M9)
A10: Ventas reales IMP (m²) – mensual | J10: 125933 | K10: 141231 | N10: =SUMIFS(B10:M10,$B$8:$M$8,"<="&$B$4) | O10: =SUM(B10:M10)
A11: % cumplimiento mes | B11: =IF(OR(B10="",B9=0),"",B10/B9) | C11: =IF(OR(C10="",C9=0),"",C10/C9) | D11: =IF(OR(D10="",D9=0),"",D10/D9) | E11: =IF(OR(E10="",E9=0),"",E10/E9) | F11: =IF(OR(F10="",F9=0),"",F10/F9) | G11: =IF(OR(G10="",G9=0),"",G10/G9) | H11: =IF(OR(H10="",H9=0),"",H10/H9) | I11: =IF(OR(I10="",I9=0),"",I10/I9) | ... M11: =IF(OR(M10="",M9=0),"",M10/M9)
A12: Ventas YTD reales – cifra oficial (01_Overview E5) | B12: Si diligencia todos los meses de la fila 10, N10 debe igualar N12. | N12: ='01_Overview'!E5
A13: % cumplimiento YTD vs Presupuesto Junta | N13: =IFERROR(N12/N9,0)
A15: % participación – Presupuesto Junta | B15: Ene | C15: Feb | D15: Mar | E15: Abr | F15: May | G15: Jun | H15: Jul | I15: Ago | J15: Sep | K15: Oct | L15: Nov | M15: Dic | N15: YTD ponderado | O15: Año
A16: (los meses deben sumar 100%; ver control fila 22)
A17: Distribución | B17: 0.1979 | C17: 0.1913 | D17: 0.1937 | E17: 0.2055 | F17: 0.206 | G17: 0.2059 | H17: 0.2054 | I17: 0.2054 | J17: 0.1976 | K17: 0.1976 | L17: 0.2054 | M17: 0.2231 | N17: =IFERROR(SUMPRODUCT(B17:M17,$B$9:$M$9,--($B$8:$M$8<=$B$4))/$N$9,0) | O17: =IFERROR(SUMPRODUCT(B17:M17,$B$9:$M$9)/$O$9,0)
A18: Industrial | B18: 0.4055 | C18: 0.392 | D18: 0.3903 | E18: 0.3658 | F18: 0.3417 | G18: 0.3415 | H18: 0.3407 | I18: 0.3407 | J18: 0.3276 | K18: 0.3683 | L18: 0.384 | M18: 0.416 | N18: =IFERROR(SUMPRODUCT(B18:M18,$B$9:$M$9,--($B$8:$M$8<=$B$4))/$N$9,0) | O18: =IFERROR(SUMPRODUCT(B18:M18,$B$9:$M$9)/$O$9,0)
A19: Otras Geografías | B19: 0.2648 | C19: 0.2987 | D19: 0.3059 | E19: 0.3185 | F19: 0.3193 | G19: 0.3166 | H19: 0.3183 | I19: 0.3183 | J19: 0.3444 | K19: 0.3444 | L19: 0.3183 | M19: 0.2596 | N19: =IFERROR(SUMPRODUCT(B19:M19,$B$9:$M$9,--($B$8:$M$8<=$B$4))/$N$9,0) | O19: =IFERROR(SUMPRODUCT(B19:M19,$B$9:$M$9)/$O$9,0)
A20: SITES (Site Cali) | B20: 0.081 | C20: 0.0783 | D20: 0.078 | E20: 0.0731 | F20: 0.0979 | G20: 0.1008 | H20: 0.1006 | I20: 0.1006 | J20: 0.0967 | K20: 0.056 | L20: 0.0572 | M20: 0.0632 | N20: =IFERROR(SUMPRODUCT(B20:M20,$B$9:$M$9,--($B$8:$M$8<=$B$4))/$N$9,0) | O20: =IFERROR(SUMPRODUCT(B20:M20,$B$9:$M$9)/$O$9,0)
A21: Ventas Alternativas | B21: 0.0508 | C21: 0.0398 | D21: 0.0321 | E21: 0.0371 | F21: 0.0351 | G21: 0.0351 | H21: 0.035 | I21: 0.035 | J21: 0.0337 | K21: 0.0337 | L21: 0.035 | M21: 0.0381 | N21: =IFERROR(SUMPRODUCT(B21:M21,$B$9:$M$9,--($B$8:$M$8<=$B$4))/$N$9,0) | O21: =IFERROR(SUMPRODUCT(B21:M21,$B$9:$M$9)/$O$9,0)
A22: Control Σ % | B22: =SUM(B17:B21) | C22: =SUM(C17:C21) | D22: =SUM(D17:D21) | E22: =SUM(E17:E21) | F22: =SUM(F17:F21) | G22: =SUM(G17:G21) | H22: =SUM(H17:H21) | I22: =SUM(I17:I21) | ... O22: =SUM(O17:O21)
A24: Canal (estructura anterior) | B24: Budget anterior YTD (RSM) | C24: % part. anterior | D24: % part. Junta YTD | E24: % part. aplicada
A25: Industrial | B25: =RSM_Resumen_Canales!E5 | C25: =IFERROR(B25/$B$31,0) | D25: =N18 | E25: =IF($B$5="Junta",D25,C25)
A26: Distribution | B26: =RSM_Resumen_Canales!E6 | C26: =IFERROR(B26/$B$31,0) | D26: =N17 | E26: =IF($B$5="Junta",D26,C26)
A27: Other Geographies | B27: =RSM_Resumen_Canales!E7 | C27: =IFERROR(B27/$B$31,0) | D27: =N19 | E27: =IF($B$5="Junta",D27,C27)
A28: Cold Storage | B28: =RSM_Resumen_Canales!E8 | C28: =IFERROR(B28/$B$31,0) | D28: 0 | E28: =IF($B$5="Junta",D28,C28)
A29: Site Cali | B29: =RSM_Resumen_Canales!E9 | C29: =IFERROR(B29/$B$31,0) | D29: =N20 | E29: =IF($B$5="Junta",D29,C29)
A30: Alternative Sales | B30: =RSM_Resumen_Canales!E10 | C30: =IFERROR(B30/$B$31,0) | D30: =N21 | E30: =IF($B$5="Junta",D30,C30)
A31: TOTAL | B31: =SUM(B25:B30) | C31: =SUM(C25:C30) | D31: =SUM(D25:D30) | E31: =SUM(E25:E30)
A33: Presupuesto Junta por canal anterior (m²) | B33: Ene | C33: Feb | D33: Mar | E33: Abr | F33: May | G33: Jun | H33: Jul | I33: Ago | J33: Sep | K33: Oct | L33: Nov | M33: Dic | N33: YTD (≤ corte) | O33: Total año
A34: (base = selector B5)
A35: Industrial | B35: =IF($B$5="Junta",B$9*B18,B$9*$C25) | C35: =IF($B$5="Junta",C$9*C18,C$9*$C25) | D35: =IF($B$5="Junta",D$9*D18,D$9*$C25) | E35: =IF($B$5="Junta",E$9*E18,E$9*$C25) | F35: =IF($B$5="Junta",F$9*F18,F$9*$C25) | G35: =IF($B$5="Junta",G$9*G18,G$9*$C25) | H35: =IF($B$5="Junta",H$9*H18,H$9*$C25) | I35: =IF($B$5="Junta",I$9*I18,I$9*$C25) | ... M35: =IF($B$5="Junta",M$9*M18,M$9*$C25) | N35: =SUMIFS(B35:M35,$B$8:$M$8,"<="&$B$4) | O35: =SUM(B35:M35)
A36: Distribution | B36: =IF($B$5="Junta",B$9*B17,B$9*$C26) | C36: =IF($B$5="Junta",C$9*C17,C$9*$C26) | D36: =IF($B$5="Junta",D$9*D17,D$9*$C26) | E36: =IF($B$5="Junta",E$9*E17,E$9*$C26) | F36: =IF($B$5="Junta",F$9*F17,F$9*$C26) | G36: =IF($B$5="Junta",G$9*G17,G$9*$C26) | H36: =IF($B$5="Junta",H$9*H17,H$9*$C26) | I36: =IF($B$5="Junta",I$9*I17,I$9*$C26) | ... M36: =IF($B$5="Junta",M$9*M17,M$9*$C26) | N36: =SUMIFS(B36:M36,$B$8:$M$8,"<="&$B$4) | O36: =SUM(B36:M36)
A37: Other Geographies | B37: =IF($B$5="Junta",B$9*B19,B$9*$C27) | C37: =IF($B$5="Junta",C$9*C19,C$9*$C27) | D37: =IF($B$5="Junta",D$9*D19,D$9*$C27) | E37: =IF($B$5="Junta",E$9*E19,E$9*$C27) | F37: =IF($B$5="Junta",F$9*F19,F$9*$C27) | G37: =IF($B$5="Junta",G$9*G19,G$9*$C27) | H37: =IF($B$5="Junta",H$9*H19,H$9*$C27) | I37: =IF($B$5="Junta",I$9*I19,I$9*$C27) | ... M37: =IF($B$5="Junta",M$9*M19,M$9*$C27) | N37: =SUMIFS(B37:M37,$B$8:$M$8,"<="&$B$4) | O37: =SUM(B37:M37)
A38: Cold Storage | B38: =IF($B$5="Junta",0,B$9*$C28) | C38: =IF($B$5="Junta",0,C$9*$C28) | D38: =IF($B$5="Junta",0,D$9*$C28) | E38: =IF($B$5="Junta",0,E$9*$C28) | F38: =IF($B$5="Junta",0,F$9*$C28) | G38: =IF($B$5="Junta",0,G$9*$C28) | H38: =IF($B$5="Junta",0,H$9*$C28) | I38: =IF($B$5="Junta",0,I$9*$C28) | ... M38: =IF($B$5="Junta",0,M$9*$C28) | N38: =SUMIFS(B38:M38,$B$8:$M$8,"<="&$B$4) | O38: =SUM(B38:M38)
A39: Site Cali | B39: =IF($B$5="Junta",B$9*B20,B$9*$C29) | C39: =IF($B$5="Junta",C$9*C20,C$9*$C29) | D39: =IF($B$5="Junta",D$9*D20,D$9*$C29) | E39: =IF($B$5="Junta",E$9*E20,E$9*$C29) | F39: =IF($B$5="Junta",F$9*F20,F$9*$C29) | G39: =IF($B$5="Junta",G$9*G20,G$9*$C29) | H39: =IF($B$5="Junta",H$9*H20,H$9*$C29) | I39: =IF($B$5="Junta",I$9*I20,I$9*$C29) | ... M39: =IF($B$5="Junta",M$9*M20,M$9*$C29) | N39: =SUMIFS(B39:M39,$B$8:$M$8,"<="&$B$4) | O39: =SUM(B39:M39)
A40: Alternative Sales | B40: =IF($B$5="Junta",B$9*B21,B$9*$C30) | C40: =IF($B$5="Junta",C$9*C21,C$9*$C30) | D40: =IF($B$5="Junta",D$9*D21,D$9*$C30) | E40: =IF($B$5="Junta",E$9*E21,E$9*$C30) | F40: =IF($B$5="Junta",F$9*F21,F$9*$C30) | G40: =IF($B$5="Junta",G$9*G21,G$9*$C30) | H40: =IF($B$5="Junta",H$9*H21,H$9*$C30) | I40: =IF($B$5="Junta",I$9*I21,I$9*$C30) | ... M40: =IF($B$5="Junta",M$9*M21,M$9*$C30) | N40: =SUMIFS(B40:M40,$B$8:$M$8,"<="&$B$4) | O40: =SUM(B40:M40)
A41: TOTAL | B41: =SUM(B35:B40) | C41: =SUM(C35:C40) | D41: =SUM(D35:D40) | E41: =SUM(E35:E40) | F41: =SUM(F35:F40) | G41: =SUM(G35:G40) | H41: =SUM(H35:H40) | I41: =SUM(I35:I40) | ... O41: =SUM(O35:O40)
A43: Presupuesto por nueva estructura (m²) | B43: Ene | C43: Feb | D43: Mar | E43: Abr | F43: May | G43: Jun | H43: Jul | I43: Ago | J43: Sep | K43: Oct | L43: Nov | M43: Dic | N43: YTD (≤ corte) | O43: Total año
A44: Ventas Alternativas | B44: =B40 | C44: =C40 | D44: =D40 | E44: =E40 | F44: =F40 | G44: =G40 | H44: =H40 | I44: =I40 | ... M44: =M40 | N44: =SUMIFS(B44:M44,$B$8:$M$8,"<="&$B$4) | O44: =SUM(B44:M44)
A45: Industrial + Distribución (total − Alternativas) | B45: =B41-B44 | C45: =C41-C44 | D45: =D41-D44 | E45: =E41-E44 | F45: =F41-F44 | G45: =G41-G44 | H45: =H41-H44 | I45: =I41-I44 | ... M45: =M41-M44 | N45: =SUMIFS(B45:M45,$B$8:$M$8,"<="&$B$4) | O45: =SUM(B45:M45)
A46: % Industrial (prorrateo, hoja 22) | B46: ='22_Canales_Segmentos'!$F$17 | C46: ='22_Canales_Segmentos'!$F$17 | D46: ='22_Canales_Segmentos'!$F$17 | E46: ='22_Canales_Segmentos'!$F$17 | F46: ='22_Canales_Segmentos'!$F$17 | G46: ='22_Canales_Segmentos'!$F$17 | H46: ='22_Canales_Segmentos'!$F$17 | I46: ='22_Canales_Segmentos'!$F$17 | ... N46: ='22_Canales_Segmentos'!$F$17
...

Sheet 04_Backlog
A1: 04 · Backlog – Octuber
A2: Tabla por producto + progresión mensual del backlog (COP MM) y margen
A4: Producto / métrica | B4: Mes actual | C4: PY | D4: Δ vs PY | E4: 1 Ene 2026 | F4: Δ vs 1 Ene
A5: IMP – Volume (m²) | B5: 525529 | C5: 360246 | D5: =IF(OR(B5="",C5=""),"",IF(C5=0,"n.a.",B5/C5-1)) | E5: 364496 | F5: =IF(OR(B5="",E5=""),"",IF(E5=0,"n.a.",B5/E5-1))
A6: Kingcore – Volume (m²) | B6: 78432 | C6: 38588 | D6: =IF(OR(B6="",C6=""),"",IF(C6=0,"n.a.",B6/C6-1)) | E6: 22362 | F6: =IF(OR(B6="",E6=""),"",IF(E6=0,"n.a.",B6/E6-1))
A7: Single Skin – Volume (m²) | B7: 57196 | C7: 21370 | D7: =IF(OR(B7="",C7=""),"",IF(C7=0,"n.a.",B7/C7-1)) | E7: 21486 | F7: =IF(OR(B7="",E7=""),"",IF(E7=0,"n.a.",B7/E7-1))
A8: Benchmark – Volume (m²) | B8: 12167 | C8: 894 | D8: =IF(OR(B8="",C8=""),"",IF(C8=0,"n.a.",B8/C8-1)) | E8: 349 | F8: =IF(OR(B8="",E8=""),"",IF(E8=0,"n.a.",B8/E8-1))
A9: IMP – Revenue (COP MM) | B9: 49836 | C9: 35225 | D9: =IF(OR(B9="",C9=""),"",IF(C9=0,"n.a.",B9/C9-1)) | E9: 35477 | F9: =IF(OR(B9="",E9=""),"",IF(E9=0,"n.a.",B9/E9-1))
A10: Margen (Std) | B10: 0.273 | C10: 0.25 | D10: =(B10-C10)*100 | E10: 0.25 | F10: =(B10-E10)*100
A11: Margen (Std) sin Canpack | B11: 0.277 | C11: 0.25 | D11: =(B11-C11)*100 | E11: 0.25 | F11: =(B11-E11)*100
A13: N° mes | B13: Mes | C13: Backlog CY (COP MM) | D13: Backlog PY (COP MM) | E13: YoY | F13: Margen CY % | G13: Etiqueta barra 2026: Backlog m² (input) | H13: Etiqueta barra 2025: Backlog m² (input)
A14: 1 | B14: Jan | C14: 35566.1 | D14: 30422.1 | E14: =IF(OR(C14="",D14=""),"",IF(D14=0,"n.a.",C14/D14-1)) | F14: 0.251
A15: 2 | B15: Feb | C15: 36104.5 | D15: 31461.6 | E15: =IF(OR(C15="",D15=""),"",IF(D15=0,"n.a.",C15/D15-1)) | F15: 0.254
A16: 3 | B16: Mar | C16: 39420.9 | D16: 36223.7 | E16: =IF(OR(C16="",D16=""),"",IF(D16=0,"n.a.",C16/D16-1)) | F16: 0.259
A17: 4 | B17: Apr | C17: 38886.8 | D17: 34454.1 | E17: =IF(OR(C17="",D17=""),"",IF(D17=0,"n.a.",C17/D17-1)) | F17: 0.253
A18: 5 | B18: May | C18: 55927.6 | D18: 31842.8 | E18: =IF(OR(C18="",D18=""),"",IF(D18=0,"n.a.",C18/D18-1)) | F18: 0.226
A19: 6 | B19: Jun | C19: 56477.9 | D19: 33251.2 | E19: =IF(OR(C19="",D19=""),"",IF(D19=0,"n.a.",C19/D19-1)) | F19: 0.239
A20: 7 | B20: Jul | C20: 57136.5 | D20: 30680.1 | E20: =IF(OR(C20="",D20=""),"",IF(D20=0,"n.a.",C20/D20-1)) | F20: 0.241
A21: 8 | B21: Aug | C21: 51456.1 | D21: 34736.9 | E21: =IF(OR(C21="",D21=""),"",IF(D21=0,"n.a.",C21/D21-1)) | F21: 0.241
A22: 9 | B22: Sep | C22: 50189 | D22: 33247.5 | E22: =IF(OR(C22="",D22=""),"",IF(D22=0,"n.a.",C22/D22-1)) | F22: 0.273 | G22: 498453 | H22: 347834
A23: 10 | B23: Oct | C23: 49836 | D23: 35224.5 | E23: =IF(OR(C23="",D23=""),"",IF(D23=0,"n.a.",C23/D23-1)) | F23: =B10 | G23: 525529 | H23: 360246
A24: 11 | B24: Nov | D24: 34456 | E24: =IF(OR(C24="",D24=""),"",IF(D24=0,"n.a.",C24/D24-1))
A25: 12 | B25: Dec | D25: 35476.9 | E25: =IF(OR(C25="",D25=""),"",IF(D25=0,"n.a.",C25/D25-1))

Sheet 05_Backlog_Canal
A1: 05 · Backlog por canal (IMP)
A2: CM se alimenta del backlog por RSM (hojas 09–14); PY y márgenes se diligencian | F2: 537065 | G2: 525529 | H2: =F2-G2
A4: Canal | B4: Backlog CM (m²) – RSM | C4: Backlog PY (m²) | D4: YoY | E4: GM % CM | F4: GM % PY | G4: Δ GM (pp) | H4: Mix % | I4: Backlog paneles | J4: Backlog otros
A5: Industrial | B5: =251984-11536 | C5: 170762.19 | D5: =IF(OR(B5="",C5=""),"",IF(C5=0,"n.a.",B5/C5-1)) | E5: 0.33117136 | F5: 0.28692083 | G5: =IF(OR(E5="",F5=""),"",(E5-F5)*100) | H5: =IFERROR(B5/$B$11,0) | I5: ='09_RSM_Industrial'!H18 | J5: ='09_RSM_Industrial'!I18
A6: Distribución | B6: 62499 | C6: 50628.625 | D6: =IF(OR(B6="",C6=""),"",IF(C6=0,"n.a.",B6/C6-1)) | E6: 0.29966956 | F6: 0.2701004 | G6: =IF(OR(E6="",F6=""),"",(E6-F6)*100) | H6: =IFERROR(B6/$B$11,0) | I6: ='10_RSM_Distribucion'!H20 | J6: ='10_RSM_Distribucion'!I20
A7: Otras Geografías | B7: 166377 | C7: 121006.42 | D7: =IF(OR(B7="",C7=""),"",IF(C7=0,"n.a.",B7/C7-1)) | E7: 0.14624363 | F7: 0.10427401 | G7: =IF(OR(E7="",F7=""),"",(E7-F7)*100) | H7: =IFERROR(B7/$B$11,0) | I7: ='11_RSM_Otras_Geo'!H20 | J7: ='11_RSM_Otras_Geo'!I20
A8: Cold Storage | B8: 28642 | C8: 1127.0509 | D8: =IF(OR(B8="",C8=""),"",IF(C8=0,"n.a.",B8/C8-1)) | E8: 0.28058377 | F8: 0.38680242 | G8: =IF(OR(E8="",F8=""),"",(E8-F8)*100) | H8: =IFERROR(B8/$B$11,0) | I8: ='12_RSM_Cold_Storage'!H20 | J8: ='12_RSM_Cold_Storage'!I20
A9: Site Cali | B9: 21774 | C9: 0 | D9: =IF(OR(B9="",C9=""),"",IF(C9=0,"n.a.",B9/C9-1)) | E9: 0.36773598 | F9: 0 | G9: =IF(OR(E9="",F9=""),"",(E9-F9)*100) | H9: =IFERROR(B9/$B$11,0) | I9: ='13_RSM_Site_Cali'!H20 | J9: ='13_RSM_Site_Cali'!I20
A10: Ventas Alternativas | B10: 5789 | C10: 4309.7179 | D10: =IF(OR(B10="",C10=""),"",IF(C10=0,"n.a.",B10/C10-1)) | E10: 0.45275886 | F10: 0.36956934 | G10: =IF(OR(E10="",F10=""),"",(E10-F10)*100) | H10: =IFERROR(B10/$B$11,0) | I10: ='14_RSM_Vtas_Alt'!H20 | J10: ='14_RSM_Vtas_Alt'!I20
A11: TOTAL | B11: =SUM(B5:B10) | C11: =IF(COUNT(C5:C10)=0,"",SUM(C5:C10)) | D11: =IF(OR(B11="",C11=""),"",IF(C11=0,"n.a.",B11/C11-1)) | G11: =IF(OR(E11="",F11=""),"",(E11-F11)*100) | H11: =SUM(H5:H10) | I11: =SUM(I5:I10) | J11: =SUM(J5:J10)
A12: Control: backlog RSM vs backlog IMP (hoja 04) | B12: =B11-'04_Backlog'!B5

Sheet 06_Perf_Forecast
A1: 06 · Performed / Forecast OI 2026
A2: Real vs forecast mensual, acumulados, trimestres y comparativo vs PY
A4: Mes de corte (último mes real) | B4: ='02_OI'!B4
A6: N° mes | B6: Mes | C6: Trimestre | D6: Estado | E6: Volumen m² | F6: Ingresos COP MM | G6: Acum. volumen m² | H6: Acum. ingresos COP MM | I6: Fuente gráfico: Real | J6: Fuente gráfico: Forecast
A7: 1 | B7: Jan | C7: ="Q"&ROUNDUP(A7/3,0) | D7: =IF(A7<=$B$4,"Real","Forecast") | E7: 104582 | F7: 9968.166 | G7: =SUM($E$7:E7) | H7: =SUM($F$7:F7) | I7: =IF(D7="Real",E7,0) | J7: =IF(D7="Forecast",E7,0)
A8: 2 | B8: Feb | C8: ="Q"&ROUNDUP(A8/3,0) | D8: =IF(A8<=$B$4,"Real","Forecast") | E8: 127405 | F8: 12767.714 | G8: =SUM($E$7:E8) | H8: =SUM($F$7:F8) | I8: =IF(D8="Real",E8,0) | J8: =IF(D8="Forecast",E8,0)
A9: 3 | B9: Mar | C9: ="Q"&ROUNDUP(A9/3,0) | D9: =IF(A9<=$B$4,"Real","Forecast") | E9: 152049 | F9: 14462.925 | G9: =SUM($E$7:E9) | H9: =SUM($F$7:F9) | I9: =IF(D9="Real",E9,0) | J9: =IF(D9="Forecast",E9,0)
A10: 4 | B10: Apr | C10: ="Q"&ROUNDUP(A10/3,0) | D10: =IF(A10<=$B$4,"Real","Forecast") | E10: 126530 | F10: 12270.448 | G10: =SUM($E$7:E10) | H10: =SUM($F$7:F10) | I10: =IF(D10="Real",E10,0) | J10: =IF(D10="Forecast",E10,0)
A11: 5 | B11: May | C11: ="Q"&ROUNDUP(A11/3,0) | D11: =IF(A11<=$B$4,"Real","Forecast") | E11: 181126 | F11: 27093.858 | G11: =SUM($E$7:E11) | H11: =SUM($F$7:F11) | I11: =IF(D11="Real",E11,0) | J11: =IF(D11="Forecast",E11,0)
A12: 6 | B12: Jun | C12: ="Q"&ROUNDUP(A12/3,0) | D12: =IF(A12<=$B$4,"Real","Forecast") | E12: 124406 | F12: 12022.773 | G12: =SUM($E$7:E12) | H12: =SUM($F$7:F12) | I12: =IF(D12="Real",E12,0) | J12: =IF(D12="Forecast",E12,0)
A13: 7 | B13: Jul | C13: ="Q"&ROUNDUP(A13/3,0) | D13: =IF(A13<=$B$4,"Real","Forecast") | E13: 114336 | F13: 11718.909 | G13: =SUM($E$7:E13) | H13: =SUM($F$7:F13) | I13: =IF(D13="Real",E13,0) | J13: =IF(D13="Forecast",E13,0)
A14: 8 | B14: Aug | C14: ="Q"&ROUNDUP(A14/3,0) | D14: =IF(A14<=$B$4,"Real","Forecast") | E14: 151623 | F14: 14500.72 | G14: =SUM($E$7:E14) | H14: =SUM($F$7:F14) | I14: =IF(D14="Real",E14,0) | J14: =IF(D14="Forecast",E14,0)
A15: 9 | B15: Sep | C15: ="Q"&ROUNDUP(A15/3,0) | D15: =IF(A15<=$B$4,"Real","Forecast") | E15: 146446 | F15: 13740.67 | G15: =SUM($E$7:E15) | H15: =SUM($F$7:F15) | I15: =IF(D15="Real",E15,0) | J15: =IF(D15="Forecast",E15,0)
A16: 10 | B16: Oct | C16: ="Q"&ROUNDUP(A16/3,0) | D16: =IF(A16<=$B$4,"Real","Forecast") | E16: 160547 | F16: 14484 | G16: =SUM($E$7:E16) | H16: =SUM($F$7:F16) | I16: =IF(D16="Real",E16,0) | J16: =IF(D16="Forecast",E16,0)
A17: 11 | B17: Nov | C17: ="Q"&ROUNDUP(A17/3,0) | D17: =IF(A17<=$B$4,"Real","Forecast") | E17: 140000 | F17: 15077.152 | G17: =SUM($E$7:E17) | H17: =SUM($F$7:F17) | I17: =IF(D17="Real",E17,0) | J17: =IF(D17="Forecast",E17,0)
A18: 12 | B18: Dec | C18: ="Q"&ROUNDUP(A18/3,0) | D18: =IF(A18<=$B$4,"Real","Forecast") | E18: 122000 | F18: 13335.741 | G18: =SUM($E$7:E18) | H18: =SUM($F$7:F18) | I18: =IF(D18="Real",E18,0) | J18: =IF(D18="Forecast",E18,0)
A20: Trimestre | E20: Volumen m² | F20: Ingresos COP MM
A21: Q1 | E21: =SUMIFS($E$7:$E$18,$C$7:$C$18,A21) | F21: =SUMIFS($F$7:$F$18,$C$7:$C$18,A21)
A22: Q2 | E22: =SUMIFS($E$7:$E$18,$C$7:$C$18,A22) | F22: =SUMIFS($F$7:$F$18,$C$7:$C$18,A22)
A23: Q3 | E23: =SUMIFS($E$7:$E$18,$C$7:$C$18,A23) | F23: =SUMIFS($F$7:$F$18,$C$7:$C$18,A23)
A24: Q4 | E24: =SUMIFS($E$7:$E$18,$C$7:$C$18,A24) | F24: =SUMIFS($F$7:$F$18,$C$7:$C$18,A24)
A26: Comparativo IMP | B26: 2026 (m²) | C26: 2025 PY (m²) | D26: YoY m² | E26: 2026 COP MM | F26: 2025 COP MM | G26: YoY COP | H26: GM 2026 | I26: GM 2025 | J26: Δ GM pp
A27: Mes actual (CM) | B27: 160547 | C27: 132619 | D27: =IF(OR(B27="",C27=""),"",IF(C27=0,"n.a.",B27/C27-1)) | E27: 14484 | F27: 10674 | G27: =IF(OR(E27="",F27=""),"",IF(F27=0,"n.a.",E27/F27-1)) | H27: 0.27 | I27: 0.24 | J27: =IF(OR(H27="",I27=""),"",(H27-I27)*100)
A28: YTD real | B28: 1400088 | C28: 1120898 | D28: =IF(OR(B28="",C28=""),"",IF(C28=0,"n.a.",B28/C28-1)) | E28: =SUMIFS(F7:F18,A7:A18,"<="&$B$4) | F28: 95505 | G28: =IF(OR(E28="",F28=""),"",IF(F28=0,"n.a.",E28/F28-1)) | H28: 0.25 | I28: 0.24 | J28: =IF(OR(H28="",I28=""),"",(H28-I28)*100)
A29: Forecast resto del año | B29: =SUMIFS(E7:E18,A7:A18,">"&$B$4) | C29: =C30-C28 | D29: =IF(OR(B29="",C29=""),"",IF(C29=0,"n.a.",B29/C29-1)) | E29: =SUMIFS(F7:F18,A7:A18,">"&$B$4) | F29: =F30-F28 | G29: =IF(OR(E29="",F29=""),"",IF(F29=0,"n.a.",E29/F29-1)) | J29: =IF(OR(H29="",I29=""),"",(H29-I29)*100)
A30: Cierre año (Real + Fcst) | B30: =SUM(E7:E18) | C30: 1359841 | D30: =IF(OR(B30="",C30=""),"",IF(C30=0,"n.a.",B30/C30-1)) | E30: =SUM(F7:F18) | F30: 131135.75 | G30: =IF(OR(E30="",F30=""),"",IF(F30=0,"n.a.",E30/F30-1)) | J30: =IF(OR(H30="",I30=""),"",(H30-I30)*100)
A32: Avance vs cierre año (volumen) | B32: =B28/B30

Sheet 07_Top_Opps
A1: 07 · Top Opportunities (pipeline abierto)
A2: Top 5 por segmento, automático desde la hoja Pipeline · criterio seleccionable
A4: Criterio de orden (cambiar en hoja Pipeline!C4): | E4: =Pipeline!C4
A6: Industrial – Top 5 oportunidades abiertas
A7: # | B7: Cliente | C7: Proyecto | D7: País | E7: Portafolio (Type) | F7: Ejecutivo | G7: m² | H7: USD | I7: Estado | J7: % Cierre | K7: Fecha cierre | L7: Valor ponderado
A8: 1 | B8: =IFERROR(IF(INDEX(Pipeline!$B$7:$B$67,MATCH(LARGE(Pipeline!$M$7:$M$67,1),Pipeline!$M$7:$M$67,0))="","—",INDEX(Pipeline!$B$7:$B$67,MATCH(LARGE(Pipeline!$M$7:$M$67,1),Pipeline!$M$7:$M$67,0))),"") | C8: =IFERROR(IF(INDEX(Pipeline!$C$7:$C$67,MATCH(LARGE(Pipeline!$M$7:$M$67,1),Pipeline!$M$7:$M$67,0))="","—",INDEX(Pipeline!$C$7:$C$67,MATCH(LARGE(Pipeline!$M$7:$M$67,1),Pipeline!$M$7:$M$67,0))),"") | D8: =IFERROR(IF(INDEX(Pipeline!$E$7:$E$67,MATCH(LARGE(Pipeline!$M$7:$M$67,1),Pipeline!$M$7:$M$67,0))="","—",INDEX(Pipeline!$E$7:$E$67,MATCH(LARGE(Pipeline!$M$7:$M$67,1),Pipeline!$M$7:$M$67,0))),"") | E8: =IFERROR(IF(INDEX(Pipeline!$F$7:$F$67,MATCH(LARGE(Pipeline!$M$7:$M$67,1),Pipeline!$M$7:$M$67,0))="","—",INDEX(Pipeline!$F$7:$F$67,MATCH(LARGE(Pipeline!$M$7:$M$67,1),Pipeline!$M$7:$M$67,0))),"") | F8: =IFERROR(IF(INDEX(Pipeline!$D$7:$D$67,MATCH(LARGE(Pipeline!$M$7:$M$67,1),Pipeline!$M$7:$M$67,0))="","—",INDEX(Pipeline!$D$7:$D$67,MATCH(LARGE(Pipeline!$M$7:$M$67,1),Pipeline!$M$7:$M$67,0))),"") | G8: =IFERROR(IF(INDEX(Pipeline!$G$7:$G$67,MATCH(LARGE(Pipeline!$M$7:$M$67,1),Pipeline!$M$7:$M$67,0))="","—",INDEX(Pipeline!$G$7:$G$67,MATCH(LARGE(Pipeline!$M$7:$M$67,1),Pipeline!$M$7:$M$67,0))),"") | H8: =IFERROR(IF(INDEX(Pipeline!$H$7:$H$67,MATCH(LARGE(Pipeline!$M$7:$M$67,1),Pipeline!$M$7:$M$67,0))="","—",INDEX(Pipeline!$H$7:$H$67,MATCH(LARGE(Pipeline!$M$7:$M$67,1),Pipeline!$M$7:$M$67,0))),"") | I8: =IFERROR(IF(INDEX(Pipeline!$I$7:$I$67,MATCH(LARGE(Pipeline!$M$7:$M$67,1),Pipeline!$M$7:$M$67,0))="","—",INDEX(Pipeline!$I$7:$I$67,MATCH(LARGE(Pipeline!$M$7:$M$67,1),Pipeline!$M$7:$M$67,0))),"") | J8: =IFERROR(IF(INDEX(Pipeline!$J$7:$J$67,MATCH(LARGE(Pipeline!$M$7:$M$67,1),Pipeline!$M$7:$M$67,0))="","—",INDEX(Pipeline!$J$7:$J$67,MATCH(LARGE(Pipeline!$M$7:$M$67,1),Pipeline!$M$7:$M$67,0))),"") | K8: =IFERROR(IF(INDEX(Pipeline!$K$7:$K$67,MATCH(LARGE(Pipeline!$M$7:$M$67,1),Pipeline!$M$7:$M$67,0))="","—",INDEX(Pipeline!$K$7:$K$67,MATCH(LARGE(Pipeline!$M$7:$M$67,1),Pipeline!$M$7:$M$67,0))),"") | L8: =IFERROR(IF(INDEX(Pipeline!$L$7:$L$67,MATCH(LARGE(Pipeline!$M$7:$M$67,1),Pipeline!$M$7:$M$67,0))="","—",INDEX(Pipeline!$L$7:$L$67,MATCH(LARGE(Pipeline!$M$7:$M$67,1),Pipeline!$M$7:$M$67,0))),"")
A9: 2 | B9: =IFERROR(IF(INDEX(Pipeline!$B$7:$B$67,MATCH(LARGE(Pipeline!$M$7:$M$67,2),Pipeline!$M$7:$M$67,0))="","—",INDEX(Pipeline!$B$7:$B$67,MATCH(LARGE(Pipeline!$M$7:$M$67,2),Pipeline!$M$7:$M$67,0))),"") | C9: =IFERROR(IF(INDEX(Pipeline!$C$7:$C$67,MATCH(LARGE(Pipeline!$M$7:$M$67,2),Pipeline!$M$7:$M$67,0))="","—",INDEX(Pipeline!$C$7:$C$67,MATCH(LARGE(Pipeline!$M$7:$M$67,2),Pipeline!$M$7:$M$67,0))),"") | D9: =IFERROR(IF(INDEX(Pipeline!$E$7:$E$67,MATCH(LARGE(Pipeline!$M$7:$M$67,2),Pipeline!$M$7:$M$67,0))="","—",INDEX(Pipeline!$E$7:$E$67,MATCH(LARGE(Pipeline!$M$7:$M$67,2),Pipeline!$M$7:$M$67,0))),"") | E9: =IFERROR(IF(INDEX(Pipeline!$F$7:$F$67,MATCH(LARGE(Pipeline!$M$7:$M$67,2),Pipeline!$M$7:$M$67,0))="","—",INDEX(Pipeline!$F$7:$F$67,MATCH(LARGE(Pipeline!$M$7:$M$67,2),Pipeline!$M$7:$M$67,0))),"") | F9: =IFERROR(IF(INDEX(Pipeline!$D$7:$D$67,MATCH(LARGE(Pipeline!$M$7:$M$67,2),Pipeline!$M$7:$M$67,0))="","—",INDEX(Pipeline!$D$7:$D$67,MATCH(LARGE(Pipeline!$M$7:$M$67,2),Pipeline!$M$7:$M$67,0))),"") | G9: 61000 | H9: 1694102 | I9: =IFERROR(IF(INDEX(Pipeline!$I$7:$I$67,MATCH(LARGE(Pipeline!$M$7:$M$67,2),Pipeline!$M$7:$M$67,0))="","—",INDEX(Pipeline!$I$7:$I$67,MATCH(LARGE(Pipeline!$M$7:$M$67,2),Pipeline!$M$7:$M$67,0))),"") | J9: =IFERROR(IF(INDEX(Pipeline!$J$7:$J$67,MATCH(LARGE(Pipeline!$M$7:$M$67,2),Pipeline!$M$7:$M$67,0))="","—",INDEX(Pipeline!$J$7:$J$67,MATCH(LARGE(Pipeline!$M$7:$M$67,2),Pipeline!$M$7:$M$67,0))),"") | K9: =IFERROR(IF(INDEX(Pipeline!$K$7:$K$67,MATCH(LARGE(Pipeline!$M$7:$M$67,2),Pipeline!$M$7:$M$67,0))="","—",INDEX(Pipeline!$K$7:$K$67,MATCH(LARGE(Pipeline!$M$7:$M$67,2),Pipeline!$M$7:$M$67,0))),"") | L9: =IFERROR(IF(INDEX(Pipeline!$L$7:$L$67,MATCH(LARGE(Pipeline!$M$7:$M$67,2),Pipeline!$M$7:$M$67,0))="","—",INDEX(Pipeline!$L$7:$L$67,MATCH(LARGE(Pipeline!$M$7:$M$67,2),Pipeline!$M$7:$M$67,0))),"")
A10: 3 | B10: =IFERROR(IF(INDEX(Pipeline!$B$7:$B$67,MATCH(LARGE(Pipeline!$M$7:$M$67,3),Pipeline!$M$7:$M$67,0))="","—",INDEX(Pipeline!$B$7:$B$67,MATCH(LARGE(Pipeline!$M$7:$M$67,3),Pipeline!$M$7:$M$67,0))),"") | C10: =IFERROR(IF(INDEX(Pipeline!$C$7:$C$67,MATCH(LARGE(Pipeline!$M$7:$M$67,3),Pipeline!$M$7:$M$67,0))="","—",INDEX(Pipeline!$C$7:$C$67,MATCH(LARGE(Pipeline!$M$7:$M$67,3),Pipeline!$M$7:$M$67,0))),"") | D10: =IFERROR(IF(INDEX(Pipeline!$E$7:$E$67,MATCH(LARGE(Pipeline!$M$7:$M$67,3),Pipeline!$M$7:$M$67,0))="","—",INDEX(Pipeline!$E$7:$E$67,MATCH(LARGE(Pipeline!$M$7:$M$67,3),Pipeline!$M$7:$M$67,0))),"") | E10: =IFERROR(IF(INDEX(Pipeline!$F$7:$F$67,MATCH(LARGE(Pipeline!$M$7:$M$67,3),Pipeline!$M$7:$M$67,0))="","—",INDEX(Pipeline!$F$7:$F$67,MATCH(LARGE(Pipeline!$M$7:$M$67,3),Pipeline!$M$7:$M$67,0))),"") | F10: =IFERROR(IF(INDEX(Pipeline!$D$7:$D$67,MATCH(LARGE(Pipeline!$M$7:$M$67,3),Pipeline!$M$7:$M$67,0))="","—",INDEX(Pipeline!$D$7:$D$67,MATCH(LARGE(Pipeline!$M$7:$M$67,3),Pipeline!$M$7:$M$67,0))),"") | G10: =IFERROR(IF(INDEX(Pipeline!$G$7:$G$67,MATCH(LARGE(Pipeline!$M$7:$M$67,3),Pipeline!$M$7:$M$67,0))="","—",INDEX(Pipeline!$G$7:$G$67,MATCH(LARGE(Pipeline!$M$7:$M$67,3),Pipeline!$M$7:$M$67,0))),"") | H10: =IFERROR(IF(INDEX(Pipeline!$H$7:$H$67,MATCH(LARGE(Pipeline!$M$7:$M$67,3),Pipeline!$M$7:$M$67,0))="","—",INDEX(Pipeline!$H$7:$H$67,MATCH(LARGE(Pipeline!$M$7:$M$67,3),Pipeline!$M$7:$M$67,0))),"") | I10: =IFERROR(IF(INDEX(Pipeline!$I$7:$I$67,MATCH(LARGE(Pipeline!$M$7:$M$67,3),Pipeline!$M$7:$M$67,0))="","—",INDEX(Pipeline!$I$7:$I$67,MATCH(LARGE(Pipeline!$M$7:$M$67,3),Pipeline!$M$7:$M$67,0))),"") | J10: =IFERROR(IF(INDEX(Pipeline!$J$7:$J$67,MATCH(LARGE(Pipeline!$M$7:$M$67,3),Pipeline!$M$7:$M$67,0))="","—",INDEX(Pipeline!$J$7:$J$67,MATCH(LARGE(Pipeline!$M$7:$M$67,3),Pipeline!$M$7:$M$67,0))),"") | K10: =IFERROR(IF(INDEX(Pipeline!$K$7:$K$67,MATCH(LARGE(Pipeline!$M$7:$M$67,3),Pipeline!$M$7:$M$67,0))="","—",INDEX(Pipeline!$K$7:$K$67,MATCH(LARGE(Pipeline!$M$7:$M$67,3),Pipeline!$M$7:$M$67,0))),"") | L10: =IFERROR(IF(INDEX(Pipeline!$L$7:$L$67,MATCH(LARGE(Pipeline!$M$7:$M$67,3),Pipeline!$M$7:$M$67,0))="","—",INDEX(Pipeline!$L$7:$L$67,MATCH(LARGE(Pipeline!$M$7:$M$67,3),Pipeline!$M$7:$M$67,0))),"")
A11: 4 | B11: =IFERROR(IF(INDEX(Pipeline!$B$7:$B$67,MATCH(LARGE(Pipeline!$M$7:$M$67,4),Pipeline!$M$7:$M$67,0))="","—",INDEX(Pipeline!$B$7:$B$67,MATCH(LARGE(Pipeline!$M$7:$M$67,4),Pipeline!$M$7:$M$67,0))),"") | C11: =IFERROR(IF(INDEX(Pipeline!$C$7:$C$67,MATCH(LARGE(Pipeline!$M$7:$M$67,4),Pipeline!$M$7:$M$67,0))="","—",INDEX(Pipeline!$C$7:$C$67,MATCH(LARGE(Pipeline!$M$7:$M$67,4),Pipeline!$M$7:$M$67,0))),"") | D11: =IFERROR(IF(INDEX(Pipeline!$E$7:$E$67,MATCH(LARGE(Pipeline!$M$7:$M$67,4),Pipeline!$M$7:$M$67,0))="","—",INDEX(Pipeline!$E$7:$E$67,MATCH(LARGE(Pipeline!$M$7:$M$67,4),Pipeline!$M$7:$M$67,0))),"") | E11: =IFERROR(IF(INDEX(Pipeline!$F$7:$F$67,MATCH(LARGE(Pipeline!$M$7:$M$67,4),Pipeline!$M$7:$M$67,0))="","—",INDEX(Pipeline!$F$7:$F$67,MATCH(LARGE(Pipeline!$M$7:$M$67,4),Pipeline!$M$7:$M$67,0))),"") | F11: =IFERROR(IF(INDEX(Pipeline!$D$7:$D$67,MATCH(LARGE(Pipeline!$M$7:$M$67,4),Pipeline!$M$7:$M$67,0))="","—",INDEX(Pipeline!$D$7:$D$67,MATCH(LARGE(Pipeline!$M$7:$M$67,4),Pipeline!$M$7:$M$67,0))),"") | G11: =IFERROR(IF(INDEX(Pipeline!$G$7:$G$67,MATCH(LARGE(Pipeline!$M$7:$M$67,4),Pipeline!$M$7:$M$67,0))="","—",INDEX(Pipeline!$G$7:$G$67,MATCH(LARGE(Pipeline!$M$7:$M$67,4),Pipeline!$M$7:$M$67,0))),"") | H11: =IFERROR(IF(INDEX(Pipeline!$H$7:$H$67,MATCH(LARGE(Pipeline!$M$7:$M$67,4),Pipeline!$M$7:$M$67,0))="","—",INDEX(Pipeline!$H$7:$H$67,MATCH(LARGE(Pipeline!$M$7:$M$67,4),Pipeline!$M$7:$M$67,0))),"") | I11: =IFERROR(IF(INDEX(Pipeline!$I$7:$I$67,MATCH(LARGE(Pipeline!$M$7:$M$67,4),Pipeline!$M$7:$M$67,0))="","—",INDEX(Pipeline!$I$7:$I$67,MATCH(LARGE(Pipeline!$M$7:$M$67,4),Pipeline!$M$7:$M$67,0))),"") | J11: =IFERROR(IF(INDEX(Pipeline!$J$7:$J$67,MATCH(LARGE(Pipeline!$M$7:$M$67,4),Pipeline!$M$7:$M$67,0))="","—",INDEX(Pipeline!$J$7:$J$67,MATCH(LARGE(Pipeline!$M$7:$M$67,4),Pipeline!$M$7:$M$67,0))),"") | K11: =IFERROR(IF(INDEX(Pipeline!$K$7:$K$67,MATCH(LARGE(Pipeline!$M$7:$M$67,4),Pipeline!$M$7:$M$67,0))="","—",INDEX(Pipeline!$K$7:$K$67,MATCH(LARGE(Pipeline!$M$7:$M$67,4),Pipeline!$M$7:$M$67,0))),"") | L11: =IFERROR(IF(INDEX(Pipeline!$L$7:$L$67,MATCH(LARGE(Pipeline!$M$7:$M$67,4),Pipeline!$M$7:$M$67,0))="","—",INDEX(Pipeline!$L$7:$L$67,MATCH(LARGE(Pipeline!$M$7:$M$67,4),Pipeline!$M$7:$M$67,0))),"")
A12: 5 | B12: =IFERROR(IF(INDEX(Pipeline!$B$7:$B$67,MATCH(LARGE(Pipeline!$M$7:$M$67,5),Pipeline!$M$7:$M$67,0))="","—",INDEX(Pipeline!$B$7:$B$67,MATCH(LARGE(Pipeline!$M$7:$M$67,5),Pipeline!$M$7:$M$67,0))),"") | C12: =IFERROR(IF(INDEX(Pipeline!$C$7:$C$67,MATCH(LARGE(Pipeline!$M$7:$M$67,5),Pipeline!$M$7:$M$67,0))="","—",INDEX(Pipeline!$C$7:$C$67,MATCH(LARGE(Pipeline!$M$7:$M$67,5),Pipeline!$M$7:$M$67,0))),"") | D12: =IFERROR(IF(INDEX(Pipeline!$E$7:$E$67,MATCH(LARGE(Pipeline!$M$7:$M$67,5),Pipeline!$M$7:$M$67,0))="","—",INDEX(Pipeline!$E$7:$E$67,MATCH(LARGE(Pipeline!$M$7:$M$67,5),Pipeline!$M$7:$M$67,0))),"") | E12: =IFERROR(IF(INDEX(Pipeline!$F$7:$F$67,MATCH(LARGE(Pipeline!$M$7:$M$67,5),Pipeline!$M$7:$M$67,0))="","—",INDEX(Pipeline!$F$7:$F$67,MATCH(LARGE(Pipeline!$M$7:$M$67,5),Pipeline!$M$7:$M$67,0))),"") | F12: =IFERROR(IF(INDEX(Pipeline!$D$7:$D$67,MATCH(LARGE(Pipeline!$M$7:$M$67,5),Pipeline!$M$7:$M$67,0))="","—",INDEX(Pipeline!$D$7:$D$67,MATCH(LARGE(Pipeline!$M$7:$M$67,5),Pipeline!$M$7:$M$67,0))),"") | G12: =IFERROR(IF(INDEX(Pipeline!$G$7:$G$67,MATCH(LARGE(Pipeline!$M$7:$M$67,5),Pipeline!$M$7:$M$67,0))="","—",INDEX(Pipeline!$G$7:$G$67,MATCH(LARGE(Pipeline!$M$7:$M$67,5),Pipeline!$M$7:$M$67,0))),"") | H12: =IFERROR(IF(INDEX(Pipeline!$H$7:$H$67,MATCH(LARGE(Pipeline!$M$7:$M$67,5),Pipeline!$M$7:$M$67,0))="","—",INDEX(Pipeline!$H$7:$H$67,MATCH(LARGE(Pipeline!$M$7:$M$67,5),Pipeline!$M$7:$M$67,0))),"") | I12: =IFERROR(IF(INDEX(Pipeline!$I$7:$I$67,MATCH(LARGE(Pipeline!$M$7:$M$67,5),Pipeline!$M$7:$M$67,0))="","—",INDEX(Pipeline!$I$7:$I$67,MATCH(LARGE(Pipeline!$M$7:$M$67,5),Pipeline!$M$7:$M$67,0))),"") | J12: =IFERROR(IF(INDEX(Pipeline!$J$7:$J$67,MATCH(LARGE(Pipeline!$M$7:$M$67,5),Pipeline!$M$7:$M$67,0))="","—",INDEX(Pipeline!$J$7:$J$67,MATCH(LARGE(Pipeline!$M$7:$M$67,5),Pipeline!$M$7:$M$67,0))),"") | K12: =IFERROR(IF(INDEX(Pipeline!$K$7:$K$67,MATCH(LARGE(Pipeline!$M$7:$M$67,5),Pipeline!$M$7:$M$67,0))="","—",INDEX(Pipeline!$K$7:$K$67,MATCH(LARGE(Pipeline!$M$7:$M$67,5),Pipeline!$M$7:$M$67,0))),"") | L12: =IFERROR(IF(INDEX(Pipeline!$L$7:$L$67,MATCH(LARGE(Pipeline!$M$7:$M$67,5),Pipeline!$M$7:$M$67,0))="","—",INDEX(Pipeline!$L$7:$L$67,MATCH(LARGE(Pipeline!$M$7:$M$67,5),Pipeline!$M$7:$M$67,0))),"")
B13: Total Top 5 | G13: =SUM(G8:G12) | H13: =SUM(H8:H12)
A15: Distribución – Top 5 oportunidades abiertas
A16: # | B16: Cliente | C16: Proyecto | D16: País | E16: Portafolio (Type) | F16: Ejecutivo | G16: m² | H16: USD | I16: Estado | J16: % Cierre | K16: Fecha cierre | L16: Valor ponderado
A17: 1 | B17: =IFERROR(IF(INDEX(Pipeline!$B$7:$B$67,MATCH(LARGE(Pipeline!$N$7:$N$67,1),Pipeline!$N$7:$N$67,0))="","—",INDEX(Pipeline!$B$7:$B$67,MATCH(LARGE(Pipeline!$N$7:$N$67,1),Pipeline!$N$7:$N$67,0))),"") | C17: =IFERROR(IF(INDEX(Pipeline!$C$7:$C$67,MATCH(LARGE(Pipeline!$N$7:$N$67,1),Pipeline!$N$7:$N$67,0))="","—",INDEX(Pipeline!$C$7:$C$67,MATCH(LARGE(Pipeline!$N$7:$N$67,1),Pipeline!$N$7:$N$67,0))),"") | D17: =IFERROR(IF(INDEX(Pipeline!$E$7:$E$67,MATCH(LARGE(Pipeline!$N$7:$N$67,1),Pipeline!$N$7:$N$67,0))="","—",INDEX(Pipeline!$E$7:$E$67,MATCH(LARGE(Pipeline!$N$7:$N$67,1),Pipeline!$N$7:$N$67,0))),"") | E17: =IFERROR(IF(INDEX(Pipeline!$F$7:$F$67,MATCH(LARGE(Pipeline!$N$7:$N$67,1),Pipeline!$N$7:$N$67,0))="","—",INDEX(Pipeline!$F$7:$F$67,MATCH(LARGE(Pipeline!$N$7:$N$67,1),Pipeline!$N$7:$N$67,0))),"") | F17: =IFERROR(IF(INDEX(Pipeline!$D$7:$D$67,MATCH(LARGE(Pipeline!$N$7:$N$67,1),Pipeline!$N$7:$N$67,0))="","—",INDEX(Pipeline!$D$7:$D$67,MATCH(LARGE(Pipeline!$N$7:$N$67,1),Pipeline!$N$7:$N$67,0))),"") | G17: =IFERROR(IF(INDEX(Pipeline!$G$7:$G$67,MATCH(LARGE(Pipeline!$N$7:$N$67,1),Pipeline!$N$7:$N$67,0))="","—",INDEX(Pipeline!$G$7:$G$67,MATCH(LARGE(Pipeline!$N$7:$N$67,1),Pipeline!$N$7:$N$67,0))),"") | H17: =IFERROR(IF(INDEX(Pipeline!$H$7:$H$67,MATCH(LARGE(Pipeline!$N$7:$N$67,1),Pipeline!$N$7:$N$67,0))="","—",INDEX(Pipeline!$H$7:$H$67,MATCH(LARGE(Pipeline!$N$7:$N$67,1),Pipeline!$N$7:$N$67,0))),"") | I17: Closed | J17: 1 | K17: =IFERROR(IF(INDEX(Pipeline!$K$7:$K$67,MATCH(LARGE(Pipeline!$N$7:$N$67,1),Pipeline!$N$7:$N$67,0))="","—",INDEX(Pipeline!$K$7:$K$67,MATCH(LARGE(Pipeline!$N$7:$N$67,1),Pipeline!$N$7:$N$67,0))),"") | L17: =IFERROR(IF(INDEX(Pipeline!$L$7:$L$67,MATCH(LARGE(Pipeline!$N$7:$N$67,1),Pipeline!$N$7:$N$67,0))="","—",INDEX(Pipeline!$L$7:$L$67,MATCH(LARGE(Pipeline!$N$7:$N$67,1),Pipeline!$N$7:$N$67,0))),"")
A18: 2 | B18: =IFERROR(IF(INDEX(Pipeline!$B$7:$B$67,MATCH(LARGE(Pipeline!$N$7:$N$67,2),Pipeline!$N$7:$N$67,0))="","—",INDEX(Pipeline!$B$7:$B$67,MATCH(LARGE(Pipeline!$N$7:$N$67,2),Pipeline!$N$7:$N$67,0))),"") | C18: =IFERROR(IF(INDEX(Pipeline!$C$7:$C$67,MATCH(LARGE(Pipeline!$N$7:$N$67,2),Pipeline!$N$7:$N$67,0))="","—",INDEX(Pipeline!$C$7:$C$67,MATCH(LARGE(Pipeline!$N$7:$N$67,2),Pipeline!$N$7:$N$67,0))),"") | D18: =IFERROR(IF(INDEX(Pipeline!$E$7:$E$67,MATCH(LARGE(Pipeline!$N$7:$N$67,2),Pipeline!$N$7:$N$67,0))="","—",INDEX(Pipeline!$E$7:$E$67,MATCH(LARGE(Pipeline!$N$7:$N$67,2),Pipeline!$N$7:$N$67,0))),"") | E18: =IFERROR(IF(INDEX(Pipeline!$F$7:$F$67,MATCH(LARGE(Pipeline!$N$7:$N$67,2),Pipeline!$N$7:$N$67,0))="","—",INDEX(Pipeline!$F$7:$F$67,MATCH(LARGE(Pipeline!$N$7:$N$67,2),Pipeline!$N$7:$N$67,0))),"") | F18: =IFERROR(IF(INDEX(Pipeline!$D$7:$D$67,MATCH(LARGE(Pipeline!$N$7:$N$67,2),Pipeline!$N$7:$N$67,0))="","—",INDEX(Pipeline!$D$7:$D$67,MATCH(LARGE(Pipeline!$N$7:$N$67,2),Pipeline!$N$7:$N$67,0))),"") | G18: =IFERROR(IF(INDEX(Pipeline!$G$7:$G$67,MATCH(LARGE(Pipeline!$N$7:$N$67,2),Pipeline!$N$7:$N$67,0))="","—",INDEX(Pipeline!$G$7:$G$67,MATCH(LARGE(Pipeline!$N$7:$N$67,2),Pipeline!$N$7:$N$67,0))),"") | H18: =IFERROR(IF(INDEX(Pipeline!$H$7:$H$67,MATCH(LARGE(Pipeline!$N$7:$N$67,2),Pipeline!$N$7:$N$67,0))="","—",INDEX(Pipeline!$H$7:$H$67,MATCH(LARGE(Pipeline!$N$7:$N$67,2),Pipeline!$N$7:$N$67,0))),"") | I18: =IFERROR(IF(INDEX(Pipeline!$I$7:$I$67,MATCH(LARGE(Pipeline!$N$7:$N$67,2),Pipeline!$N$7:$N$67,0))="","—",INDEX(Pipeline!$I$7:$I$67,MATCH(LARGE(Pipeline!$N$7:$N$67,2),Pipeline!$N$7:$N$67,0))),"") | J18: =IFERROR(IF(INDEX(Pipeline!$J$7:$J$67,MATCH(LARGE(Pipeline!$N$7:$N$67,2),Pipeline!$N$7:$N$67,0))="","—",INDEX(Pipeline!$J$7:$J$67,MATCH(LARGE(Pipeline!$N$7:$N$67,2),Pipeline!$N$7:$N$67,0))),"") | K18: =IFERROR(IF(INDEX(Pipeline!$K$7:$K$67,MATCH(LARGE(Pipeline!$N$7:$N$67,2),Pipeline!$N$7:$N$67,0))="","—",INDEX(Pipeline!$K$7:$K$67,MATCH(LARGE(Pipeline!$N$7:$N$67,2),Pipeline!$N$7:$N$67,0))),"") | L18: =IFERROR(IF(INDEX(Pipeline!$L$7:$L$67,MATCH(LARGE(Pipeline!$N$7:$N$67,2),Pipeline!$N$7:$N$67,0))="","—",INDEX(Pipeline!$L$7:$L$67,MATCH(LARGE(Pipeline!$N$7:$N$67,2),Pipeline!$N$7:$N$67,0))),"")
