Workbook
Name S1_Encabezado: PPT_1!$A$1:$G$7
Name S1_Tabla: PPT_1!$I$9:$R$19
Name S1_Alertas: PPT_1!$T$21:$U$26
Name S2_Encabezado: PPT_2!$A$1:$G$7
Name S2_Tabla: PPT_2!$I$9:$O$24
Name S2_Alertas: PPT_2!$Q$26:$R$29
Name S3_Encabezado: PPT_3!$A$1:$G$7
Name S3_Tabla: PPT_3!$I$9:$N$14
Name S3_Pipeline: PPT_3!$P$16:$U$21
Name S3_Alertas: PPT_3!$W$23:$X$27

Sheet Instrucciones
A1: Base del Comité de Operaciones · Ventas, Revenue y Order Intake
A2: Customer Excellence — este libro alimenta por vínculos la presentación Comite_Ventas_Vinculado.pptx
A4: CADA SEMANA
A5: 1. Diligencie las celdas AMARILLAS de Config, Ventas_m2, Revenue, Order_Intake, Pipeline y Comentarios.
A6: Celdas AZULES = traen el dato de otra hoja por fórmula (puede sobrescribirlas si necesita otro valor).
A7: Celdas GRISES = fórmulas; no las edite.
A8: 2. Guarde el libro (Ctrl+G / Ctrl+S).
A9: 3. Abra Comite_Ventas_Vinculado.pptx y elija 'Actualizar vínculos'.
A10: Si PowerPoint ya estaba abierto: Archivo > Información > Editar vínculos a archivos > seleccione todos > Actualizar ahora.
A12: PRIMERA VEZ (o si cambia la carpeta)
A13: - Deje este Excel y el PowerPoint en la MISMA carpeta. Si la carpeta es C:\Comite_Ventas, no hay que hacer nada más.
A14: - Si usa otra carpeta: con PowerPoint cerrado, doble clic en Actualizar_Rutas.bat (apunta todos los vínculos a esta carpeta).
... A28: Fórmula

Sheet Config
A1: Configuración del periodo
A2: Alimenta títulos, semáforos y alertas de las 3 diapositivas
A3: Mes | B3: Septiembre
A4: Año | B4: 2026
A5: Semana de corte (1-4) | B5: 4
A6: Fecha del comité (texto o fecha) | B6: 30/09/2026
A7: Área que presenta | B7: Customer Excellence
A8: Umbral verde (≥) | B8: 0.95
A9: Umbral amarillo (≥) | B9: 0.85
A10: Alcance Order Intake | B10: Premium (Env + Refri)
A11: Budget Order Intake mes (m²) | B11: 147719

Sheet Ventas_m2
A1: Volumen de ventas (m²) por línea
A2: F'cast W = plan de facturación semanal · Real/Proy W = facturado en semanas cerradas y proyección en la semana en curso · Real Sales = facturado acumulado. Para agregar una línea, inserte una fila dentro del grupo y ajuste el subtotal.
A4: Línea | B4: F'cast Inicial | C4: F'cast Actual | D4: Budget | E4: F'cast W1 | F4: F'cast W2 | G4: F'cast W3 | H4: F'cast W4 | I4: Real/Proy W1 | J4: Real/Proy W2 | K4: Real/Proy W3 | L4: Real/Proy W4 | M4: Real Sales (facturado) | N4: Cierre proyectado | O4: % F'cast vs Budget | P4: % Real vs Budget | Q4: Gap Real vs Budget | R4: Cumpl. W1 | S4: Cumpl. W2 | T4: Cumpl. W3 | U4: Cumpl. W4
A5: Envolventes | B5: 103379 | C5: 83329 | D5: 91536 | E5: 25832 | F5: 16666 | G5: 19999 | H5: 20832 | I5: 28862 | J5: 19733 | K5: 17184 | L5: 17550 | M5: 80178 | N5: =SUM(I5:L5) | O5: =IF(D5=0,"",C5/D5) | P5: =IF(D5=0,"",M5/D5) | Q5: =M5-D5 | R5: =IF(OR(E5=0,1>Config!$B$5),"",I5/E5) | S5: =IF(OR(F5=0,2>Config!$B$5),"",J5/F5) | T5: =IF(OR(G5=0,3>Config!$B$5),"",K5/G5) | U5: =IF(OR(H5=0,4>Config!$B$5),"",L5/H5)
A6: Refrigeración | B6: 35600 | C6: 41293 | D6: 43141 | E6: 12801 | F6: 8259 | G6: 9910 | H6: 10323 | I6: 12610 | J6: 5429 | K6: 8229 | L6: 15025 | M6: 33426 | N6: =SUM(I6:L6) | O6: =IF(D6=0,"",C6/D6) | P6: =IF(D6=0,"",M6/D6) | Q6: =M6-D6 | R6: =IF(OR(E6=0,1>Config!$B$5),"",I6/E6) | S6: =IF(OR(F6=0,2>Config!$B$5),"",J6/F6) | T6: =IF(OR(G6=0,3>Config!$B$5),"",K6/G6) | U6: =IF(OR(H6=0,4>Config!$B$5),"",L6/H6)
A7: Premium | B7: =SUM(B5:B6) | C7: =SUM(C5:C6) | D7: =SUM(D5:D6) | E7: =SUM(E5:E6) | F7: =SUM(F5:F6) | G7: =SUM(G5:G6) | H7: =SUM(H5:H6) | I7: =SUM(I5:I6) | ... M7: =SUM(M5:M6) | N7: =SUM(I7:L7) | O7: =IF(D7=0,"",C7/D7) | P7: =IF(D7=0,"",M7/D7) | Q7: =M7-D7 | R7: =IF(OR(E7=0,1>Config!$B$5),"",I7/E7) | S7: =IF(OR(F7=0,2>Config!$B$5),"",J7/F7) | T7: =IF(OR(G7=0,3>Config!$B$5),"",K7/G7) | U7: =IF(OR(H7=0,4>Config!$B$5),"",L7/H7)
A8: KingCore | B8: 29779 | C8: 25931 | D8: 27974 | E8: 3690 | F8: 5186 | G8: 10572 | H8: 6483 | I8: 4460 | J8: 1760 | K8: 9860 | L8: 9129 | M8: 25209 | N8: =SUM(I8:L8) | O8: =IF(D8=0,"",C8/D8) | P8: =IF(D8=0,"",M8/D8) | Q8: =M8-D8 | R8: =IF(OR(E8=0,1>Config!$B$5),"",I8/E8) | S8: =IF(OR(F8=0,2>Config!$B$5),"",J8/F8) | T8: =IF(OR(G8=0,3>Config!$B$5),"",K8/G8) | U8: =IF(OR(H8=0,4>Config!$B$5),"",L8/H8)
A9: Single Skin | B9: 23851 | C9: 4594 | D9: 20387 | E9: 721 | F9: 2800 | G9: 0 | H9: 1073 | I9: 2209 | J9: 1042 | K9: 0 | L9: 1343 | M9: 3251 | N9: =SUM(I9:L9) | O9: =IF(D9=0,"",C9/D9) | P9: =IF(D9=0,"",M9/D9) | Q9: =M9-D9 | R9: =IF(OR(E9=0,1>Config!$B$5),"",I9/E9) | S9: =IF(OR(F9=0,2>Config!$B$5),"",J9/F9) | T9: =IF(OR(G9=0,3>Config!$B$5),"",K9/G9) | U9: =IF(OR(H9=0,4>Config!$B$5),"",L9/H9)
A10: Ducto | B10: 520 | C10: 1044 | D10: 1385 | E10: 396 | F10: 0 | G10: 520 | H10: 0 | I10: 1044 | J10: 0 | K10: 0 | L10: 0 | M10: 1044 | N10: =SUM(I10:L10) | O10: =IF(D10=0,"",C10/D10) | P10: =IF(D10=0,"",M10/D10) | Q10: =M10-D10 | R10: =IF(OR(E10=0,1>Config!$B$5),"",I10/E10) | S10: =IF(OR(F10=0,2>Config!$B$5),"",J10/F10) | T10: =IF(OR(G10=0,3>Config!$B$5),"",K10/G10) | U10: =IF(OR(H10=0,4>Config!$B$5),"",L10/H10)
A11: Estándar | B11: =SUM(B8:B10) | C11: =SUM(C8:C10) | D11: =SUM(D8:D10) | E11: =SUM(E8:E10) | F11: =SUM(F8:F10) | G11: =SUM(G8:G10) | H11: =SUM(H8:H10) | I11: =SUM(I8:I10) | ... M11: =SUM(M8:M10) | N11: =SUM(I11:L11) | O11: =IF(D11=0,"",C11/D11) | P11: =IF(D11=0,"",M11/D11) | Q11: =M11-D11 | R11: =IF(OR(E11=0,1>Config!$B$5),"",I11/E11) | S11: =IF(OR(F11=0,2>Config!$B$5),"",J11/F11) | T11: =IF(OR(G11=0,3>Config!$B$5),"",K11/G11) | U11: =IF(OR(H11=0,4>Config!$B$5),"",L11/H11)
A12: Línea Arquitectónica | B12: 718 | C12: 718 | D12: 3182 | E12: 0 | F12: 0 | G12: 0 | H12: 718 | I12: 0 | J12: 264 | K12: 0 | L12: 0 | M12: 264 | N12: =SUM(I12:L12) | O12: =IF(D12=0,"",C12/D12) | P12: =IF(D12=0,"",M12/D12) | Q12: =M12-D12 | R12: =IF(OR(E12=0,1>Config!$B$5),"",I12/E12) | S12: =IF(OR(F12=0,2>Config!$B$5),"",J12/F12) | T12: =IF(OR(G12=0,3>Config!$B$5),"",K12/G12) | U12: =IF(OR(H12=0,4>Config!$B$5),"",L12/H12)
A13: Total | B13: =B7+B11+B12 | C13: =C7+C11+C12 | D13: =D7+D11+D12 | E13: =E7+E11+E12 | F13: =F7+F11+F12 | G13: =G7+G11+G12 | H13: =H7+H11+H12 | I13: =I7+I11+I12 | ... M13: =M7+M11+M12 | N13: =SUM(I13:L13) | O13: =IF(D13=0,"",C13/D13) | P13: =IF(D13=0,"",M13/D13) | Q13: =M13-D13 | R13: =IF(OR(E13=0,1>Config!$B$5),"",I13/E13) | S13: =IF(OR(F13=0,2>Config!$B$5),"",J13/F13) | T13: =IF(OR(G13=0,3>Config!$B$5),"",K13/G13) | U13: =IF(OR(H13=0,4>Config!$B$5),"",L13/H13)

Sheet Revenue
A1: Revenue (COP) por línea — F'cast del mes
A2: Cantidades y Budget de las líneas de panel vienen de Ventas_m2 (azul). % Perf. = cantidad ÷ Budget cantidad o, si no hay, Revenue ÷ Budget COP. En subtotales, solo sobre las líneas que tienen Budget.
A4: Línea | B4: Unidad | C4: Cantidad F'cast | D4: Revenue F'cast (COP) | E4: Budget cantidad | F4: Budget Revenue (COP) | G4: Precio promedio | H4: % Performance | I4: % Mix Revenue
A5: Envolventes | B5: m² | C5: =Ventas_m2!C5 | D5: 9169606489 | E5: =Ventas_m2!D5 | G5: =IF(N(C5)=0,"",D5/C5) | H5: =IF(N(E5)>0,C5/E5,IF(N(F5)>0,D5/F5,"")) | I5: =IF($D$19=0,"",D5/$D$19)
A6: Refrigeración | B6: m² | C6: =Ventas_m2!C6 | D6: 4478225850 | E6: =Ventas_m2!D6 | G6: =IF(N(C6)=0,"",D6/C6) | H6: =IF(N(E6)>0,C6/E6,IF(N(F6)>0,D6/F6,"")) | I6: =IF($D$19=0,"",D6/$D$19)
A7: Premium | B7: m² | C7: =SUM(C5:C6) | D7: =SUM(D5:D6) | E7: =SUM(E5:E6) | F7: =SUM(F5:F6) | G7: =IF(N(C7)=0,"",D7/C7) | H7: =IF(E7>0,SUMIF(E5:E6,">0",C5:C6)/E7,IF(F7>0,D7/F7,"")) | I7: =IF($D$19=0,"",D7/$D$19)
A8: KingCore | B8: m² | C8: =Ventas_m2!C8 | D8: 836015895 | E8: =Ventas_m2!D8 | G8: =IF(N(C8)=0,"",D8/C8) | H8: =IF(N(E8)>0,C8/E8,IF(N(F8)>0,D8/F8,"")) | I8: =IF($D$19=0,"",D8/$D$19)
A9: Single Skin | B9: m² | C9: =Ventas_m2!C9 | D9: 103998996 | E9: =Ventas_m2!D9 | G9: =IF(N(C9)=0,"",D9/C9) | H9: =IF(N(E9)>0,C9/E9,IF(N(F9)>0,D9/F9,"")) | I9: =IF($D$19=0,"",D9/$D$19)
A10: Ducto | B10: m² | C10: =Ventas_m2!C10 | D10: 52372800 | E10: =Ventas_m2!D10 | G10: =IF(N(C10)=0,"",D10/C10) | H10: =IF(N(E10)>0,C10/E10,IF(N(F10)>0,D10/F10,"")) | I10: =IF($D$19=0,"",D10/$D$19)
A11: Traslúcida | B11: m² | C11: 2155 | D11: 573520000 | G11: =IF(N(C11)=0,"",D11/C11) | H11: =IF(N(E11)>0,C11/E11,IF(N(F11)>0,D11/F11,"")) | I11: =IF($D$19=0,"",D11/$D$19)
A12: Estándar | B12: m² | C12: =SUM(C8:C11) | D12: =SUM(D8:D11) | E12: =SUM(E8:E11) | F12: =SUM(F8:F11) | G12: =IF(N(C12)=0,"",D12/C12) | H12: =IF(E12>0,SUMIF(E8:E11,">0",C8:C11)/E12,IF(F12>0,D12/F12,"")) | I12: =IF($D$19=0,"",D12/$D$19)
A13: Línea Arquitectónica | B13: m² | C13: 264 | D13: 20500000 | E13: =Ventas_m2!D12 | G13: =IF(N(C13)=0,"",D13/C13) | H13: =IF(N(E13)>0,C13/E13,IF(N(F13)>0,D13/F13,"")) | I13: =IF($D$19=0,"",D13/$D$19)
A14: Proyectos | B14: — | D14: 328000000 | F14: 533000000 | G14: =IF(N(C14)=0,"",D14/C14) | H14: =IF(N(E14)>0,C14/E14,IF(N(F14)>0,D14/F14,"")) | I14: =IF($D$19=0,"",D14/$D$19)
A15: Fijaciones y Accesorios | B15: — | D15: 1007000000 | G15: =IF(N(C15)=0,"",D15/C15) | H15: =IF(N(E15)>0,C15/E15,IF(N(F15)>0,D15/F15,"")) | I15: =IF($D$19=0,"",D15/$D$19)
A16: Consumibles | B16: — | D16: 0 | G16: =IF(N(C16)=0,"",D16/C16) | H16: =IF(N(E16)>0,C16/E16,IF(N(F16)>0,D16/F16,"")) | I16: =IF($D$19=0,"",D16/$D$19)
A17: Puertas | B17: und | C17: 17 | D17: 83050000 | G17: =IF(N(C17)=0,"",D17/C17) | H17: =IF(N(E17)>0,C17/E17,IF(N(F17)>0,D17/F17,"")) | I17: =IF($D$19=0,"",D17/$D$19)
A18: Facturación ICO | B18: — | D18: 1251189846 | G18: =IF(N(C18)=0,"",D18/C18) | H18: =IF(N(E18)>0,C18/E18,IF(N(F18)>0,D18/F18,"")) | I18: =IF($D$19=0,"",D18/$D$19)
A19: TOTAL F'cast (COP) | D19: =D7+D12+D13+D14+D15+D16+D17+D18 | I19: =IF($D$19=0,"",D19/$D$19)

Sheet Order_Intake
A1: Order Intake semanal — Budget vs negocios ganados (m² adjudicados)
A2: Budget semanal = Budget del mes (Config) ÷ 4, sobrescribible. Estado: Cerrada / En curso / Proyectada. Real vacío = semana aún sin datos.
A4: Semana | B4: Budget (m²) | C4: Real ganado (m²) | D4: Estado | E4: Gap (m²) | F4: Cumplimiento | G4: Por ganar ponderado (Pipeline) | H4: Budget acumulado | I4: Ganado acumulado | J4: Proyectado acumulado
A5: W1 | B5: =ROUND(Config!$B$11/4,0) | C5: 25901 | D5: Cerrada | E5: =IF(C5="","",C5-B5) | F5: =IF(OR(C5="",N(B5)=0),"",C5/B5) | G5: =SUMIFS(Pipeline!$H$5:$H$29,Pipeline!$F$5:$F$29,A5) | H5: =SUM($B$5:B5) | I5: =IF(C5="",NA(),SUM($C$5:C5)) | J5: =IF(C5="",NA(),I5)+SUM($G$5:G5)
A6: W2 | B6: =ROUND(Config!$B$11/4,0) | C6: 41491 | D6: Cerrada | E6: =IF(C6="","",C6-B6) | F6: =IF(OR(C6="",N(B6)=0),"",C6/B6) | G6: =SUMIFS(Pipeline!$H$5:$H$29,Pipeline!$F$5:$F$29,A6) | H6: =SUM($B$5:B6) | I6: =IF(C6="",NA(),SUM($C$5:C6)) | J6: =IF(C6="",NA(),I6)+SUM($G$5:G6)
A7: W3 | B7: =ROUND(Config!$B$11/4,0) | C7: 45187 | D7: Cerrada | E7: =IF(C7="","",C7-B7) | F7: =IF(OR(C7="",N(B7)=0),"",C7/B7) | G7: =SUMIFS(Pipeline!$H$5:$H$29,Pipeline!$F$5:$F$29,A7) | H7: =SUM($B$5:B7) | I7: =IF(C7="",NA(),SUM($C$5:C7)) | J7: =IF(C7="",NA(),I7)+SUM($G$5:G7)
A8: W4 | B8: =Config!$B$11-SUM(B5:B7) | C8: 27588 | D8: En curso | E8: =IF(C8="","",C8-B8) | F8: =IF(OR(C8="",N(B8)=0),"",C8/B8) | G8: =SUMIFS(Pipeline!$H$5:$H$29,Pipeline!$F$5:$F$29,A8) | H8: =SUM($B$5:B8) | I8: =IF(C8="",NA(),SUM($C$5:C8)) | J8: =IF(C8="",NA(),I8)+SUM($G$5:G8)
A9: TOTAL | B9: =SUM(B5:B8) | C9: =SUM(C5:C8) | E9: =C9-B9 | F9: =IF(B9=0,"",C9/B9) | G9: =SUM(G5:G8)
A11: Control: la suma semanal debe igualar el Budget del mes | D11: =IF(B9=Config!B11,"OK","Revise: la suma semanal difiere del Budget del mes")

Sheet Pipeline
A1: Pipeline — negocios por ganar
A2: Filas de EJEMPLO: reemplácelas por las oportunidades reales. Ponderado = m² × probabilidad. Cierre esperado: W1..W4 del mes en curso o 'Mes siguiente'.
A4: Oportunidad / Proyecto | B4: Cliente | C4: Línea | D4: m² | E4: Probabilidad | F4: Cierre esperado | G4: Responsable | H4: m² ponderados | I4: Orden (aux)
A5: Oportunidad A (ejemplo) | B5: Cliente por definir | C5: Envolventes | D5: 6500 | E5: 0.7 | F5: W4 | G5: Comercial | H5: =IF(A5="","",N(D5)*N(E5)) | I5: =IF(A5="","",H5+(100-ROW())/1000000)
A6: Oportunidad B (ejemplo) | B6: Cliente por definir | C6: Refrigeración | D6: 4200 | E6: 0.5 | F6: W4 | G6: Comercial | H6: =IF(A6="","",N(D6)*N(E6)) | I6: =IF(A6="","",H6+(100-ROW())/1000000)
A7: Oportunidad C (ejemplo) | B7: Cliente por definir | C7: Envolventes | D7: 12000 | E7: 0.6 | F7: Mes siguiente | G7: Comercial | H7: =IF(A7="","",N(D7)*N(E7)) | I7: =IF(A7="","",H7+(100-ROW())/1000000)
A8: Oportunidad D (ejemplo) | B8: Cliente por definir | C8: Refrigeración | D8: 8000 | E8: 0.4 | F8: Mes siguiente | G8: Comercial | H8: =IF(A8="","",N(D8)*N(E8)) | I8: =IF(A8="","",H8+(100-ROW())/1000000)
H9: =IF(A9="","",N(D9)*N(E9)) | I9: =IF(A9="","",H9+(100-ROW())/1000000)
H10: =IF(A10="","",N(D10)*N(E10)) | I10: =IF(A10="","",H10+(100-ROW())/1000000)
H11: =IF(A11="","",N(D11)*N(E11)) | I11: =IF(A11="","",H11+(100-ROW())/1000000)
H12: =IF(A12="","",N(D12)*N(E12)) | I12: =IF(A12="","",H12+(100-ROW())/1000000)
H13: =IF(A13="","",N(D13)*N(E13)) | I13: =IF(A13="","",H13+(100-ROW())/1000000)
H14: =IF(A14="","",N(D14)*N(E14)) | I14: =IF(A14="","",H14+(100-ROW())/1000000)
H15: =IF(A15="","",N(D15)*N(E15)) | I15: =IF(A15="","",H15+(100-ROW())/1000000)
H16: =IF(A16="","",N(D16)*N(E16)) | I16: =IF(A16="","",H16+(100-ROW())/1000000)
H17: =IF(A17="","",N(D17)*N(E17)) | I17: =IF(A17="","",H17+(100-ROW())/1000000)
H18: =IF(A18="","",N(D18)*N(E18)) | I18: =IF(A18="","",H18+(100-ROW())/1000000)
H19: =IF(A19="","",N(D19)*N(E19)) | I19: =IF(A19="","",H19+(100-ROW())/1000000)
H20: =IF(A20="","",N(D20)*N(E20)) | I20: =IF(A20="","",H20+(100-ROW())/1000000)
... H29: =IF(A29="","",N(D29)*N(E29)) | I29: =IF(A29="","",H29+(100-ROW())/1000000)
A31: TOTAL | D31: =SUM(D5:D29) | H31: =SUM(H5:H29)

Sheet Comentarios
A1: Comentarios para cada diapositiva (opcional)
A2: Aparecen primero en el recuadro de alertas de la diapositiva; deje vacío si no aplica.
A4: Diapositiva | B4: Comentario
A5: 1 · Volumen m²
A6: 1 · Volumen m²
A7: 2 · Revenue
A8: 2 · Revenue
A9: 3 · Order Intake
A10: 3 · Order Intake

Sheet PPT_1
A1: ="Ventas "&Config!$B$3&" · Volumen (m²)" | G1: Comité de Operaciones | AZ1: Umbral verde | BA1: =Config!$B$8 | CB1: Premium semanal (m²) | CH1: Budget vs F'cast vs Real (m²)
A2: ="F'cast vs Budget vs Real Sales por línea y cumplimiento semanal · Corte W"&Config!$B$5 | G2: =Config!$B$7&" · "&IF(ISNUMBER(Config!$B$6),TEXT(DAY(Config!$B$6),"00")&"/"&TEXT(MONTH(Config!$B$6),"00")&"/"&YEAR(Config!$B$6),Config!$B$6) | AZ2: Umbral amarillo | BA2: =Config!$B$9 | CC2: F'cast semanal | CD2: Real/Proy semanal | CI2: Budget | CJ2: F'cast actual | CK2: Real Sales
CB3: W1 | CC3: =Ventas_m2!E7 | CD3: =Ventas_m2!I7 | CH3: =Ventas_m2!A5 | CI3: =Ventas_m2!D5 | CJ3: =Ventas_m2!C5 | CK3: =Ventas_m2!M5
A4: REAL SALES PREMIUM | C4: CIERRE PROYECTADO PREMIUM | E4: REAL SALES ESTÁNDAR | G4: GAP TOTAL VS BUDGET | CB4: W2 | CC4: =Ventas_m2!F7 | CD4: =Ventas_m2!J7 | CH4: =Ventas_m2!A6 | CI4: =Ventas_m2!D6 | CJ4: =Ventas_m2!C6 | CK4: =Ventas_m2!M6
A5: =FIXED(Ventas_m2!$M$7,0)&" m²" | C5: =FIXED(Ventas_m2!$N$7,0)&" m²" | E5: =FIXED(Ventas_m2!$M$11,0)&" m²" | G5: =FIXED(Ventas_m2!$Q$13,0)&" m²" | CB5: W3 | CC5: =Ventas_m2!G7 | CD5: =Ventas_m2!K7 | CH5: =Ventas_m2!A8 | CI5: =Ventas_m2!D8 | CJ5: =Ventas_m2!C8 | CK5: =Ventas_m2!M8
A6: ="● "&ROUND((Ventas_m2!$P$7)*100,0)&"%"&" "&"del Budget ("&FIXED(Ventas_m2!$D$7,0)&")" | C6: ="● "&ROUND((Ventas_m2!$N$7/Ventas_m2!$D$7)*100,0)&"%"&" "&"del Budget · F'cast "&FIXED(Ventas_m2!$C$7,0) | E6: ="● "&ROUND((Ventas_m2!$P$11)*100,0)&"%"&" "&"del Budget ("&FIXED(Ventas_m2!$D$11,0)&")" | G6: ="● "&ROUND((Ventas_m2!$P$13)*100,0)&"%"&" "&"Real "&FIXED(Ventas_m2!$M$13,0)&" de "&FIXED(Ventas_m2!$D$13,0) | BC6: =IF(NOT(ISNUMBER(Ventas_m2!$P$7)),4,IF(Ventas_m2!$P$7>=$BA$1,3,IF(Ventas_m2!$P$7>=$BA$2,2,1))) | BD6: =IF(NOT(ISNUMBER(Ventas_m2!$N$7/Ventas_m2!$D$7)),4,IF(Ventas_m2!$N$7/Ventas_m2!$D$7>=$BA$1,3,IF(Ventas_m2!$N$7/Ventas_m2!$D$7>=$BA$2,2,1))) | BE6: =IF(NOT(ISNUMBER(Ventas_m2!$P$11)),4,IF(Ventas_m2!$P$11>=$BA$1,3,IF(Ventas_m2!$P$11>=$BA$2,2,1))) | BF6: =IF(NOT(ISNUMBER(Ventas_m2!$P$13)),4,IF(Ventas_m2!$P$13>=$BA$1,3,IF(Ventas_m2!$P$13>=$BA$2,2,1))) | CB6: W4 | CC6: =Ventas_m2!H7 | CD6: =Ventas_m2!L7 | CH6: =Ventas_m2!A9 | CI6: =Ventas_m2!D9 | CJ6: =Ventas_m2!C9 | CK6: =Ventas_m2!M9
CH7: =Ventas_m2!A10 | CI7: =Ventas_m2!D10 | CJ7: =Ventas_m2!C10 | CK7: =Ventas_m2!M10
CH8: =Ventas_m2!A12 | CI8: =Ventas_m2!D12 | CJ8: =Ventas_m2!C12 | CK8: =Ventas_m2!M12
I9: Línea | J9: Budget | K9: F'cast Act. | L9: Real Sales | M9: Cierre proy. | N9: % Real vs Bgt | O9: W1 | P9: W2 | Q9: W3 | R9: W4
I10: =Ventas_m2!A5 | J10: =Ventas_m2!D5 | K10: =Ventas_m2!C5 | L10: =Ventas_m2!M5 | M10: =Ventas_m2!N5 | N10: =IF(Ventas_m2!P5="","–",Ventas_m2!P5) | O10: =IF(Ventas_m2!R5="","–",Ventas_m2!R5) | P10: =IF(Ventas_m2!S5="","–",Ventas_m2!S5) | Q10: =IF(Ventas_m2!T5="","–",Ventas_m2!T5) | R10: =IF(Ventas_m2!U5="","–",Ventas_m2!U5)
I11: =Ventas_m2!A6 | J11: =Ventas_m2!D6 | K11: =Ventas_m2!C6 | L11: =Ventas_m2!M6 | M11: =Ventas_m2!N6 | N11: =IF(Ventas_m2!P6="","–",Ventas_m2!P6) | O11: =IF(Ventas_m2!R6="","–",Ventas_m2!R6) | P11: =IF(Ventas_m2!S6="","–",Ventas_m2!S6) | Q11: =IF(Ventas_m2!T6="","–",Ventas_m2!T6) | R11: =IF(Ventas_m2!U6="","–",Ventas_m2!U6)
I12: =Ventas_m2!A7 | J12: =Ventas_m2!D7 | K12: =Ventas_m2!C7 | L12: =Ventas_m2!M7 | M12: =Ventas_m2!N7 | N12: =IF(Ventas_m2!P7="","–",Ventas_m2!P7) | O12: =IF(Ventas_m2!R7="","–",Ventas_m2!R7) | P12: =IF(Ventas_m2!S7="","–",Ventas_m2!S7) | Q12: =IF(Ventas_m2!T7="","–",Ventas_m2!T7) | R12: =IF(Ventas_m2!U7="","–",Ventas_m2!U7)
I13: =Ventas_m2!A8 | J13: =Ventas_m2!D8 | K13: =Ventas_m2!C8 | L13: =Ventas_m2!M8 | M13: =Ventas_m2!N8 | N13: =IF(Ventas_m2!P8="","–",Ventas_m2!P8) | O13: =IF(Ventas_m2!R8="","–",Ventas_m2!R8) | P13: =IF(Ventas_m2!S8="","–",Ventas_m2!S8) | Q13: =IF(Ventas_m2!T8="","–",Ventas_m2!T8) | R13: =IF(Ventas_m2!U8="","–",Ventas_m2!U8)
I14: =Ventas_m2!A9 | J14: =Ventas_m2!D9 | K14: =Ventas_m2!C9 | L14: =Ventas_m2!M9 | M14: =Ventas_m2!N9 | N14: =IF(Ventas_m2!P9="","–",Ventas_m2!P9) | O14: =IF(Ventas_m2!R9="","–",Ventas_m2!R9) | P14: =IF(Ventas_m2!S9="","–",Ventas_m2!S9) | Q14: =IF(Ventas_m2!T9="","–",Ventas_m2!T9) | R14: =IF(Ventas_m2!U9="","–",Ventas_m2!U9)
I15: =Ventas_m2!A10 | J15: =Ventas_m2!D10 | K15: =Ventas_m2!C10 | L15: =Ventas_m2!M10 | M15: =Ventas_m2!N10 | N15: =IF(Ventas_m2!P10="","–",Ventas_m2!P10) | O15: =IF(Ventas_m2!R10="","–",Ventas_m2!R10) | P15: =IF(Ventas_m2!S10="","–",Ventas_m2!S10) | Q15: =IF(Ventas_m2!T10="","–",Ventas_m2!T10) | R15: =IF(Ventas_m2!U10="","–",Ventas_m2!U10)
I16: =Ventas_m2!A11 | J16: =Ventas_m2!D11 | K16: =Ventas_m2!C11 | L16: =Ventas_m2!M11 | M16: =Ventas_m2!N11 | N16: =IF(Ventas_m2!P11="","–",Ventas_m2!P11) | O16: =IF(Ventas_m2!R11="","–",Ventas_m2!R11) | P16: =IF(Ventas_m2!S11="","–",Ventas_m2!S11) | Q16: =IF(Ventas_m2!T11="","–",Ventas_m2!T11) | R16: =IF(Ventas_m2!U11="","–",Ventas_m2!U11)
I17: =Ventas_m2!A12 | J17: =Ventas_m2!D12 | K17: =Ventas_m2!C12 | L17: =Ventas_m2!M12 | M17: =Ventas_m2!N12 | N17: =IF(Ventas_m2!P12="","–",Ventas_m2!P12) | O17: =IF(Ventas_m2!R12="","–",Ventas_m2!R12) | P17: =IF(Ventas_m2!S12="","–",Ventas_m2!S12) | Q17: =IF(Ventas_m2!T12="","–",Ventas_m2!T12) | R17: =IF(Ventas_m2!U12="","–",Ventas_m2!U12)
I18: =Ventas_m2!A13 | J18: =Ventas_m2!D13 | K18: =Ventas_m2!C13 | L18: =Ventas_m2!M13 | M18: =Ventas_m2!N13 | N18: =IF(Ventas_m2!P13="","–",Ventas_m2!P13) | O18: =IF(Ventas_m2!R13="","–",Ventas_m2!R13) | P18: =IF(Ventas_m2!S13="","–",Ventas_m2!S13) | Q18: =IF(Ventas_m2!T13="","–",Ventas_m2!T13) | R18: =IF(Ventas_m2!U13="","–",Ventas_m2!U13)
I19: W1–W4 = cumplimiento semanal: Real/Proy de la semana ÷ F'cast semanal.
T21: ALERTAS Y TENDENCIAS
T22: =IF(U22="","","●") | U22: =IFERROR(INDEX($BJ$41:$BJ$46,MATCH(1,$BL$41:$BL$46,0)),"") | BM22: =IFERROR(INDEX($BK$41:$BK$46,MATCH(1,$BL$41:$BL$46,0)),0)
T23: =IF(U23="","","●") | U23: =IFERROR(INDEX($BJ$41:$BJ$46,MATCH(2,$BL$41:$BL$46,0)),"") | BN23: =IFERROR(INDEX($BK$41:$BK$46,MATCH(2,$BL$41:$BL$46,0)),0)
T24: =IF(U24="","","●") | U24: =IFERROR(INDEX($BJ$41:$BJ$46,MATCH(3,$BL$41:$BL$46,0)),"") | BO24: =IFERROR(INDEX($BK$41:$BK$46,MATCH(3,$BL$41:$BL$46,0)),0)
T25: =IF(U25="","","●") | U25: =IFERROR(INDEX($BJ$41:$BJ$46,MATCH(4,$BL$41:$BL$46,0)),"") | BP25: =IFERROR(INDEX($BK$41:$BK$46,MATCH(4,$BL$41:$BL$46,0)),0)
BG40: =IF(ISNUMBER(Ventas_m2!P5),Ventas_m2!P5+1/1000000,"") | BH40: =Ventas_m2!A5 | BI40: =IF(ISNUMBER(Ventas_m2!P5),Ventas_m2!P5,"")
BG41: =IF(ISNUMBER(Ventas_m2!P6),Ventas_m2!P6+2/1000000,"") | BH41: =Ventas_m2!A6 | BI41: =IF(ISNUMBER(Ventas_m2!P6),Ventas_m2!P6,"") | BJ41: =IFERROR(IF(Comentarios!$B$5="","",Comentarios!$B$5),"") | BK41: =IFERROR(4,4) | BL41: =0+IF(BJ41="",0,1)
BG42: =IF(ISNUMBER(Ventas_m2!P8),Ventas_m2!P8+3/1000000,"") | BH42: =Ventas_m2!A8 | BI42: =IF(ISNUMBER(Ventas_m2!P8),Ventas_m2!P8,"") | BJ42: =IFERROR(IF(Comentarios!$B$6="","",Comentarios!$B$6),"") | BK42: =IFERROR(4,4) | BL42: =BL41+IF(BJ42="",0,1)
BG43: =IF(ISNUMBER(Ventas_m2!P9),Ventas_m2!P9+4/1000000,"") | BH43: =Ventas_m2!A9 | BI43: =IF(ISNUMBER(Ventas_m2!P9),Ventas_m2!P9,"") | BJ43: =IFERROR("Premium proyecta cerrar en "&FIXED(Ventas_m2!$N$7,0)&" m² ("&ROUND((Ventas_m2!$N$7/Ventas_m2!$D$7)*100,0)&"%"&" del Budget); brecha de "&FIXED(Ventas_m2!$N$7-Ventas_m2!$D$7,0)&" m².","") | BK43: =IFERROR(IF(NOT(ISNUMBER(Ventas_m2!$N$7/Ventas_m2!$D$7)),4,IF(Ventas_m2!$N$7/Ventas_m2!$D$7>=$BA$1,3,IF(Ventas_m2!$N$7/Ventas_m2!$D$7>=$BA$2,2,1))),4) | BL43: =BL42+IF(BJ43="",0,1)
BG44: =IF(ISNUMBER(Ventas_m2!P10),Ventas_m2!P10+5/1000000,"") | BH44: =Ventas_m2!A10 | BI44: =IF(ISNUMBER(Ventas_m2!P10),Ventas_m2!P10,"") | BJ44: =IFERROR(INDEX($BH$40:$BH$45,MATCH(SMALL($BG$40:$BG$45,1),$BG$40:$BG$45,0))&": Real "&FIXED(INDEX(Ventas_m2!$M$1:$M$20,INDEX({5,6,8,9,10,12},MATCH(SMALL($BG$40:$BG$45,1),$BG$40:$BG$45,0))),0)&" m² = "&ROUND((INDEX($BI$40:$BI$45,MATCH(SMALL($BG$40:$BG$45,1),$BG$40:$BG$45,0)))*100,0)&"%"&" del Budget (gap "&FIXED(INDEX(Ventas_m2!$M$1:$M$20,INDEX({5,6,8,9,10,12},MATCH(SMALL($BG$40:$BG$45,1),$BG$40:$BG$45,0)))-INDEX(Ventas_m2!$D$1:$D$20,INDEX({5,6,8,9,10,12},MATCH(SMALL($BG$40:$BG$45,1),$BG$40:$BG$45,0))),0)&" m²).","") | BK44: =IFERROR(IF(NOT(ISNUMBER(INDEX($BI$40:$BI$45,MATCH(SMALL($BG$40:$BG$45,1),$BG$40:$BG$45,0)))),4,IF(INDEX($BI$40:$BI$45,MATCH(SMALL($BG$40:$BG$45,1),$BG$40:$BG$45,0))>=$BA$1,3,IF(INDEX($BI$40:$BI$45,MATCH(SMALL($BG$40:$BG$45,1),$BG$40:$BG$45,0))>=$BA$2,2,1))),4) | BL44: =BL43+IF(BJ44="",0,1)
BG45: =IF(ISNUMBER(Ventas_m2!P12),Ventas_m2!P12+6/1000000,"") | BH45: =Ventas_m2!A12 | BI45: =IF(ISNUMBER(Ventas_m2!P12),Ventas_m2!P12,"") | BJ45: =IFERROR(INDEX($BH$40:$BH$45,MATCH(SMALL($BG$40:$BG$45,2),$BG$40:$BG$45,0))&": Real "&FIXED(INDEX(Ventas_m2!$M$1:$M$20,INDEX({5,6,8,9,10,12},MATCH(SMALL($BG$40:$BG$45,2),$BG$40:$BG$45,0))),0)&" m² = "&ROUND((INDEX($BI$40:$BI$45,MATCH(SMALL($BG$40:$BG$45,2),$BG$40:$BG$45,0)))*100,0)&"%"&" del Budget (gap "&FIXED(INDEX(Ventas_m2!$M$1:$M$20,INDEX({5,6,8,9,10,12},MATCH(SMALL($BG$40:$BG$45,2),$BG$40:$BG$45,0)))-INDEX(Ventas_m2!$D$1:$D$20,INDEX({5,6,8,9,10,12},MATCH(SMALL($BG$40:$BG$45,2),$BG$40:$BG$45,0))),0)&" m²).","") | BK45: =IFERROR(IF(NOT(ISNUMBER(INDEX($BI$40:$BI$45,MATCH(SMALL($BG$40:$BG$45,2),$BG$40:$BG$45,0)))),4,IF(INDEX($BI$40:$BI$45,MATCH(SMALL($BG$40:$BG$45,2),$BG$40:$BG$45,0))>=$BA$1,3,IF(INDEX($BI$40:$BI$45,MATCH(SMALL($BG$40:$BG$45,2),$BG$40:$BG$45,0))>=$BA$2,2,1))),4) | BL45: =BL44+IF(BJ45="",0,1)
BJ46: =IFERROR(INDEX($BH$40:$BH$45,MATCH(SMALL($BG$40:$BG$45,3),$BG$40:$BG$45,0))&": Real "&FIXED(INDEX(Ventas_m2!$M$1:$M$20,INDEX({5,6,8,9,10,12},MATCH(SMALL($BG$40:$BG$45,3),$BG$40:$BG$45,0))),0)&" m² = "&ROUND((INDEX($BI$40:$BI$45,MATCH(SMALL($BG$40:$BG$45,3),$BG$40:$BG$45,0)))*100,0)&"%"&" del Budget (gap "&FIXED(INDEX(Ventas_m2!$M$1:$M$20,INDEX({5,6,8,9,10,12},MATCH(SMALL($BG$40:$BG$45,3),$BG$40:$BG$45,0)))-INDEX(Ventas_m2!$D$1:$D$20,INDEX({5,6,8,9,10,12},MATCH(SMALL($BG$40:$BG$45,3),$BG$40:$BG$45,0))),0)&" m²).","") | BK46: =IFERROR(IF(NOT(ISNUMBER(INDEX($BI$40:$BI$45,MATCH(SMALL($BG$40:$BG$45,3),$BG$40:$BG$45,0)))),4,IF(INDEX($BI$40:$BI$45,MATCH(SMALL($BG$40:$BG$45,3),$BG$40:$BG$45,0))>=$BA$1,3,IF(INDEX($BI$40:$BI$45,MATCH(SMALL($BG$40:$BG$45,3),$BG$40:$BG$45,0))>=$BA$2,2,1))),4) | BL46: =BL45+IF(BJ46="",0,1)

Sheet PPT_2
A1: ="Ventas "&Config!$B$3&" · m² y Revenue" | G1: Comité de Operaciones | AZ1: Umbral verde | BA1: =Config!$B$8 | CB1: Mix de revenue por grupo (M COP) | CH1: Revenue por línea (millones COP)
A2: ="F'cast actual del mes en m² y valorizado en COP: precio promedio, mix y performance vs Budget" | G2: =Config!$B$7&" · "&IF(ISNUMBER(Config!$B$6),TEXT(DAY(Config!$B$6),"00")&"/"&TEXT(MONTH(Config!$B$6),"00")&"/"&YEAR(Config!$B$6),Config!$B$6) | AZ2: Umbral amarillo | BA2: =Config!$B$9 | CC2: Revenue (M COP) | CI2: Revenue (M COP)
CB3: Premium | CC3: =(Revenue!D7)/1000000 | CH3: =INDEX($BK$60:$BK$71,MATCH(LARGE($BM$60:$BM$71,1),$BM$60:$BM$71,0)) | CI3: =INDEX($BL$60:$BL$71,MATCH(LARGE($BM$60:$BM$71,1),$BM$60:$BM$71,0))
A4: REVENUE F'CAST TOTAL | C4: REVENUE PREMIUM | E4: VOLUMEN F'CAST (M²) | G4: PRECIO PROM. PREMIUM / M² | CB4: Estándar | CC4: =(Revenue!D12)/1000000 | CH4: =INDEX($BK$60:$BK$71,MATCH(LARGE($BM$60:$BM$71,2),$BM$60:$BM$71,0)) | CI4: =INDEX($BL$60:$BL$71,MATCH(LARGE($BM$60:$BM$71,2),$BM$60:$BM$71,0))
A5: ="$ "&FIXED((Revenue!$D$19)/1000000,0)&" M" | C5: ="$ "&FIXED((Revenue!$D$7)/1000000,0)&" M" | E5: =FIXED(Revenue!$C$7+Revenue!$C$12+N(Revenue!$C$13),0)&" m²" | G5: ="$ "&FIXED(Revenue!$G$7,0) | CB5: Arquitectónica | CC5: =(Revenue!D13)/1000000 | CH5: =INDEX($BK$60:$BK$71,MATCH(LARGE($BM$60:$BM$71,3),$BM$60:$BM$71,0)) | CI5: =INDEX($BL$60:$BL$71,MATCH(LARGE($BM$60:$BM$71,3),$BM$60:$BM$71,0))
A6: ="incluye ICO "&"$ "&FIXED((Revenue!$D$18)/1000000,0)&" M" | C6: =ROUND((Revenue!$D$7/(Revenue!$D$19-Revenue!$D$18))*100,0)&"%"&" del revenue de producto" | E6: ="● "&ROUND(((SUMIF(Revenue!$E$5:$E$6,">0",Revenue!$C$5:$C$6)+SUMIF(Revenue!$E$8:$E$11,">0",Revenue!$C$8:$C$11)+IF(N(Revenue!$E$13)>0,Revenue!$C$13,0))/(Revenue!$E$7+Revenue!$E$12+N(Revenue!$E$13)))*100,0)&"%"&" "&"del Budget ("&FIXED((Revenue!$E$7+Revenue!$E$12+N(Revenue!$E$13)),0)&" m²)" | G6: ="Estándar: $ "&FIXED(Revenue!$G$12,0)&" / m²" | BC6: =IF(NOT(ISNUMBER((SUMIF(Revenue!$E$5:$E$6,">0",Revenue!$C$5:$C$6)+SUMIF(Revenue!$E$8:$E$11,">0",Revenue!$C$8:$C$11)+IF(N(Revenue!$E$13)>0,Revenue!$C$13,0))/(Revenue!$E$7+Revenue!$E$12+N(Revenue!$E$13)))),4,IF((SUMIF(Revenue!$E$5:$E$6,">0",Revenue!$C$5:$C$6)+SUMIF(Revenue!$E$8:$E$11,">0",Revenue!$C$8:$C$11)+IF(N(Revenue!$E$13)>0,Revenue!$C$13,0))/(Revenue!$E$7+Revenue!$E$12+N(Revenue!$E$13))>=$BA$1,3,IF((SUMIF(Revenue!$E$5:$E$6,">0",Revenue!$C$5:$C$6)+SUMIF(Revenue!$E$8:$E$11,">0",Revenue!$C$8:$C$11)+IF(N(Revenue!$E$13)>0,Revenue!$C$13,0))/(Revenue!$E$7+Revenue!$E$12+N(Revenue!$E$13))>=$BA$2,2,1))) | CB6: Proyectos | CC6: =(Revenue!D14)/1000000 | CH6: =INDEX($BK$60:$BK$71,MATCH(LARGE($BM$60:$BM$71,4),$BM$60:$BM$71,0)) | CI6: =INDEX($BL$60:$BL$71,MATCH(LARGE($BM$60:$BM$71,4),$BM$60:$BM$71,0))
CB7: Accesorios | CC7: =(Revenue!D15+Revenue!D16)/1000000 | CH7: =INDEX($BK$60:$BK$71,MATCH(LARGE($BM$60:$BM$71,5),$BM$60:$BM$71,0)) | CI7: =INDEX($BL$60:$BL$71,MATCH(LARGE($BM$60:$BM$71,5),$BM$60:$BM$71,0))
CB8: Puertas | CC8: =(Revenue!D17)/1000000 | CH8: =INDEX($BK$60:$BK$71,MATCH(LARGE($BM$60:$BM$71,6),$BM$60:$BM$71,0)) | CI8: =INDEX($BL$60:$BL$71,MATCH(LARGE($BM$60:$BM$71,6),$BM$60:$BM$71,0))
I9: Línea | J9: Cantidad | K9: Precio prom. | L9: Revenue (COP) | M9: Mix | N9: Budget | O9: % Perf. | CB9: ICO | CC9: =(Revenue!D18)/1000000 | CH9: =INDEX($BK$60:$BK$71,MATCH(LARGE($BM$60:$BM$71,7),$BM$60:$BM$71,0)) | CI9: =INDEX($BL$60:$BL$71,MATCH(LARGE($BM$60:$BM$71,7),$BM$60:$BM$71,0))
I10: =Revenue!A5 | J10: =IF(N(Revenue!C5)=0,"–",FIXED(Revenue!C5,0)&IF(OR(Revenue!B5="m²",Revenue!B5="",Revenue!B5="—"),""," "&Revenue!B5)) | K10: =IF(Revenue!G5="","–","$ "&FIXED(Revenue!G5,0)) | L10: =Revenue!D5 | M10: =Revenue!I5 | N10: =IF(N(Revenue!E5)>0,FIXED(Revenue!E5,0),IF(N(Revenue!F5)>0,"$ "&FIXED((Revenue!F5)/1000000,0)&" M","–")) | O10: =IF(Revenue!H5="","–",Revenue!H5) | CH10: =INDEX($BK$60:$BK$71,MATCH(LARGE($BM$60:$BM$71,8),$BM$60:$BM$71,0)) | CI10: =INDEX($BL$60:$BL$71,MATCH(LARGE($BM$60:$BM$71,8),$BM$60:$BM$71,0))
I11: =Revenue!A6 | J11: =IF(N(Revenue!C6)=0,"–",FIXED(Revenue!C6,0)&IF(OR(Revenue!B6="m²",Revenue!B6="",Revenue!B6="—"),""," "&Revenue!B6)) | K11: =IF(Revenue!G6="","–","$ "&FIXED(Revenue!G6,0)) | L11: =Revenue!D6 | M11: =Revenue!I6 | N11: =IF(N(Revenue!E6)>0,FIXED(Revenue!E6,0),IF(N(Revenue!F6)>0,"$ "&FIXED((Revenue!F6)/1000000,0)&" M","–")) | O11: =IF(Revenue!H6="","–",Revenue!H6) | CH11: =INDEX($BK$60:$BK$71,MATCH(LARGE($BM$60:$BM$71,9),$BM$60:$BM$71,0)) | CI11: =INDEX($BL$60:$BL$71,MATCH(LARGE($BM$60:$BM$71,9),$BM$60:$BM$71,0))
I12: =Revenue!A7 | J12: =IF(N(Revenue!C7)=0,"–",FIXED(Revenue!C7,0)&IF(OR(Revenue!B7="m²",Revenue!B7="",Revenue!B7="—"),""," "&Revenue!B7)) | K12: =IF(Revenue!G7="","–","$ "&FIXED(Revenue!G7,0)) | L12: =Revenue!D7 | M12: =Revenue!I7 | N12: =IF(N(Revenue!E7)>0,FIXED(Revenue!E7,0),IF(N(Revenue!F7)>0,"$ "&FIXED((Revenue!F7)/1000000,0)&" M","–")) | O12: =IF(Revenue!H7="","–",Revenue!H7) | CH12: =INDEX($BK$60:$BK$71,MATCH(LARGE($BM$60:$BM$71,10),$BM$60:$BM$71,0)) | CI12: =INDEX($BL$60:$BL$71,MATCH(LARGE($BM$60:$BM$71,10),$BM$60:$BM$71,0))
I13: =Revenue!A8 | J13: =IF(N(Revenue!C8)=0,"–",FIXED(Revenue!C8,0)&IF(OR(Revenue!B8="m²",Revenue!B8="",Revenue!B8="—"),""," "&Revenue!B8)) | K13: =IF(Revenue!G8="","–","$ "&FIXED(Revenue!G8,0)) | L13: =Revenue!D8 | M13: =Revenue!I8 | N13: =IF(N(Revenue!E8)>0,FIXED(Revenue!E8,0),IF(N(Revenue!F8)>0,"$ "&FIXED((Revenue!F8)/1000000,0)&" M","–")) | O13: =IF(Revenue!H8="","–",Revenue!H8) | CH13: =INDEX($BK$60:$BK$71,MATCH(LARGE($BM$60:$BM$71,11),$BM$60:$BM$71,0)) | CI13: =INDEX($BL$60:$BL$71,MATCH(LARGE($BM$60:$BM$71,11),$BM$60:$BM$71,0))
I14: =Revenue!A9 | J14: =IF(N(Revenue!C9)=0,"–",FIXED(Revenue!C9,0)&IF(OR(Revenue!B9="m²",Revenue!B9="",Revenue!B9="—"),""," "&Revenue!B9)) | K14: =IF(Revenue!G9="","–","$ "&FIXED(Revenue!G9,0)) | L14: =Revenue!D9 | M14: =Revenue!I9 | N14: =IF(N(Revenue!E9)>0,FIXED(Revenue!E9,0),IF(N(Revenue!F9)>0,"$ "&FIXED((Revenue!F9)/1000000,0)&" M","–")) | O14: =IF(Revenue!H9="","–",Revenue!H9) | CH14: =INDEX($BK$60:$BK$71,MATCH(LARGE($BM$60:$BM$71,12),$BM$60:$BM$71,0)) | CI14: =INDEX($BL$60:$BL$71,MATCH(LARGE($BM$60:$BM$71,12),$BM$60:$BM$71,0))
I15: =Revenue!A10 | J15: =IF(N(Revenue!C10)=0,"–",FIXED(Revenue!C10,0)&IF(OR(Revenue!B10="m²",Revenue!B10="",Revenue!B10="—"),""," "&Revenue!B10)) | K15: =IF(Revenue!G10="","–","$ "&FIXED(Revenue!G10,0)) | L15: =Revenue!D10 | M15: =Revenue!I10 | N15: =IF(N(Revenue!E10)>0,FIXED(Revenue!E10,0),IF(N(Revenue!F10)>0,"$ "&FIXED((Revenue!F10)/1000000,0)&" M","–")) | O15: =IF(Revenue!H10="","–",Revenue!H10)
I16: =Revenue!A11 | J16: =IF(N(Revenue!C11)=0,"–",FIXED(Revenue!C11,0)&IF(OR(Revenue!B11="m²",Revenue!B11="",Revenue!B11="—"),""," "&Revenue!B11)) | K16: =IF(Revenue!G11="","–","$ "&FIXED(Revenue!G11,0)) | L16: =Revenue!D11 | M16: =Revenue!I11 | N16: =IF(N(Revenue!E11)>0,FIXED(Revenue!E11,0),IF(N(Revenue!F11)>0,"$ "&FIXED((Revenue!F11)/1000000,0)&" M","–")) | O16: =IF(Revenue!H11="","–",Revenue!H11)
I17: =Revenue!A12 | J17: =IF(N(Revenue!C12)=0,"–",FIXED(Revenue!C12,0)&IF(OR(Revenue!B12="m²",Revenue!B12="",Revenue!B12="—"),""," "&Revenue!B12)) | K17: =IF(Revenue!G12="","–","$ "&FIXED(Revenue!G12,0)) | L17: =Revenue!D12 | M17: =Revenue!I12 | N17: =IF(N(Revenue!E12)>0,FIXED(Revenue!E12,0),IF(N(Revenue!F12)>0,"$ "&FIXED((Revenue!F12)/1000000,0)&" M","–")) | O17: =IF(Revenue!H12="","–",Revenue!H12)
I18: =Revenue!A13 | J18: =IF(N(Revenue!C13)=0,"–",FIXED(Revenue!C13,0)&IF(OR(Revenue!B13="m²",Revenue!B13="",Revenue!B13="—"),""," "&Revenue!B13)) | K18: =IF(Revenue!G13="","–","$ "&FIXED(Revenue!G13,0)) | L18: =Revenue!D13 | M18: =Revenue!I13 | N18: =IF(N(Revenue!E13)>0,FIXED(Revenue!E13,0),IF(N(Revenue!F13)>0,"$ "&FIXED((Revenue!F13)/1000000,0)&" M","–")) | O18: =IF(Revenue!H13="","–",Revenue!H13)
I19: =Revenue!A14 | J19: =IF(N(Revenue!C14)=0,"–",FIXED(Revenue!C14,0)&IF(OR(Revenue!B14="m²",Revenue!B14="",Revenue!B14="—"),""," "&Revenue!B14)) | K19: =IF(Revenue!G14="","–","$ "&FIXED(Revenue!G14,0)) | L19: =Revenue!D14 | M19: =Revenue!I14 | N19: =IF(N(Revenue!E14)>0,FIXED(Revenue!E14,0),IF(N(Revenue!F14)>0,"$ "&FIXED((Revenue!F14)/1000000,0)&" M","–")) | O19: =IF(Revenue!H14="","–",Revenue!H14)
I20: =Revenue!A15 | J20: =IF(N(Revenue!C15)=0,"–",FIXED(Revenue!C15,0)&IF(OR(Revenue!B15="m²",Revenue!B15="",Revenue!B15="—"),""," "&Revenue!B15)) | K20: =IF(Revenue!G15="","–","$ "&FIXED(Revenue!G15,0)) | L20: =Revenue!D15 | M20: =Revenue!I15 | N20: =IF(N(Revenue!E15)>0,FIXED(Revenue!E15,0),IF(N(Revenue!F15)>0,"$ "&FIXED((Revenue!F15)/1000000,0)&" M","–")) | O20: =IF(Revenue!H15="","–",Revenue!H15)
I21: =Revenue!A16 | J21: =IF(N(Revenue!C16)=0,"–",FIXED(Revenue!C16,0)&IF(OR(Revenue!B16="m²",Revenue!B16="",Revenue!B16="—"),""," "&Revenue!B16)) | K21: =IF(Revenue!G16="","–","$ "&FIXED(Revenue!G16,0)) | L21: =Revenue!D16 | M21: =Revenue!I16 | N21: =IF(N(Revenue!E16)>0,FIXED(Revenue!E16,0),IF(N(Revenue!F16)>0,"$ "&FIXED((Revenue!F16)/1000000,0)&" M","–")) | O21: =IF(Revenue!H16="","–",Revenue!H16)
I22: =Revenue!A17 | J22: =IF(N(Revenue!C17)=0,"–",FIXED(Revenue!C17,0)&IF(OR(Revenue!B17="m²",Revenue!B17="",Revenue!B17="—"),""," "&Revenue!B17)) | K22: =IF(Revenue!G17="","–","$ "&FIXED(Revenue!G17,0)) | L22: =Revenue!D17 | M22: =Revenue!I17 | N22: =IF(N(Revenue!E17)>0,FIXED(Revenue!E17,0),IF(N(Revenue!F17)>0,"$ "&FIXED((Revenue!F17)/1000000,0)&" M","–")) | O22: =IF(Revenue!H17="","–",Revenue!H17)
I23: =Revenue!A18 | J23: =IF(N(Revenue!C18)=0,"–",FIXED(Revenue!C18,0)&IF(OR(Revenue!B18="m²",Revenue!B18="",Revenue!B18="—"),""," "&Revenue!B18)) | K23: =IF(Revenue!G18="","–","$ "&FIXED(Revenue!G18,0)) | L23: =Revenue!D18 | M23: =Revenue!I18 | N23: =IF(N(Revenue!E18)>0,FIXED(Revenue!E18,0),IF(N(Revenue!F18)>0,"$ "&FIXED((Revenue!F18)/1000000,0)&" M","–")) | O23: =IF(Revenue!H18="","–",Revenue!H18)
I24: =Revenue!A19 | L24: =Revenue!D19 | M24: =Revenue!I19
Q27: =IF(R27="","","●") | R27: =IFERROR(INDEX($BF$46:$BF$49,MATCH(1,$BH$46:$BH$49,0)),"") | BI27: =IFERROR(INDEX($BG$46:$BG$49,MATCH(1,$BH$46:$BH$49,0)),0)
Q28: =IF(R28="","","●") | R28: =IFERROR(INDEX($BF$46:$BF$49,MATCH(2,$BH$46:$BH$49,0)),"") | BJ28: =IFERROR(INDEX($BG$46:$BG$49,MATCH(2,$BH$46:$BH$49,0)),0)
BD40: =IF(AND(ISNUMBER(Revenue!H5),Revenue!H5<$BA$2),Revenue!A5&" "&ROUND((Revenue!H5)*100,0)&"%"&", ","") | BE40: =IF((BD40&BD41&BD42&BD43&BD44&BD45&BD46&BD47&BD48&BD49&BD50&BD51)="","",LEFT(BD40&BD41&BD42&BD43&BD44&BD45&BD46&BD47&BD48&BD49&BD50&BD51,LEN(BD40&BD41&BD42&BD43&BD44&BD45&BD46&BD47&BD48&BD49&BD50&BD51)-2))
BD41: =IF(AND(ISNUMBER(Revenue!H6),Revenue!H6<$BA$2),Revenue!A6&" "&ROUND((Revenue!H6)*100,0)&"%"&", ","")
BD42: =IF(AND(ISNUMBER(Revenue!H8),Revenue!H8<$BA$2),Revenue!A8&" "&ROUND((Revenue!H8)*100,0)&"%"&", ","")
BD43: =IF(AND(ISNUMBER(Revenue!H9),Revenue!H9<$BA$2),Revenue!A9&" "&ROUND((Revenue!H9)*100,0)&"%"&", ","")
BD44: =IF(AND(ISNUMBER(Revenue!H10),Revenue!H10<$BA$2),Revenue!A10&" "&ROUND((Revenue!H10)*100,0)&"%"&", ","")
BD45: =IF(AND(ISNUMBER(Revenue!H11),Revenue!H11<$BA$2),Revenue!A11&" "&ROUND((Revenue!H11)*100,0)&"%"&", ","")
BD46: =IF(AND(ISNUMBER(Revenue!H13),Revenue!H13<$BA$2),Revenue!A13&" "&ROUND((Revenue!H13)*100,0)&"%"&", ","") | BF46: =IFERROR(IF(Comentarios!$B$7="","",Comentarios!$B$7),"") | BG46: =IFERROR(4,4) | BH46: =0+IF(BF46="",0,1)
BD47: =IF(AND(ISNUMBER(Revenue!H14),Revenue!H14<$BA$2),Revenue!A14&" "&ROUND((Revenue!H14)*100,0)&"%"&", ","") | BF47: =IFERROR(IF(Comentarios!$B$8="","",Comentarios!$B$8),"") | BG47: =IFERROR(4,4) | BH47: =BH46+IF(BF47="",0,1)
BD48: =IF(AND(ISNUMBER(Revenue!H15),Revenue!H15<$BA$2),Revenue!A15&" "&ROUND((Revenue!H15)*100,0)&"%"&", ","") | BF48: =IFERROR("Premium concentra "&ROUND((Revenue!$D$7/(Revenue!$D$19-Revenue!$D$18))*100,0)&"%"&" del revenue de producto ("&"$ "&FIXED((Revenue!$D$7)/1000000,0)&" M"&").","") | BG48: =IFERROR(4,4) | BH48: =BH47+IF(BF48="",0,1)
BD49: =IF(AND(ISNUMBER(Revenue!H16),Revenue!H16<$BA$2),Revenue!A16&" "&ROUND((Revenue!H16)*100,0)&"%"&", ","") | BF49: =IFERROR(IF($BE$40="","Todas las líneas con Budget están sobre el umbral amarillo.","Bajo umbral vs Budget: "&$BE$40&"."),"") | BG49: =IFERROR(IF($BE$40="",3,1),4) | BH49: =BH48+IF(BF49="",0,1)
BD50: =IF(AND(ISNUMBER(Revenue!H17),Revenue!H17<$BA$2),Revenue!A17&" "&ROUND((Revenue!H17)*100,0)&"%"&", ","")
BD51: =IF(AND(ISNUMBER(Revenue!H18),Revenue!H18<$BA$2),Revenue!A18&" "&ROUND((Revenue!H18)*100,0)&"%"&", ","")
BK60: =Revenue!A5 | BL60: =N(Revenue!D5)/1000000 | BM60: =BL60+(12-0)/1000000000
BK61: =Revenue!A6 | BL61: =N(Revenue!D6)/1000000 | BM61: =BL61+(12-1)/1000000000
...

Sheet PPT_3
A1: ="Order Intake "&Config!$B$3 | G1: Comité de Operaciones | AZ1: Umbral verde | BA1: =Config!$B$8 | CB1: Order Intake semanal (m²) | CH1: Acumulado del mes vs Budget (m²)
A2: =Config!$B$10&" · Negocios ganados (m² adjudicados) vs Budget y proyección por ganar" | G2: =Config!$B$7&" · "&IF(ISNUMBER(Config!$B$6),TEXT(DAY(Config!$B$6),"00")&"/"&TEXT(MONTH(Config!$B$6),"00")&"/"&YEAR(Config!$B$6),Config!$B$6) | AZ2: Umbral amarillo | BA2: =Config!$B$9 | CC2: Budget | CD2: Ganado | CE2: Por ganar (ponderado) | CI2: Budget acumulado | CJ2: Ganado acumulado | CK2: Proyectado (ganado + pipeline)
CB3: W1 | CC3: =Order_Intake!B5 | CD3: =N(Order_Intake!C5) | CE3: =Order_Intake!G5 | CH3: W1 | CI3: =Order_Intake!H5 | CJ3: =Order_Intake!I5 | CK3: =Order_Intake!J5
A4: NEGOCIOS GANADOS | C4: GAP VS BUDGET | E4: CIERRE PROYECTADO MES | G4: PIPELINE MES SIGUIENTE | CB4: W2 | CC4: =Order_Intake!B6 | CD4: =N(Order_Intake!C6) | CE4: =Order_Intake!G6 | CH4: W2 | CI4: =Order_Intake!H6 | CJ4: =Order_Intake!I6 | CK4: =Order_Intake!J6
A5: =FIXED(Order_Intake!$C$9,0)&" m²" | C5: =FIXED(Order_Intake!$C$9-Config!$B$11,0)&" m²" | E5: =FIXED(Order_Intake!$C$9+Order_Intake!$G$9,0)&" m²" | G5: =FIXED(Pipeline!$H$31-Order_Intake!$G$9,0)&" m²" | CB5: W3 | CC5: =Order_Intake!B7 | CD5: =N(Order_Intake!C7) | CE5: =Order_Intake!G7 | CH5: W3 | CI5: =Order_Intake!H7 | CJ5: =Order_Intake!I7 | CK5: =Order_Intake!J7
A6: ="● "&ROUND((Order_Intake!$C$9/Config!$B$11)*100,0)&"%"&" "&"del Budget ("&FIXED(Config!$B$11,0)&")" | C6: ="acumulado a W"&COUNT(Order_Intake!$C$5:$C$8) | E6: ="● "&ROUND(((Order_Intake!$C$9+Order_Intake!$G$9)/Config!$B$11)*100,0)&"%"&" "&"con pipeline ponderado "&FIXED(Order_Intake!$G$9,0) | G6: ="ponderado · "&FIXED((Pipeline!$D$31-SUM(SUMIFS(Pipeline!$D$5:$D$29,Pipeline!$F$5:$F$29,{"W1","W2","W3","W4"}))),0)&" m² brutos" | BC6: =IF(NOT(ISNUMBER(Order_Intake!$C$9/Config!$B$11)),4,IF(Order_Intake!$C$9/Config!$B$11>=$BA$1,3,IF(Order_Intake!$C$9/Config!$B$11>=$BA$2,2,1))) | BD6: =IF(NOT(ISNUMBER((Order_Intake!$C$9+Order_Intake!$G$9)/Config!$B$11)),4,IF((Order_Intake!$C$9+Order_Intake!$G$9)/Config!$B$11>=$BA$1,3,IF((Order_Intake!$C$9+Order_Intake!$G$9)/Config!$B$11>=$BA$2,2,1))) | CB6: W4 | CC6: =Order_Intake!B8 | CD6: =N(Order_Intake!C8) | CE6: =Order_Intake!G8 | CH6: W4 | CI6: =Order_Intake!H8 | CJ6: =Order_Intake!I8 | CK6: =Order_Intake!J8
I9: Order Intake | J9: W1 | K9: W2 | L9: W3 | M9: W4 | N9: Total
I10: Budget | J10: =Order_Intake!B5 | K10: =Order_Intake!B6 | L10: =Order_Intake!B7 | M10: =Order_Intake!B8 | N10: =Config!$B$11
I11: Ganado | J11: =IF(Order_Intake!C5="","–",FIXED(Order_Intake!C5,0)&IF(Order_Intake!D5="En curso","*","")) | K11: =IF(Order_Intake!C6="","–",FIXED(Order_Intake!C6,0)&IF(Order_Intake!D6="En curso","*","")) | L11: =IF(Order_Intake!C7="","–",FIXED(Order_Intake!C7,0)&IF(Order_Intake!D7="En curso","*","")) | M11: =IF(Order_Intake!C8="","–",FIXED(Order_Intake!C8,0)&IF(Order_Intake!D8="En curso","*","")) | N11: =Order_Intake!$C$9
I12: Gap | J12: =IF(Order_Intake!C5="","–",Order_Intake!E5) | K12: =IF(Order_Intake!C6="","–",Order_Intake!E6) | L12: =IF(Order_Intake!C7="","–",Order_Intake!E7) | M12: =IF(Order_Intake!C8="","–",Order_Intake!E8) | N12: =Order_Intake!$C$9-Config!$B$11
I13: % Cumpl. | J13: =IF(Order_Intake!F5="","–",Order_Intake!F5) | K13: =IF(Order_Intake!F6="","–",Order_Intake!F6) | L13: =IF(Order_Intake!F7="","–",Order_Intake!F7) | M13: =IF(Order_Intake!F8="","–",Order_Intake!F8) | N13: =IF(Config!$B$11=0,"–",Order_Intake!$C$9/Config!$B$11)
I14: =IF(COUNTIF(Order_Intake!D5:D8,"En curso")>0,"* Semana en curso: valor parcial al corte.","")
P16: Negocio por ganar | Q16: Línea | R16: m² | S16: Prob. | T16: Cierre | U16: Pond.
P17: =IFERROR(INDEX(Pipeline!$A$5:$A$29,MATCH(LARGE(Pipeline!$I$5:$I$29,1),Pipeline!$I$5:$I$29,0)),IF(COUNT(Pipeline!$I$5:$I$29)=0,"Sin oportunidades en la hoja Pipeline","")) | Q17: =IFERROR(INDEX(Pipeline!$C$5:$C$29,MATCH(LARGE(Pipeline!$I$5:$I$29,1),Pipeline!$I$5:$I$29,0)),"") | R17: =IFERROR(INDEX(Pipeline!$D$5:$D$29,MATCH(LARGE(Pipeline!$I$5:$I$29,1),Pipeline!$I$5:$I$29,0)),"") | S17: =IFERROR(INDEX(Pipeline!$E$5:$E$29,MATCH(LARGE(Pipeline!$I$5:$I$29,1),Pipeline!$I$5:$I$29,0)),"") | T17: =IF(LEFT(IFERROR(INDEX(Pipeline!$F$5:$F$29,MATCH(LARGE(Pipeline!$I$5:$I$29,1),Pipeline!$I$5:$I$29,0)),""),3)="Mes","Mes sig.",IFERROR(INDEX(Pipeline!$F$5:$F$29,MATCH(LARGE(Pipeline!$I$5:$I$29,1),Pipeline!$I$5:$I$29,0)),"")) | U17: =IFERROR(INDEX(Pipeline!$H$5:$H$29,MATCH(LARGE(Pipeline!$I$5:$I$29,1),Pipeline!$I$5:$I$29,0)),"")
P18: =IFERROR(INDEX(Pipeline!$A$5:$A$29,MATCH(LARGE(Pipeline!$I$5:$I$29,2),Pipeline!$I$5:$I$29,0)),"") | Q18: =IFERROR(INDEX(Pipeline!$C$5:$C$29,MATCH(LARGE(Pipeline!$I$5:$I$29,2),Pipeline!$I$5:$I$29,0)),"") | R18: =IFERROR(INDEX(Pipeline!$D$5:$D$29,MATCH(LARGE(Pipeline!$I$5:$I$29,2),Pipeline!$I$5:$I$29,0)),"") | S18: =IFERROR(INDEX(Pipeline!$E$5:$E$29,MATCH(LARGE(Pipeline!$I$5:$I$29,2),Pipeline!$I$5:$I$29,0)),"") | T18: =IF(LEFT(IFERROR(INDEX(Pipeline!$F$5:$F$29,MATCH(LARGE(Pipeline!$I$5:$I$29,2),Pipeline!$I$5:$I$29,0)),""),3)="Mes","Mes sig.",IFERROR(INDEX(Pipeline!$F$5:$F$29,MATCH(LARGE(Pipeline!$I$5:$I$29,2),Pipeline!$I$5:$I$29,0)),"")) | U18: =IFERROR(INDEX(Pipeline!$H$5:$H$29,MATCH(LARGE(Pipeline!$I$5:$I$29,2),Pipeline!$I$5:$I$29,0)),"")
P19: =IFERROR(INDEX(Pipeline!$A$5:$A$29,MATCH(LARGE(Pipeline!$I$5:$I$29,3),Pipeline!$I$5:$I$29,0)),"") | Q19: =IFERROR(INDEX(Pipeline!$C$5:$C$29,MATCH(LARGE(Pipeline!$I$5:$I$29,3),Pipeline!$I$5:$I$29,0)),"") | R19: =IFERROR(INDEX(Pipeline!$D$5:$D$29,MATCH(LARGE(Pipeline!$I$5:$I$29,3),Pipeline!$I$5:$I$29,0)),"") | S19: =IFERROR(INDEX(Pipeline!$E$5:$E$29,MATCH(LARGE(Pipeline!$I$5:$I$29,3),Pipeline!$I$5:$I$29,0)),"") | T19: =IF(LEFT(IFERROR(INDEX(Pipeline!$F$5:$F$29,MATCH(LARGE(Pipeline!$I$5:$I$29,3),Pipeline!$I$5:$I$29,0)),""),3)="Mes","Mes sig.",IFERROR(INDEX(Pipeline!$F$5:$F$29,MATCH(LARGE(Pipeline!$I$5:$I$29,3),Pipeline!$I$5:$I$29,0)),"")) | U19: =IFERROR(INDEX(Pipeline!$H$5:$H$29,MATCH(LARGE(Pipeline!$I$5:$I$29,3),Pipeline!$I$5:$I$29,0)),"")
P20: =IFERROR(INDEX(Pipeline!$A$5:$A$29,MATCH(LARGE(Pipeline!$I$5:$I$29,4),Pipeline!$I$5:$I$29,0)),"") | Q20: =IFERROR(INDEX(Pipeline!$C$5:$C$29,MATCH(LARGE(Pipeline!$I$5:$I$29,4),Pipeline!$I$5:$I$29,0)),"") | R20: =IFERROR(INDEX(Pipeline!$D$5:$D$29,MATCH(LARGE(Pipeline!$I$5:$I$29,4),Pipeline!$I$5:$I$29,0)),"") | S20: =IFERROR(INDEX(Pipeline!$E$5:$E$29,MATCH(LARGE(Pipeline!$I$5:$I$29,4),Pipeline!$I$5:$I$29,0)),"") | T20: =IF(LEFT(IFERROR(INDEX(Pipeline!$F$5:$F$29,MATCH(LARGE(Pipeline!$I$5:$I$29,4),Pipeline!$I$5:$I$29,0)),""),3)="Mes","Mes sig.",IFERROR(INDEX(Pipeline!$F$5:$F$29,MATCH(LARGE(Pipeline!$I$5:$I$29,4),Pipeline!$I$5:$I$29,0)),"")) | U20: =IFERROR(INDEX(Pipeline!$H$5:$H$29,MATCH(LARGE(Pipeline!$I$5:$I$29,4),Pipeline!$I$5:$I$29,0)),"")
P21: =IFERROR(INDEX(Pipeline!$A$5:$A$29,MATCH(LARGE(Pipeline!$I$5:$I$29,5),Pipeline!$I$5:$I$29,0)),"") | Q21: =IFERROR(INDEX(Pipeline!$C$5:$C$29,MATCH(LARGE(Pipeline!$I$5:$I$29,5),Pipeline!$I$5:$I$29,0)),"") | R21: =IFERROR(INDEX(Pipeline!$D$5:$D$29,MATCH(LARGE(Pipeline!$I$5:$I$29,5),Pipeline!$I$5:$I$29,0)),"") | S21: =IFERROR(INDEX(Pipeline!$E$5:$E$29,MATCH(LARGE(Pipeline!$I$5:$I$29,5),Pipeline!$I$5:$I$29,0)),"") | T21: =IF(LEFT(IFERROR(INDEX(Pipeline!$F$5:$F$29,MATCH(LARGE(Pipeline!$I$5:$I$29,5),Pipeline!$I$5:$I$29,0)),""),3)="Mes","Mes sig.",IFERROR(INDEX(Pipeline!$F$5:$F$29,MATCH(LARGE(Pipeline!$I$5:$I$29,5),Pipeline!$I$5:$I$29,0)),"")) | U21: =IFERROR(INDEX(Pipeline!$H$5:$H$29,MATCH(LARGE(Pipeline!$I$5:$I$29,5),Pipeline!$I$5:$I$29,0)),"")
W23: ALERTAS
W24: =IF(X24="","","●") | X24: =IFERROR(INDEX($BG$43:$BG$47,MATCH(1,$BI$43:$BI$47,0)),"") | BJ24: =IFERROR(INDEX($BH$43:$BH$47,MATCH(1,$BI$43:$BI$47,0)),0)
W25: =IF(X25="","","●") | X25: =IFERROR(INDEX($BG$43:$BG$47,MATCH(2,$BI$43:$BI$47,0)),"") | BK25: =IFERROR(INDEX($BH$43:$BH$47,MATCH(2,$BI$43:$BI$47,0)),0)
W26: =IF(X26="","","●") | X26: =IFERROR(INDEX($BG$43:$BG$47,MATCH(3,$BI$43:$BI$47,0)),"") | BL26: =IFERROR(INDEX($BH$43:$BH$47,MATCH(3,$BI$43:$BI$47,0)),0)
BG43: =IFERROR(IF(Comentarios!$B$9="","",Comentarios!$B$9),"") | BH43: =IFERROR(4,4) | BI43: =0+IF(BG43="",0,1)
BG44: =IFERROR(IF(Comentarios!$B$10="","",Comentarios!$B$10),"") | BH44: =IFERROR(4,4) | BI44: =BI43+IF(BG44="",0,1)
BG45: =IFERROR("Acumulado "&ROUND((Order_Intake!$C$9/Config!$B$11)*100,0)&"%"&" del Budget; gap "&FIXED(Order_Intake!$C$9-Config!$B$11,0)&" m².","") | BH45: =IFERROR(IF(NOT(ISNUMBER(Order_Intake!$C$9/Config!$B$11)),4,IF(Order_Intake!$C$9/Config!$B$11>=$BA$1,3,IF(Order_Intake!$C$9/Config!$B$11>=$BA$2,2,1))),4) | BI45: =BI44+IF(BG45="",0,1)
BG46: =IFERROR(IF($BF$60="","Ninguna semana bajo el umbral amarillo.","Semanas bajo umbral: "&$BF$60&"."),"") | BH46: =IFERROR(IF($BF$60="",3,1),4) | BI46: =BI45+IF(BG46="",0,1)
BG47: =IFERROR(IF((Config!$B$11-Order_Intake!$C$9)<=0,"Budget del mes cumplido.","Pipeline del mes cubre "&ROUND((Order_Intake!$G$9/(Config!$B$11-Order_Intake!$C$9))*100,0)&"%"&" del gap ("&FIXED(Order_Intake!$G$9,0)&" de "&FIXED((Config!$B$11-Order_Intake!$C$9),0)&" m²)."),"") | BH47: =IFERROR(IF((Config!$B$11-Order_Intake!$C$9)<=0,3,IF(NOT(ISNUMBER(Order_Intake!$G$9/(Config!$B$11-Order_Intake!$C$9))),4,IF(Order_Intake!$G$9/(Config!$B$11-Order_Intake!$C$9)>=$BA$1,3,IF(Order_Intake!$G$9/(Config!$B$11-Order_Intake!$C$9)>=$BA$2,2,1)))),4) | BI47: =BI46+IF(BG47="",0,1)
BE60: =IF(AND(ISNUMBER(Order_Intake!F5),Order_Intake!F5<$BA$2),"W1 ("&ROUND((Order_Intake!F5)*100,0)&"%"&"), ","") | BF60: =IF((BE60&BE61&BE62&BE63)="","",LEFT(BE60&BE61&BE62&BE63,LEN(BE60&BE61&BE62&BE63)-2))
BE61: =IF(AND(ISNUMBER(Order_Intake!F6),Order_Intake!F6<$BA$2),"W2 ("&ROUND((Order_Intake!F6)*100,0)&"%"&"), ","")
BE62: =IF(AND(ISNUMBER(Order_Intake!F7),Order_Intake!F7<$BA$2),"W3 ("&ROUND((Order_Intake!F7)*100,0)&"%"&"), ","")
BE63: =IF(AND(ISNUMBER(Order_Intake!F8),Order_Intake!F8<$BA$2),"W4 ("&ROUND((Order_Intake!F8)*100,0)&"%"&"), ","")
